Workbook

Sheet Overview
A1: Vaishno Devi Helicopter Yatra – Overview
A2: Jammu – Katra – Vaishno Devi – Jammu · 3 nights / 4 days · mode: car, helicopter Katra ⇄ Sanjichhat · Departure: 13–16 March 2027
A3: Departure date (Day 1) | B3: 46459 | C3: ← change this date and every day / row date updates | I3: Key dates
A4: Day | B4: Date | C4: Route | D4: Car km | E4: Night stay | F4: First start | G4: Last end | I4: Registrations close | J4: 46381
A5: 1 | B5: =$B$3+A5-1 -> 46459 | C5: Jammu Airport arrival (14:00), Jammu temples | D5: =SUMIF('Minute-by-Minute'!$A$5:$A$60,A5,'Minute-by-Minute'!$I$5:$I$60) -> 32 | E5: Jammu | F5: =_xlfn.MINIFS('Minute-by-Minute'!$C$5:$C$60,'Minute-by-Minute'!$A$5:$A$60,A5) -> 0.58333333 | G5: =_xlfn.MAXIFS('Minute-by-Minute'!$D$5:$D$60,'Minute-by-Minute'!$A$5:$A$60,A5) -> 0.88541667 | I5: Yatri data to travel agent | J5: 46386
A6: 2 | B6: =$B$3+A6-1 -> 46460 | C6: Jammu → Katra → Sanjichhat (helicopter) → Bhawan (battery car) | D6: =SUMIF('Minute-by-Minute'!$A$5:$A$60,A6,'Minute-by-Minute'!$I$5:$I$60) -> 52 | E6: Bhawan | F6: =_xlfn.MINIFS('Minute-by-Minute'!$C$5:$C$60,'Minute-by-Minute'!$A$5:$A$60,A6) -> 0.3125 | G6: =_xlfn.MAXIFS('Minute-by-Minute'!$D$5:$D$60,'Minute-by-Minute'!$A$5:$A$60,A6) -> 0.85416667 | I6: Helicopter tickets booked | J6: 46388
A7: 3 | B7: =$B$3+A7-1 -> 46461 | C7: Bhawan → Bhairon → Sanjichhat (helicopter) → Katra → Jammu | D7: =SUMIF('Minute-by-Minute'!$A$5:$A$60,A7,'Minute-by-Minute'!$I$5:$I$60) -> 58 | E7: Jammu | F7: =_xlfn.MINIFS('Minute-by-Minute'!$C$5:$C$60,'Minute-by-Minute'!$A$5:$A$60,A7) -> 0.1875 | G7: =_xlfn.MAXIFS('Minute-by-Minute'!$D$5:$D$60,'Minute-by-Minute'!$A$5:$A$60,A7) -> 0.875
A8: 4 | B8: =$B$3+A8-1 -> 46462 | C8: Jammu hotel → Jammu Airport departure | D8: =SUMIF('Minute-by-Minute'!$A$5:$A$60,A8,'Minute-by-Minute'!$I$5:$I$60) -> 7 | E8: — | F8: =_xlfn.MINIFS('Minute-by-Minute'!$C$5:$C$60,'Minute-by-Minute'!$A$5:$A$60,A8) -> 0.3125 | G8: =_xlfn.MAXIFS('Minute-by-Minute'!$D$5:$D$60,'Minute-by-Minute'!$A$5:$A$60,A8) -> 0.40625 | I8: Flight info
A9: Total | D9: =SUM(D5:D8) -> 149 | E9: 3 nights | I9: Arrival at Jammu Airport on 13 March 2027 before 14:00
I10: Departure from Jammu Airport on 16 March 2027 after 14:00
A11: Other transport: 2 helicopter flights (5–8 min each), battery car Sanjichhat → Bhawan (2.5 km), Bhairon ropeway, ~3 km downhill track Bhairon → Sanjichhat on Day 3 (escorts assist seniors).
A12: Assumptions: arrival at Jammu Airport at 14:00 on Day 1; breakfast 07:30–08:30 and departure from the hotel at 09:00 every day; helicopter slots 12:15 (Day 2) and 12:15 (Day 3); same Jammu hotel on Days 1 and 3 (main luggage stays there on Day 2); Day 4 at Jammu Airport by 09:20; one vehicle convoy for the group. | I12: Price
I13: 3N/4D: ₹50,000 per person + 5% GST, excluding flight charges

Sheet Minute-by-Minute
A1: 4 Days Vaishno Devi Helicopter Package – Minute-to-Minute Plan
A2: Departure: 13–16 March 2027. Draft as of 21 Oct 2026. Car km and drive times are approximate – verify on Google Maps. Edit Start/End times; Mins and totals recalculate.
A4: Day | B4: Date | C4: Start | D4: End | E4: Mins | F4: Mode | G4: From | H4: To | I4: Car km | J4: What we do | K4: Google Map
A5: 1 | B5: =Overview!$B$3+A5-1 -> 46459 | C5: 0.58333333 | D5: 0.60416667 | E5: =ROUND((D5-C5)*1440,0) -> 30 | F5: Arrival | G5: Jammu Airport (IXJ) | J5: Meet our representative, garland welcome, load luggage, headcount | K5: Open map
A6: 1 | B6: =Overview!$B$3+A6-1 -> 46459 | C6: 0.60416667 | D6: 0.61805556 | E6: =ROUND((D6-C6)*1440,0) -> 20 | F6: Car | G6: Jammu Airport | H6: Hotel, Jammu | I6: 7 | J6: Transfer to the hotel | K6: Open map
A7: 1 | B7: =Overview!$B$3+A7-1 -> 46459 | C7: 0.61805556 | D7: 0.63541667 | E7: =ROUND((D7-C7)*1440,0) -> 25 | F7: Halt | G7: Hotel, Jammu | J7: Check-in, freshen up | K7: Open map
A8: 1 | B8: =Overview!$B$3+A8-1 -> 46459 | C8: 0.63541667 | D8: 0.65972222 | E8: =ROUND((D8-C8)*1440,0) -> 35 | F8: Lunch | G8: Hotel restaurant, Jammu | J8: Lunch | K8: Open map
A9: 1 | B9: =Overview!$B$3+A9-1 -> 46459 | C9: 0.65972222 | D9: 0.67013889 | E9: =ROUND((D9-C9)*1440,0) -> 15 | F9: Car | G9: Hotel, Jammu | H9: Raghunath Temple | I9: 5 | J9: Drive to the old-city temple complex | K9: Open map
A10: 1 | B10: =Overview!$B$3+A10-1 -> 46459 | C10: 0.67013889 | D10: 0.69791667 | E10: =ROUND((D10-C10)*1440,0) -> 40 | F10: Darshan | G10: Raghunath Temple | J10: Darshan of Sri Rama, Sita and Lakshmana; galleries of saligramas; group kirtan | K10: Open map
A11: 1 | B11: =Overview!$B$3+A11-1 -> 46459 | C11: 0.69791667 | D11: 0.70486111 | E11: =ROUND((D11-C11)*1440,0) -> 10 | F11: Car | G11: Raghunath Temple | H11: Ranbireshwar Temple | I11: 1 | J11: Short hop | K11: Open map
A12: 1 | B12: =Overview!$B$3+A12-1 -> 46459 | C12: 0.70486111 | D12: 0.72222222 | E12: =ROUND((D12-C12)*1440,0) -> 25 | F12: Darshan | G12: Ranbireshwar Temple | J12: Darshan of the 7.5 ft Shiva lingam and crystal lingams | K12: Open map
A13: 1 | B13: =Overview!$B$3+A13-1 -> 46459 | C13: 0.72222222 | D13: 0.73611111 | E13: =ROUND((D13-C13)*1440,0) -> 20 | F13: Car | G13: Ranbireshwar Temple | H13: Bahu Fort (Bawe Wali Mata) | I13: 6 | J13: Cross the Tawi to Bahu Fort | K13: Open map
A14: 1 | B14: =Overview!$B$3+A14-1 -> 46459 | C14: 0.73611111 | D14: 0.77083333 | E14: =ROUND((D14-C14)*1440,0) -> 50 | F14: Darshan | G14: Bawe Wali Mata Temple & Bahu Fort | J14: Darshan of Mahakali (Bawe Wali Mata); fort ramparts and Bagh-e-Bahu gardens at sunset | K14: Open map
A15: 1 | B15: =Overview!$B$3+A15-1 -> 46459 | C15: 0.77083333 | D15: 0.78819444 | E15: =ROUND((D15-C15)*1440,0) -> 25 | F15: Car | G15: Bahu Fort | H15: Peer Kho Cave Temple | I15: 7 | J15: Drive along Circular Road | K15: Open map
A16: 1 | B16: =Overview!$B$3+A16-1 -> 46459 | C16: 0.78819444 | D16: 0.8125 | E16: =ROUND((D16-C16)*1440,0) -> 35 | F16: Darshan | G16: Peer Kho Cave Temple | J16: Cave shrine of the self-manifest Shiva lingam; evening aarti | K16: Open map
A17: 1 | B17: =Overview!$B$3+A17-1 -> 46459 | C17: 0.8125 | D17: 0.82638889 | E17: =ROUND((D17-C17)*1440,0) -> 20 | F17: Car | G17: Peer Kho Cave Temple | H17: Hotel, Jammu | I17: 6 | J17: Return to the hotel | K17: Open map
A18: 1 | B18: =Overview!$B$3+A18-1 -> 46459 | C18: 0.82638889 | D18: 0.84375 | E18: =ROUND((D18-C18)*1440,0) -> 25 | F18: Halt | G18: Hotel, Jammu | J18: Freshen up; Day 2 briefing (photo ID, small bag for Bhawan; main luggage stays at this hotel) | K18: Open map
A19: 1 | B19: =Overview!$B$3+A19-1 -> 46459 | C19: 0.84375 | D19: 0.88541667 | E19: =ROUND((D19-C19)*1440,0) -> 60 | F19: Dinner | G19: Hotel restaurant, Jammu | J19: Dinner | K19: Open map
A20: 2 | B20: =Overview!$B$3+A20-1 -> 46460 | C20: 0.3125 | D20: 0.35416667 | E20: =ROUND((D20-C20)*1440,0) -> 60 | F20: Breakfast | G20: Hotel restaurant, Jammu | J20: Breakfast | K20: Open map
A21: 2 | B21: =Overview!$B$3+A21-1 -> 46460 | C21: 0.35416667 | D21: 0.375 | E21: =ROUND((D21-C21)*1440,0) -> 30 | F21: Halt | G21: Hotel, Jammu | J21: Check-out with a small bag; main luggage stays at the Jammu hotel for Day 3 | K21: Open map
A22: 2 | B22: =Overview!$B$3+A22-1 -> 46460 | C22: 0.375 | D22: 0.4375 | E22: =ROUND((D22-C22)*1440,0) -> 90 | F22: Car | G22: Hotel, Jammu | H22: Katra | I22: 50 | J22: Drive via the Jammu–Katra highway; tea stop en route | K22: Open map
A23: 2 | B23: =Overview!$B$3+A23-1 -> 46460 | C23: 0.4375 | D23: 0.45833333 | E23: =ROUND((D23-C23)*1440,0) -> 30 | F23: Registration | G23: Yatra Registration Counter, Katra | J23: RFID Yatra cards for every yatri (carry original photo ID) | K23: Open map
A24: 2 | B24: =Overview!$B$3+A24-1 -> 46460 | C24: 0.45833333 | D24: 0.46527778 | E24: =ROUND((D24-C24)*1440,0) -> 10 | F24: Car | G24: Katra town | H24: Katra Helipad | I24: 2 | J24: Drive to the helipad | K24: Open map
A25: 2 | B25: =Overview!$B$3+A25-1 -> 46460 | C25: 0.46527778 | D25: 0.51041667 | E25: =ROUND((D25-C25)*1440,0) -> 65 | F25: Reporting | G25: Katra Helipad | J25: Report for the allotted slot: ticket and ID check, baggage weighing, security | K25: Open map
A26: 2 | B26: =Overview!$B$3+A26-1 -> 46460 | C26: 0.51041667 | D26: 0.51736111 | E26: =ROUND((D26-C26)*1440,0) -> 10 | F26: Helicopter | G26: Katra Helipad | H26: Sanjichhat Helipad | J26: Helicopter flight, about 5–8 minutes | K26: Open map
A27: 2 | B27: =Overview!$B$3+A27-1 -> 46460 | C27: 0.51736111 | D27: 0.54166667 | E27: =ROUND((D27-C27)*1440,0) -> 35 | F27: Battery car | G27: Sanjichhat Helipad | H27: Bhawan | J27: 2.5 km to Bhawan by battery car | K27: Open map
A28: 2 | B28: =Overview!$B$3+A28-1 -> 46460 | C28: 0.54166667 | D28: 0.5625 | E28: =ROUND((D28-C28)*1440,0) -> 30 | F28: Halt | G28: Bhawan | J28: Check-in at Bhawan accommodation; cloak room | K28: Open map
A29: 2 | B29: =Overview!$B$3+A29-1 -> 46460 | C29: 0.5625 | D29: 0.59375 | E29: =ROUND((D29-C29)*1440,0) -> 45 | F29: Lunch | G29: Restaurant, Bhawan | J29: Lunch | K29: Open map
A30: 2 | B30: =Overview!$B$3+A30-1 -> 46460 | C30: 0.59375 | D30: 0.6875 | E30: =ROUND((D30-C30)*1440,0) -> 135 | F30: Rest | G30: Bhawan | J30: Rest, japa, group kirtan | K30: Open map
A31: 2 | B31: =Overview!$B$3+A31-1 -> 46460 | C31: 0.6875 | D31: 0.75 | E31: =ROUND((D31-C31)*1440,0) -> 90 | F31: Darshan | G31: Holy Cave, Bhawan | J31: Darshan of the three Pindis (Maha Kali, Maha Lakshmi, Maha Saraswati) | K31: Open map
A32: 2 | B32: =Overview!$B$3+A32-1 -> 46460 | C32: 0.75 | D32: 0.8125 | E32: =ROUND((D32-C32)*1440,0) -> 90 | F32: Aarti | G32: Bhawan | J32: Evening Aarti | K32: Open map
A33: 2 | B33: =Overview!$B$3+A33-1 -> 46460 | C33: 0.8125 | D33: 0.85416667 | E33: =ROUND((D33-C33)*1440,0) -> 60 | F33: Dinner | G33: Restaurant, Bhawan | J33: Dinner | K33: Open map
A34: 3 | B34: =Overview!$B$3+A34-1 -> 46461 | C34: 0.1875 | D34: 0.22916667 | E34: =ROUND((D34-C34)*1440,0) -> 60 | F34: Halt | G34: Bhawan | J34: Wake-up, bath, get ready | K34: Open map
A35: 3 | B35: =Overview!$B$3+A35-1 -> 46461 | C35: 0.22916667 | D35: 0.29166667 | E35: =ROUND((D35-C35)*1440,0) -> 90 | F35: Aarti | G35: Bhawan | J35: Morning Aarti at the Holy Cave | K35: Open map
A36: 3 | B36: =Overview!$B$3+A36-1 -> 46461 | C36: 0.29166667 | D36: 0.3125 | E36: =ROUND((D36-C36)*1440,0) -> 30 | F36: Rest | G36: Bhawan | J36: Rest, pack small bag | K36: Open map
A37: 3 | B37: =Overview!$B$3+A37-1 -> 46461 | C37: 0.3125 | D37: 0.35416667 | E37: =ROUND((D37-C37)*1440,0) -> 60 | F37: Breakfast | G37: Restaurant, Bhawan | J37: Breakfast | K37: Open map
A38: 3 | B38: =Overview!$B$3+A38-1 -> 46461 | C38: 0.35416667 | D38: 0.375 | E38: =ROUND((D38-C38)*1440,0) -> 30 | F38: Halt | G38: Bhawan | J38: Check-out, collect cloak-room items | K38: Open map
A39: 3 | B39: =Overview!$B$3+A39-1 -> 46461 | C39: 0.375 | D39: 0.38541667 | E39: =ROUND((D39-C39)*1440,0) -> 15 | F39: Walk | G39: Bhawan | H39: Bhawan ropeway station | J39: Short walk (~300 m) to the ropeway | K39: Open map
A40: 3 | B40: =Overview!$B$3+A40-1 -> 46461 | C40: 0.38541667 | D40: 0.39930556 | E40: =ROUND((D40-C40)*1440,0) -> 20 | F40: Ropeway | G40: Bhawan ropeway station | H40: Bhairon Ghati | J40: Ropeway ride, about 3 minutes plus queue | K40: Open map
A41: 3 | B41: =Overview!$B$3+A41-1 -> 46461 | C41: 0.39930556 | D41: 0.42708333 | E41: =ROUND((D41-C41)*1440,0) -> 40 | F41: Darshan | G41: Bhairon Baba Temple | J41: Darshan of Bhairon Baba – completes the yatra | K41: Open map
...

Sheet Meal Plan
A1: Meal plan (all pure-veg)
A3: Day | B3: Meal | C3: Time | D3: Where
A4: 1 | B4: Lunch | C4: 15:15–15:50 | D4: Hotel restaurant, Jammu
A5: 1 | B5: Dinner | C5: 20:15–21:15 | D5: Hotel restaurant, Jammu
A6: 2 | B6: Breakfast | C6: 07:30–08:30 | D6: Hotel restaurant, Jammu
A7: 2 | B7: Lunch | C7: 13:30–14:15 | D7: Restaurant, Bhawan
A8: 2 | B8: Dinner | C8: 19:30–20:30 | D8: Restaurant, Bhawan
A9: 3 | B9: Breakfast | C9: 07:30–08:30 | D9: Restaurant, Bhawan
A10: 3 | B10: Lunch | C10: 12:40–13:30 | D10: Restaurant, Katra
A11: 3 | B11: Dinner | C11: 20:00–21:00 | D11: Hotel restaurant, Jammu
A12: 4 | B12: Breakfast | C12: 07:30–08:30 | D12: Hotel restaurant, Jammu

Sheet Pros & Cons
A1: Aspect | B1: Good | C1: Bad
A2: Helicopter | B2: Cuts the 13 km climb to ~10 min; ideal for seniors and families | C2: Weather-dependent; slots sell out fast; tight baggage limit
A3: Battery car Sanjichhat → Bhawan | B3: No walking on Day 2; comfortable for seniors | C3: Queues at peak hours
A4: Night at Bhawan | B4: Both Evening and Morning Aarti; unhurried darshan | C4: Shared, basic rooms; limited supply
A5: Jammu sightseeing on Day 1 | B5: Uses arrival day well; four temples in 32 km | C5: Afternoon-only window after a 14:00 arrival; little slack if flights are late
A6: Bhairon by ropeway | B6: Completes the yatra with no extra climb | C6: Queues at peak hours; ropeway may stop in bad weather
A7: Katra afternoon (Day 3) | B7: Banganga, Darshani Deodi and shopping at an easy pace | C7: Crowded market; ~1.5 hr drive back to Jammu
A8: Same Jammu hotel on Days 1 and 3 | B8: Main luggage waits there; short airport run on Day 4 | C8: Long Day 3 (04:30 wake-up to Jammu by 18:00)
A9: Overall pace | B9: 3 nights only; little road travel (149 km) | C9: Early starts on Days 2 and 3 (04:30 wake-up at Bhawan)
A10: Food | B10: All meals arranged; pure-veg throughout | C10: Simple menu at Bhawan

Sheet Challenges & Backups
A1: Challenge | B1: Impact | C1: How we prevent it | D1: Backup on the day
A2: Helicopter grounded (rain, fog, wind) | B2: Day 2 Bhawan arrival or Day 3 return slips | C2: Avoid Jul–Aug; book earliest slots; keep 2–3 hrs slack | D2: Wait for next slot; else the 13 km track from Katra (battery car Ardhkuwari → Bhawan); inform the Jammu hotel
A3: Helicopter slots not available | B3: Package cannot run as planned | C3: Book the day the SMVDSB portal opens; book all yatris together | D3: Shift dates
A4: Yatri misses reporting time | B4: Seat forfeited | C4: Leave Katra town by 11:00; registration before helipad | D4: Re-book a later slot if seats remain
A5: Bhawan rooms not available | B5: No night at Bhawan | C5: Book on SMVDSB portal as soon as dates are fixed | D5: Darshan Day 2 evening, return to Jammu same night; Morning Aarti dropped
A6: Long darshan queues | B6: Aarti or flight missed | C6: Avoid peak dates; darshan in the afternoon after rest | D6: Darshan Day 3 early morning, keep the 12:15 flight
A7: Aarti passes not available | B7: Group cannot sit inside for Aarti | C7: Book Atka Aarti passes the day booking opens | D7: Join Aarti from the courtyard screens
A8: Senior tires on the Day 3 downhill track | B8: Group delayed | C8: Pre-trip fitness question; escorts walk with seniors | D8: One escort stays back; use Bhawan medical centre
A9: Lost RFID card or ID | B9: Cannot enter the track | C9: Leader keeps photocopies; yatris carry originals | D9: Re-issue at Katra counter with ID copy
A10: Prepaid SIMs from other states don't work in J&K | B10: Group out of contact | C10: Tell yatris in advance; carry postpaid numbers | D10: Leader and assistant on postpaid; fixed meeting points
A11: Road block / landslide Jammu–Katra | B11: Day 2 or Day 3 delayed | C11: Leave on time; check traffic | D11: Ask local driver for open alternative route
A12: Flight delays at Jammu (winter fog) | B12: Day 1 sightseeing cut short | C12: Choose flights landing well before 14:00 | D12: Drop Peer Kho on Day 1
A13: Lost yatri in crowd | B13: Panic, delay | C13: Group cap/scarf; buddy pairs; head counts at every move | D13: Meet at fixed point; announce at help desk

Sheet Dos & Donts
A1: Type | B1: Point
A2: Do – yatris | B2: Carry the original photo ID used for helicopter and Yatra booking
A3: Do – yatris | B3: Keep the RFID Yatra card on you from Katra till the end of Day 3
A4: Do – yatris | B4: Small day bag for Bhawan; main suitcase stays at the Jammu hotel
A5: Do – yatris | B5: Report 10 minutes before every departure time
A6: Do – yatris | B6: Stay with your buddy; wear the group cap or scarf
A7: Do – yatris | B7: Deposit phones, cameras and bags in the cloak room before darshan
A8: Do – yatris | B8: Drink water often; eat light before the helicopter and the track
A9: Do – yatris | B9: Chant; follow Shrine Board queue instructions
A10: Do – yatris | B10: Tell the tour leader at once if unwell
A11: Don't – yatris | B11: Carry phones, cameras, bags, leather goods or eatables into the darshan area (check cloak-room board)
A12: Don't – yatris | B12: Exceed the helicopter baggage limit
... A24: Don't – tour team | B24: Change the plan without telling the yatra coordinator

Sheet Checklist
A1: Bookings & documents checklist (T = departure date)
A3: When | B3: Task | C3: Owner | D3: Notes | E3: Status (fill in)
A4: T−60 days | B4: Fix dates; avoid Navratri, May–June holidays, Jul–Aug monsoon | C4: Yatra coordinator
A5: By 25 Dec 2026 | B5: Registrations close: collect yatri names, photo ID (Aadhaar / passport), age, weight, phone, emergency contact, medical notes | C5: Yatra coordinator | D5: Last date 25 Dec 2026; name exactly as on ID; weight needed for the helicopter
A6: 30 Dec 2026 | B6: Send complete yatri data to the travel agent | C6: Yatra coordinator | D6: Names as on ID, ID numbers, ages, weights, phone numbers
A7: 1 Jan 2027 | B7: Book helicopter Day 2 & Day 3 on SMVDSB portal | C7: Travel agent with yatra coordinator
A8: Booking opening day | B8: Book Bhawan accommodation Day 2 night | C8: Yatra coordinator
A9: Booking opening day | B9: Book Atka Aarti passes, Bhairon ropeway and the Sanjichhat → Bhawan battery car | C9: Yatra coordinator
A10: T−45 days | B10: Book flights / trains: arrival before 14:00 on 13 Mar; departure after 14:00 on 16 Mar | C10: Travel desk
A11: T−45 days | B11: Book the Jammu hotel for Days 1 and 3 (same hotel; luggage storage on Day 2) | C11: Travel desk
A12: T−30 days | B12: Book vehicles for all 4 days | C12: Travel desk
A13: T−15 days | B13: Pre-order Day 1 lunch and all hotel dinner menus; pre-book the Day 3 lunch restaurant in Katra | C13: Tour leader
A14: T−15 days | B14: Travel insurance for every yatri | C14: Travel desk
A15: T−7 days | B15: Pre-departure meeting: itinerary, packing, do's & don'ts, SIM advice | C15: Tour leader
A16: T−2 days | B16: Reconfirm hotel, vehicles, restaurants, helicopter slots | C16: Tour leader
A17: T−1 day | B17: Print tickets, room booking, passes, yatri list, ID copies | C17: Tour leader
A18: Day 2 at Katra | B18: RFID Yatra registration for every yatri | C18: Tour leader

Sheet Packing List
A1: Bag / season | B1: Item
A2: Day bag | B2: Original photo ID + photocopy
A3: Day bag | B3: Helicopter ticket and RFID Yatra card
A4: Day bag | B4: One change of clothes, towel
A5: Day bag | B5: Shawl / light jacket
A6: Day bag | B6: Medicines for 2 days + prescription
A7: Day bag | B7: Water bottle, dry fruits
A8: Day bag | B8: Japa mala, small torch, small-note cash
A9: Main suitcase | B9: Clothes for 4 days
A10: Main suitcase | B10: Walking shoes with grip + slippers
A11: Main suitcase | B11: Toiletries, sunscreen, cap
A12: Main suitcase | B12: Raincoat / umbrella
... A18: Oct–Nov | B18: Light woollens for Bhawan nights

Sheet Health & Safety
A1: Topic | B1: Guidance
A2: Exertion | B2: Only ~3 km on track, downhill on Day 3 (Bhairon → Sanjichhat); Sanjichhat → Bhawan by battery car; rest by car, helicopter, ropeway
A3: Fitness check | B3: Ask about heart, BP, diabetes, asthma, knees; escorts assist anyone who finds the 3 km downhill walk on Day 3 hard
A4: Altitude | B4: Bhawan ~5,200 ft; walk slowly, rest, drink water
A5: Helicopter | B5: Pregnant women, infants, recent surgery: check operator rules before booking
A6: Medical help | B6: Shrine Board medical points on track and at Bhawan; hospitals in Katra and Jammu
A7: Seniors | B7: Seat first; 1 escort per 5–6 seniors on track; darshan after rest
A8: Food & water | B8: Hotels and pre-booked restaurants only; packaged water; avoid fried snacks before flight
A9: Crowd safety | B9: Buddy pairs, group cap/scarf, head counts, fixed meeting points
A10: Valuables | B10: Neck pouch for cash/ID; cloak rooms; no jewellery
A11: Insurance | B11: Every yatri insured; policy no. on yatri list

Sheet Best Time
A1: Months | B1: Weather | C1: Crowd | D1: Helicopter reliability | E1: Verdict
A2: Mar–Apr | B2: Pleasant days, cool nights | C2: Medium; very high in Chaitra Navratri | D2: Good | E2: Recommended (avoid Navratri week)
A3: May–Jun | B3: Hot in Jammu (40°C+), pleasant at Bhawan | C3: Very high (school holidays) | D3: Good | E3: Possible; book very early
A4: Jul–Aug | B4: Monsoon rain, landslide risk | C4: Low–medium | D4: Poor; frequent cancellations | E4: Avoid
A5: Sep | B5: Rain easing | C5: Medium | D5: Fair | E5: Possible late September
A6: Oct–Nov | B6: Clear, cool | C6: Medium; very high in Sharad Navratri | D6: Good | E6: Recommended (avoid Navratri week)
A7: Dec–Feb | B7: Cold; snow possible at Bhairon; fog at Jammu | C7: Low, except New Year week | D7: Fair; fog delays | E7: Possible for hardy groups

Sheet Team & Contacts
A1: Role / contact | B1: Responsibility / notes | C1: Name | D1: Phone
A2: Tour leader | B2: Day plan, head counts, tickets, vendor coordination, backup decisions
A3: Assistant / escort | B3: Seniors and slow walkers; rear of group; second document set
A4: Yatra coordinator (Hyderabad) | B4: Bookings, changes, escalation
A5: Kirtan / spiritual lead | B5: Kirtan, japa, katha at halts and evenings
A6: SMVDSB helpline | B6: Take from official SMVDSB website
A7: Helicopter operator, Katra | B7: From the ticket
A8: Hotel, Jammu (Days 1 and 3)
A9: Driver(s)
A10: Hospital, Katra
A11: Hospital, Jammu
A12: Police / emergency | B12: National emergency number | D12: 112

Sheet Cost Heads
A1: Cost heads per yatri (₹)
A2: Fill the yellow cells from current quotes; totals recalculate. Example: Bhairon ropeway – enter the per-yatri ticket price.
A3: Package price: 3N/4D ₹50,000 per person + 5% GST, excluding flight charges
A4: Cost head | B4: Basis | C4: In package? | D4: Amount per yatri (₹)
A5: Flights / trains to and from Jammu | B5: Per yatri | C5: No – excluded from price
A6: Hotel Jammu, 2 nights (Days 1 and 3) | B6: Twin sharing | C6: Yes
A7: Bhawan accommodation, 1 night | B7: Per bed / room | C7: Yes
A8: Helicopter Katra ⇄ Sanjichhat | B8: Per yatri, both ways | C8: Yes
A9: Battery car Sanjichhat → Bhawan | B9: Per yatri | C9: Yes
A10: Bhairon ropeway | B10: Per yatri | C10: Yes
A11: Atka Aarti passes | B11: Per yatri | C11: Yes
A12: Vehicles, 4 days (149 km + waiting) | B12: Per vehicle, split by seats | C12: Yes
A13: All meals, Day 1 lunch to Day 4 breakfast | B13: Per yatri | C13: Yes
A14: Travel insurance | B14: Per yatri | C14: Yes
A15: Tour leader and assistant costs | B15: Split across yatris | C15: Yes
A16: Subtotal (items in package) | D16: =SUMIF(C5:C15,"Yes",D5:D15) -> 0
A17: Contingency % | B17: Assumption: 5–10% for helicopter rebooking and delays | D17: 0.05
A18: Package cost per yatri | D18: =D16*(1+D17) -> 0
A20: Not included: flights, shopping, personal offerings, tips.

Sheet Open Points
A1: Point to confirm | B1: Status (fill in)
A2: Every yatri's arrival in Jammu by 14:00 on Day 1, and departure flight / train times on Day 4
A3: Helicopter slots booked on 1 Jan 2027 for Day 2 and Day 3 + reporting time
A4: Helicopter baggage limit per yatri; main luggage stays at the Jammu hotel on Day 2
A5: Bhawan accommodation booked for Day 2 night
A6: Atka Aarti passes – availability and booking window
A7: Bhairon ropeway tickets; Sanjichhat → Bhawan battery car
A8: Jammu hotel fixed for Days 1 and 3; replace area map links with exact hotel pins
A9: Verify every car km and drive time on Google Maps
A10: Escorts for seniors on the Day 3 downhill track (Bhairon → Sanjichhat)
A11: Weather back-up if helicopter is grounded
