Workbook

Sheet Dashboard
A1: MKCD - Visa & Travel Dashboard
A2: Living workbook: edit the yellow cells / add rows; everything else recalculates.
A4: Item | B4: Value | C4: Comment
A5: Today | B5: =TODAY() | C5: Auto
A6: Passport expires | B6: ='Visas Held'!$B$14 | C6: Indian passport
A7: Days to passport expiry | B7: ='Visas Held'!$B$16
A8: Last safe travel date (6-month rule) | B8: ='Visas Held'!$B$17 | C8: Most countries need 6 months validity
A9: Start passport renewal by | B9: ='Visas Held'!$B$18
A10: USA B1/B2 - valid until | B10: ='Visas Held'!$E$5 | C10: Used Sep 2025
A11: USA B1/B2 - days left | B11: ='Visas Held'!$E$5-TODAY()
A12: Australia visitor - valid until | B12: ='Visas Held'!$E$6 | C12: Business Visitor stream - check before pilgrimage use
A13: Australia - days left | B13: ='Visas Held'!$E$6-TODAY()
A14: Countries visited (stamp-verified) | B14: =COUNTIF('Country Summary'!B5:B17,">0") | C14: Includes Schengen countries visited Jul 2024
A15: Total international visits logged | B15: ='Country Summary'!B19 | C15: Each entry = one visit
A16: Visits to most-visited country | B16: =MAX('Country Summary'!B5:B17)
A17: Destinations reachable NOW via visa privileges | B17: =COUNTIF('Access Map'!N5:N40,"YES") | C17: Excludes visa-free countries for Indians; see Access Map
A18: Valid visas right now | B18: =COUNTIF('Visas Held'!H5:H30,"VALID")
A19: Expired visas to renew | B19: =COUNTIF('Visas Held'!H5:H30,"EXPIRED") | C19: Schengen & UK
A21: Top actions
A22: Passport expires 17 Sep 2028 | C22: Most countries need 6 months validity -> practical last safe travel date ~17 Mar 2028. Start renewal ~Sep 2027. Passports issued in India are e-passports since 28 May 2025. Keep old passport: US & Australia visas stay valid but must be carried; tell Australia Home Affairs new passport number (ImmiAccount).
A23: Schengen: no valid visa | C23: Both France visas expired (Apr 2026). You now have 2 lawful visas in 3 years -> eligible for the EU 'cascade' 2-year multiple-entry visa. Apply 3 months before the next Europe yatra.
A24: UK: no valid visa | C24: UK visa expired 29 Dec 2024. Apply 3-4 weeks ahead; consider a 2-year or 5-year Standard Visitor visa if you will return often.
A25: Australia: confirm stream | C25: Visa is Business Visitor stream (condition 8115). A pilgrimage yatra with devotees may count as tourism - confirm whether to apply for a Tourist-stream visa.
A26: Malaysia visa-free ends 31 Dec 2026 | C26: Get visa/e-visa for any 2027 Malaysia yatra unless extended.

Sheet Travel Log
A1: Travel Log - stamp-verified international trips
A2: Source: passport scan (Nov 2025). Add new rows at the bottom; Days & Country Summary update automatically. Yellow = please confirm.
A4: # | B4: Country | C4: Entry date | D4: Exit date | E4: Days (incl.) | F4: Type | G4: Entry point | H4: Exit point | I4: Visa / permit used | J4: Evidence (passport page) | K4: Confidence | L4: Notes
A5: 1 | B5: Nepal | D5: 43531 | E5: =IF(AND(ISNUMBER(C5),ISNUMBER(D5)),D5-C5+1,"") | F5: Visit | G5: (entry stamp not in this passport) | H5: Tribhuvan Intl, Kathmandu | I5: No visa needed (Indian PP) | J5: Passport p.3: Nepal departed + India arrival New Delhi 07 Mar 2019 | K5: Check | L5: Entry date unknown - add from old passport/tickets
A6: 2 | B6: Nepal | C6: 43600 | E6: =IF(AND(ISNUMBER(C6),ISNUMBER(D6)),D6-C6+1,"") | F6: Visit | G6: Nepal land/air entry | H6: (exit stamp not in this passport) | I6: No visa needed | J6: Passport p.3: India departed New Delhi 15 May 2019, Nepal arrived 15 May 2019 | K6: High | L6: Return date unknown - add
A7: 3 | B7: Sri Lanka | C7: 43736 | D7: 43745 | E7: =IF(AND(ISNUMBER(C7),ISNUMBER(D7)),D7-C7+1,"") | F7: Visit | G7: Colombo (BIA) | H7: Colombo (BIA) -> Madurai | I7: ETA 30-day, 1st visit (exp 28/10/2019) | J7: Passport p.5/p.9: SL permitted 28 Sep 2019; embarked 07 Oct 2019; India arrival Madurai 07 Oct 2019 | K7: High | L7: India departure New Delhi 27 Sep 2019
A8: 4 | B8: Sri Lanka | C8: 43816 | D8: 43828 | E8: =IF(AND(ISNUMBER(C8),ISNUMBER(D8)),D8-C8+1,"") | F8: Visit | G8: Colombo (BIA) | H8: Colombo (BIA) -> Hyderabad | I8: ETA 30-day, 1st visit (exp 16/01/2020) | J8: Passport p.4: India dep. RGI Hyderabad 17 Dec 2019; SL departure + India arrival RGI 29 Dec 2019 | K8: High
A9: 5 | B9: Sri Lanka | C9: 44585 | D9: 44592 | E9: =IF(AND(ISNUMBER(C9),ISNUMBER(D9)),D9-C9+1,"") | F9: Visit | G9: Colombo (BIA) | H9: Colombo (BIA) -> Chennai | I9: ETA 30-day, 1st visit (exp 23/02/2022) | J9: Passport p.4/p.9: India dep. Chennai 24 Jan 2022; SL embarked 31 Jan 2022; India arrival Chennai 31 Jan 2022 | K9: High | L9: COVID-era trip
A10: 6 | B10: Nepal | C10: 44665 | D10: 44672 | E10: =IF(AND(ISNUMBER(C10),ISNUMBER(D10)),D10-C10+1,"") | F10: Visit | G10: Nepal (arrived 14 Apr 2022) | H10: Tribhuvan Intl, Kathmandu -> Bengaluru | I10: No visa needed | J10: Passport p.6/p.7/p.9: India dep. New Delhi 14 Apr 2022; Nepal departed 21 Apr 2022; India arrival Bengaluru 21 Apr 2022 | K10: High
A11: 7 | B11: Thailand | C11: 44964 | D11: 44965 | E11: =IF(AND(ISNUMBER(C11),ISNUMBER(D11)),D11-C11+1,"") | F11: Visit | G11: Suvarnabhumi (BKK) | H11: Suvarnabhumi (BKK) | I11: Visa on Arrival (30 days) | J11: Passport p.7-8: Thai admitted 7 Feb 2023, departed 8 Feb 2023; India dep. Bengaluru 07 Feb 2023 | K11: High | L11: Connection/transit stop en route to Cambodia
A12: 8 | B12: Cambodia | C12: 44965 | D12: 44967 | E12: =IF(AND(ISNUMBER(C12),ISNUMBER(D12)),D12-C12+1,"") | F12: Visit | G12: Siem Reap (REP) | H12: Siem Reap (REP) | I12: e-Visa (valid to 07 Mar 2023) | J12: Passport p.10: Cambodia entry 08 Feb 2023, exit 10 Feb 2023 | K12: High
A13: 9 | B13: Thailand | C13: 44967 | D13: 44969 | E13: =IF(AND(ISNUMBER(C13),ISNUMBER(D13)),D13-C13+1,"") | F13: Visit | G13: Suvarnabhumi (BKK) | H13: Suvarnabhumi (BKK) -> Bengaluru | I13: Visa on Arrival (30 days) | J13: Passport p.8: Thai admitted 10 Feb 2023 (until 11 Mar), departed 12 Feb 2023; India arrival Bengaluru 12 Feb 2023 | K13: High
A14: 10 | B14: Thailand | C14: 45101 | D14: 45104 | E14: =IF(AND(ISNUMBER(C14),ISNUMBER(D14)),D14-C14+1,"") | F14: Visit | G14: Thailand (BKK) | H14: Thailand (BKK) | I14: Visa on Arrival | J14: Passport p.20-21: Thai VOA stamp admitted 2? Jun 2023 until 9 Jul 2023 (class TR-15 = 15 days -> 24 Jun); Thai departed 27 Jun 2023; India dep. RGI Hyderabad 24 Jun 2023 | K14: Check | L14: Day digit smudged; 24 Jun inferred from 15-day limit (9 Jul) + India departure 24 Jun
A15: 11 | B15: Cambodia | C15: 45104 | D15: 45107 | E15: =IF(AND(ISNUMBER(C15),ISNUMBER(D15)),D15-C15+1,"") | F15: Visit | G15: Siem Reap (REP) | H15: Siem Reap (REP) | I15: e-Visa (valid 27 Jun-26 Jul 2023) | J15: Passport p.20: Cambodia entry 27 Jun 2023, exit 30 Jun 2023 | K15: High | L15: India arrival RGI Hyderabad 01 Jul 2023 (return probably via Thailand)
A16: 12 | B16: France | C16: 45488 | D16: 45500 | E16: =IF(AND(ISNUMBER(C16),ISNUMBER(D16)),D16-C16+1,"") | F16: Visit | G16: Paris CDG | H16: Milan Malpensa (Italy) | I16: Schengen C visa #1 (France-issued, Pondicherry) | J16: Passport p.9/p.17: CDG stamp 15 Jul 2024; Malpensa stamp 27 Jul 2024; India dep. Mumbai 14 Jul 2024 | K16: High | L16: Schengen trip 15-27 Jul 2024 covering France, Belgium, Netherlands, Germany, Switzerland, Italy; France dates = whole-trip window, split per country when known
A17: 13 | B17: Belgium | E17: =IF(AND(ISNUMBER(C17),ISNUMBER(D17)),D17-C17+1,"") | F17: Visit | G17: By road/rail within Schengen (no stamp) | H17: By road/rail within Schengen (no stamp) | I17: Schengen C visa #1 | J17: Your confirmation (Oct 2026): visited during the 15-27 Jul 2024 Europe trip | K17: Check | L17: Dates unknown - within 15-27 Jul 2024; add from itinerary
A18: 14 | B18: Netherlands | E18: =IF(AND(ISNUMBER(C18),ISNUMBER(D18)),D18-C18+1,"") | F18: Visit | G18: By road/rail within Schengen (no stamp) | H18: By road/rail within Schengen (no stamp) | I18: Schengen C visa #1 | J18: Your confirmation (Oct 2026): visited during the 15-27 Jul 2024 Europe trip | K18: Check | L18: Dates unknown - within 15-27 Jul 2024; add from itinerary
A19: 15 | B19: Germany | E19: =IF(AND(ISNUMBER(C19),ISNUMBER(D19)),D19-C19+1,"") | F19: Visit | G19: By road/rail within Schengen (no stamp) | H19: By road/rail within Schengen (no stamp) | I19: Schengen C visa #1 | J19: Your confirmation (Oct 2026): visited during the 15-27 Jul 2024 Europe trip | K19: Check | L19: Dates unknown - within 15-27 Jul 2024; add from itinerary
A20: 16 | B20: Switzerland | E20: =IF(AND(ISNUMBER(C20),ISNUMBER(D20)),D20-C20+1,"") | F20: Visit | G20: By road/rail within Schengen (no stamp) | H20: By road/rail within Schengen (no stamp) | I20: Schengen C visa #1 | J20: Your confirmation (Oct 2026): visited during the 15-27 Jul 2024 Europe trip | K20: Check | L20: Dates unknown - within 15-27 Jul 2024; add from itinerary
A21: 17 | B21: Italy | D21: 45500 | E21: =IF(AND(ISNUMBER(C21),ISNUMBER(D21)),D21-C21+1,"") | F21: Visit | G21: By road/rail within Schengen (Rome visited) | H21: Milan Malpensa (MXP) -> London Gatwick | I21: Schengen C visa #1 | J21: Your confirmation (Oct 2026): Rome visited; Passport p.17: Malpensa exit stamp 27 Jul 2024 | K21: Check | L21: Entry date unknown - within 15-27 Jul 2024; departed Schengen from Milan
A22: 18 | B22: United Kingdom | C22: 45500 | E22: =IF(AND(ISNUMBER(C22),ISNUMBER(D22)),D22-C22+1,"") | F22: Visit | G22: London Gatwick | H22: (UK does not stamp exit) | I22: UK Standard Visitor C-visit, multiple, 29 Jun-29 Dec 2024 | J22: Passport p.23: Gatwick stamp 27 Jul 2024 | K22: High | L22: Left UK by 01 Aug 2024 (UAE entry)
A23: 19 | B23: UAE | C23: 45505 | E23: =IF(AND(ISNUMBER(C23),ISNUMBER(D23)),D23-C23+1,"") | F23: Visit | G23: Dubai Intl (DXB) | H23: (UAE does not stamp exit) | I23: Visa/entry per stamp (Indian PP) | J23: Passport p.10: UAE entry stamp 01 Aug 2024; India arrival RGI Hyderabad 05 Aug 2024 | K23: High | L23: Stayed up to ~4 days
A24: 20 | B24: USA | C24: 45904 | D24: 45930 | E24: =IF(AND(ISNUMBER(C24),ISNUMBER(D24)),D24-C24+1,"") | F24: Visit | G24: USA (CBP admitted 04 Sep 2025) | H24: USA -> Mumbai | I24: B1/B2 10-yr visa (admitted until 03 Mar 2026) | J24: Passport p.26 + p.10: India dep. New Delhi 03 Sep 2025; CBP stamp 04 Sep 2025; India arrival Mumbai 30 Sep 2025 | K24: High | L24: First use of US visa

Sheet Country Summary
A1: Countries visited - summary
A2: Counts rows of type 'Visit' in the Travel Log. Add a country name in column A and the rest fills in.
A4: Country | B4: Times visited | C4: First entry | D4: Latest entry | E4: Total days (known) | F4: Visa types used
A5: Belgium | B5: =COUNTIFS('Travel Log'!$B$5:$B$84,A5,'Travel Log'!$F$5:$F$84,"Visit") | C5: =IF(COUNTIFS('Travel Log'!$B$5:$B$84,A5,'Travel Log'!$C$5:$C$84,">0")=0,"",_xlfn.MINIFS('Travel Log'!$C$5:$C$84,'Travel Log'!$B$5:$B$84,A5,'Travel Log'!$C$5:$C$84,">0")) | D5: =IF(COUNTIFS('Travel Log'!$B$5:$B$84,A5,'Travel Log'!$C$5:$C$84,">0")=0,"",_xlfn.MAXIFS('Travel Log'!$C$5:$C$84,'Travel Log'!$B$5:$B$84,A5,'Travel Log'!$C$5:$C$84,">0")) | E5: =SUMIFS('Travel Log'!$E$5:$E$84,'Travel Log'!$B$5:$B$84,A5,'Travel Log'!$F$5:$F$84,"Visit") | F5: Schengen C visa #1
A6: Cambodia | B6: =COUNTIFS('Travel Log'!$B$5:$B$84,A6,'Travel Log'!$F$5:$F$84,"Visit") | C6: =IF(COUNTIFS('Travel Log'!$B$5:$B$84,A6,'Travel Log'!$C$5:$C$84,">0")=0,"",_xlfn.MINIFS('Travel Log'!$C$5:$C$84,'Travel Log'!$B$5:$B$84,A6,'Travel Log'!$C$5:$C$84,">0")) | D6: =IF(COUNTIFS('Travel Log'!$B$5:$B$84,A6,'Travel Log'!$C$5:$C$84,">0")=0,"",_xlfn.MAXIFS('Travel Log'!$C$5:$C$84,'Travel Log'!$B$5:$B$84,A6,'Travel Log'!$C$5:$C$84,">0")) | E6: =SUMIFS('Travel Log'!$E$5:$E$84,'Travel Log'!$B$5:$B$84,A6,'Travel Log'!$F$5:$F$84,"Visit") | F6: e-Visa (valid 27 Jun-26 Jul 2023); e-Visa (valid to 07 Mar 2023)
A7: France | B7: =COUNTIFS('Travel Log'!$B$5:$B$84,A7,'Travel Log'!$F$5:$F$84,"Visit") | C7: =IF(COUNTIFS('Travel Log'!$B$5:$B$84,A7,'Travel Log'!$C$5:$C$84,">0")=0,"",_xlfn.MINIFS('Travel Log'!$C$5:$C$84,'Travel Log'!$B$5:$B$84,A7,'Travel Log'!$C$5:$C$84,">0")) | D7: =IF(COUNTIFS('Travel Log'!$B$5:$B$84,A7,'Travel Log'!$C$5:$C$84,">0")=0,"",_xlfn.MAXIFS('Travel Log'!$C$5:$C$84,'Travel Log'!$B$5:$B$84,A7,'Travel Log'!$C$5:$C$84,">0")) | E7: =SUMIFS('Travel Log'!$E$5:$E$84,'Travel Log'!$B$5:$B$84,A7,'Travel Log'!$F$5:$F$84,"Visit") | F7: Schengen C visa #1 (France-issued, Pondicherry)
A8: Germany | B8: =COUNTIFS('Travel Log'!$B$5:$B$84,A8,'Travel Log'!$F$5:$F$84,"Visit") | C8: =IF(COUNTIFS('Travel Log'!$B$5:$B$84,A8,'Travel Log'!$C$5:$C$84,">0")=0,"",_xlfn.MINIFS('Travel Log'!$C$5:$C$84,'Travel Log'!$B$5:$B$84,A8,'Travel Log'!$C$5:$C$84,">0")) | D8: =IF(COUNTIFS('Travel Log'!$B$5:$B$84,A8,'Travel Log'!$C$5:$C$84,">0")=0,"",_xlfn.MAXIFS('Travel Log'!$C$5:$C$84,'Travel Log'!$B$5:$B$84,A8,'Travel Log'!$C$5:$C$84,">0")) | E8: =SUMIFS('Travel Log'!$E$5:$E$84,'Travel Log'!$B$5:$B$84,A8,'Travel Log'!$F$5:$F$84,"Visit") | F8: Schengen C visa #1
A9: Italy | B9: =COUNTIFS('Travel Log'!$B$5:$B$84,A9,'Travel Log'!$F$5:$F$84,"Visit") | C9: =IF(COUNTIFS('Travel Log'!$B$5:$B$84,A9,'Travel Log'!$C$5:$C$84,">0")=0,"",_xlfn.MINIFS('Travel Log'!$C$5:$C$84,'Travel Log'!$B$5:$B$84,A9,'Travel Log'!$C$5:$C$84,">0")) | D9: =IF(COUNTIFS('Travel Log'!$B$5:$B$84,A9,'Travel Log'!$C$5:$C$84,">0")=0,"",_xlfn.MAXIFS('Travel Log'!$C$5:$C$84,'Travel Log'!$B$5:$B$84,A9,'Travel Log'!$C$5:$C$84,">0")) | E9: =SUMIFS('Travel Log'!$E$5:$E$84,'Travel Log'!$B$5:$B$84,A9,'Travel Log'!$F$5:$F$84,"Visit") | F9: Schengen C visa #1
A10: Nepal | B10: =COUNTIFS('Travel Log'!$B$5:$B$84,A10,'Travel Log'!$F$5:$F$84,"Visit") | C10: =IF(COUNTIFS('Travel Log'!$B$5:$B$84,A10,'Travel Log'!$C$5:$C$84,">0")=0,"",_xlfn.MINIFS('Travel Log'!$C$5:$C$84,'Travel Log'!$B$5:$B$84,A10,'Travel Log'!$C$5:$C$84,">0")) | D10: =IF(COUNTIFS('Travel Log'!$B$5:$B$84,A10,'Travel Log'!$C$5:$C$84,">0")=0,"",_xlfn.MAXIFS('Travel Log'!$C$5:$C$84,'Travel Log'!$B$5:$B$84,A10,'Travel Log'!$C$5:$C$84,">0")) | E10: =SUMIFS('Travel Log'!$E$5:$E$84,'Travel Log'!$B$5:$B$84,A10,'Travel Log'!$F$5:$F$84,"Visit") | F10: No visa needed; No visa needed (Indian PP)
A11: Netherlands | B11: =COUNTIFS('Travel Log'!$B$5:$B$84,A11,'Travel Log'!$F$5:$F$84,"Visit") | C11: =IF(COUNTIFS('Travel Log'!$B$5:$B$84,A11,'Travel Log'!$C$5:$C$84,">0")=0,"",_xlfn.MINIFS('Travel Log'!$C$5:$C$84,'Travel Log'!$B$5:$B$84,A11,'Travel Log'!$C$5:$C$84,">0")) | D11: =IF(COUNTIFS('Travel Log'!$B$5:$B$84,A11,'Travel Log'!$C$5:$C$84,">0")=0,"",_xlfn.MAXIFS('Travel Log'!$C$5:$C$84,'Travel Log'!$B$5:$B$84,A11,'Travel Log'!$C$5:$C$84,">0")) | E11: =SUMIFS('Travel Log'!$E$5:$E$84,'Travel Log'!$B$5:$B$84,A11,'Travel Log'!$F$5:$F$84,"Visit") | F11: Schengen C visa #1
A12: Sri Lanka | B12: =COUNTIFS('Travel Log'!$B$5:$B$84,A12,'Travel Log'!$F$5:$F$84,"Visit") | C12: =IF(COUNTIFS('Travel Log'!$B$5:$B$84,A12,'Travel Log'!$C$5:$C$84,">0")=0,"",_xlfn.MINIFS('Travel Log'!$C$5:$C$84,'Travel Log'!$B$5:$B$84,A12,'Travel Log'!$C$5:$C$84,">0")) | D12: =IF(COUNTIFS('Travel Log'!$B$5:$B$84,A12,'Travel Log'!$C$5:$C$84,">0")=0,"",_xlfn.MAXIFS('Travel Log'!$C$5:$C$84,'Travel Log'!$B$5:$B$84,A12,'Travel Log'!$C$5:$C$84,">0")) | E12: =SUMIFS('Travel Log'!$E$5:$E$84,'Travel Log'!$B$5:$B$84,A12,'Travel Log'!$F$5:$F$84,"Visit") | F12: ETA 30-day, 1st visit (exp 16/01/2020); ETA 30-day, 1st visit (exp 23/02/2022); ETA 30-day, 1st visit (exp 28/10/2019)
A13: Switzerland | B13: =COUNTIFS('Travel Log'!$B$5:$B$84,A13,'Travel Log'!$F$5:$F$84,"Visit") | C13: =IF(COUNTIFS('Travel Log'!$B$5:$B$84,A13,'Travel Log'!$C$5:$C$84,">0")=0,"",_xlfn.MINIFS('Travel Log'!$C$5:$C$84,'Travel Log'!$B$5:$B$84,A13,'Travel Log'!$C$5:$C$84,">0")) | D13: =IF(COUNTIFS('Travel Log'!$B$5:$B$84,A13,'Travel Log'!$C$5:$C$84,">0")=0,"",_xlfn.MAXIFS('Travel Log'!$C$5:$C$84,'Travel Log'!$B$5:$B$84,A13,'Travel Log'!$C$5:$C$84,">0")) | E13: =SUMIFS('Travel Log'!$E$5:$E$84,'Travel Log'!$B$5:$B$84,A13,'Travel Log'!$F$5:$F$84,"Visit") | F13: Schengen C visa #1
A14: Thailand | B14: =COUNTIFS('Travel Log'!$B$5:$B$84,A14,'Travel Log'!$F$5:$F$84,"Visit") | C14: =IF(COUNTIFS('Travel Log'!$B$5:$B$84,A14,'Travel Log'!$C$5:$C$84,">0")=0,"",_xlfn.MINIFS('Travel Log'!$C$5:$C$84,'Travel Log'!$B$5:$B$84,A14,'Travel Log'!$C$5:$C$84,">0")) | D14: =IF(COUNTIFS('Travel Log'!$B$5:$B$84,A14,'Travel Log'!$C$5:$C$84,">0")=0,"",_xlfn.MAXIFS('Travel Log'!$C$5:$C$84,'Travel Log'!$B$5:$B$84,A14,'Travel Log'!$C$5:$C$84,">0")) | E14: =SUMIFS('Travel Log'!$E$5:$E$84,'Travel Log'!$B$5:$B$84,A14,'Travel Log'!$F$5:$F$84,"Visit") | F14: Visa on Arrival; Visa on Arrival (30 days)
A15: UAE | B15: =COUNTIFS('Travel Log'!$B$5:$B$84,A15,'Travel Log'!$F$5:$F$84,"Visit") | C15: =IF(COUNTIFS('Travel Log'!$B$5:$B$84,A15,'Travel Log'!$C$5:$C$84,">0")=0,"",_xlfn.MINIFS('Travel Log'!$C$5:$C$84,'Travel Log'!$B$5:$B$84,A15,'Travel Log'!$C$5:$C$84,">0")) | D15: =IF(COUNTIFS('Travel Log'!$B$5:$B$84,A15,'Travel Log'!$C$5:$C$84,">0")=0,"",_xlfn.MAXIFS('Travel Log'!$C$5:$C$84,'Travel Log'!$B$5:$B$84,A15,'Travel Log'!$C$5:$C$84,">0")) | E15: =SUMIFS('Travel Log'!$E$5:$E$84,'Travel Log'!$B$5:$B$84,A15,'Travel Log'!$F$5:$F$84,"Visit") | F15: Visa/entry per stamp (Indian PP)
A16: USA | B16: =COUNTIFS('Travel Log'!$B$5:$B$84,A16,'Travel Log'!$F$5:$F$84,"Visit") | C16: =IF(COUNTIFS('Travel Log'!$B$5:$B$84,A16,'Travel Log'!$C$5:$C$84,">0")=0,"",_xlfn.MINIFS('Travel Log'!$C$5:$C$84,'Travel Log'!$B$5:$B$84,A16,'Travel Log'!$C$5:$C$84,">0")) | D16: =IF(COUNTIFS('Travel Log'!$B$5:$B$84,A16,'Travel Log'!$C$5:$C$84,">0")=0,"",_xlfn.MAXIFS('Travel Log'!$C$5:$C$84,'Travel Log'!$B$5:$B$84,A16,'Travel Log'!$C$5:$C$84,">0")) | E16: =SUMIFS('Travel Log'!$E$5:$E$84,'Travel Log'!$B$5:$B$84,A16,'Travel Log'!$F$5:$F$84,"Visit") | F16: B1/B2 10-yr visa (admitted until 03 Mar 2026)
A17: United Kingdom | B17: =COUNTIFS('Travel Log'!$B$5:$B$84,A17,'Travel Log'!$F$5:$F$84,"Visit") | C17: =IF(COUNTIFS('Travel Log'!$B$5:$B$84,A17,'Travel Log'!$C$5:$C$84,">0")=0,"",_xlfn.MINIFS('Travel Log'!$C$5:$C$84,'Travel Log'!$B$5:$B$84,A17,'Travel Log'!$C$5:$C$84,">0")) | D17: =IF(COUNTIFS('Travel Log'!$B$5:$B$84,A17,'Travel Log'!$C$5:$C$84,">0")=0,"",_xlfn.MAXIFS('Travel Log'!$C$5:$C$84,'Travel Log'!$B$5:$B$84,A17,'Travel Log'!$C$5:$C$84,">0")) | E17: =SUMIFS('Travel Log'!$E$5:$E$84,'Travel Log'!$B$5:$B$84,A17,'Travel Log'!$F$5:$F$84,"Visit") | F17: UK Standard Visitor C-visit, multiple, 29 Jun-29 Dec 2024
A19: TOTAL | B19: =SUM(B5:B17) | E19: =SUM(E5:E17)
A21: Schengen trip 15-27 Jul 2024: France (entry CDG), Belgium, Netherlands, Germany, Switzerland, Italy/Rome (exit Milan) - internal borders are not stamped, so per-country dates are blank until you add them.

Sheet Visas Held
A1: Visas I hold / have held
A2: Status, days left and warnings are formulas based on TODAY().
A4: Visa | B4: Country / area | C4: Category | D4: Valid from | E4: Valid to | F4: Entries | G4: Stay allowed | H4: Status (auto) | I4: Days left (auto) | J4: Used? | K4: Notes / conditions | L4: Source
A5: USA B1/B2 Visitor | B5: United States | C5: B1/B2, 10 yrs | D5: 45657 | E5: 49304 | F5: Multiple | G5: Up to 6 months per admission (set by CBP) | H5: =IF(E5<TODAY(),"EXPIRED",IF(E5-TODAY()<180,"EXPIRING SOON","VALID")) | I5: =E5-TODAY() | J5: Used once (Sep 2025) | K5: Used once (Sep 2025) | Ref: Control no. ...0010 / foil V2775359 | L5: Passport p.26 + your Visa sheet
A6: Australia Visitor (subclass 600) | B6: Australia | C6: Business Visitor stream | D6: 45974 | E6: 47800 | F6: Multiple | G6: 3 months per arrival | H6: =IF(E6<TODAY(),"EXPIRED",IF(E6-TODAY()<180,"EXPIRING SOON","VALID")) | I6: =E6-TODAY() | J6: Not yet used (as per records) | K6: Not yet used (as per records) - conditions 8115 (business-visitor activity only), 8201 (max 3 months study) | Ref: Doc no. matches passport (VEVO) | L6: VEVO check 13 Nov 2025
A7: Schengen C (France) #1 | B7: Schengen area | C7: Arts/Science/Sport (cultural) | D7: 45488 | E7: 45533 | F7: Multiple | G7: 30 days | H7: =IF(E7<TODAY(),"EXPIRED",IF(E7-TODAY()<180,"EXPIRING SOON","VALID")) | I7: =E7-TODAY() | J7: Used Jul 2024 (France->Italy) | L7: Passport p.17
A8: Schengen C (France) #2 | B8: Schengen area | C8: Arts/Science/Sport (cultural) | D8: 45951 | E8: 46131 | F8: Multiple | G8: 30 days | H8: =IF(E8<TODAY(),"EXPIRED",IF(E8-TODAY()<180,"EXPIRING SOON","VALID")) | I8: =E8-TODAY() | J8: Expired 19 Apr 2026 | L8: Passport p.18
A9: UK Standard Visitor | B9: United Kingdom | C9: C-visit, 180 days, no work | D9: 45472 | E9: 45655 | F9: Multiple | G9: up to 6 months per visit | H9: =IF(E9<TODAY(),"EXPIRED",IF(E9-TODAY()<180,"EXPIRING SOON","VALID")) | I9: =E9-TODAY() | J9: Used Jul 2024; expired 29 Dec 2024 | L9: Passport p.23
A11: PASSPORT
A12: Document | B12: Indian ordinary passport (36 pages)
A13: Issued | B13: 43361
A14: Expires | B14: 47013
A15: Place of issue | B15: Hyderabad
A16: Days to expiry | B16: =B14-TODAY()
A17: 6-month rule date | B17: =EDATE(B14,-6)
A18: Start renewal by | B18: =EDATE(B14,-12)
A19: Old passport (issued 15/10/2008, Bangalore) not supplied - earlier travel not captured.

Sheet Access Map
A1: Access Map - where a third-country visa replaces a separate visa (Indian passport)
A2: Row 3: set each document to Yes/No (Yes = you hold it today). Column K then shows where you can go NOW. Cell text = condition to check.
F3: I hold -> | G3: Yes | H3: No | I3: No | J3: No | K3: No | L3: Yes | M3: No
A4: Country / territory | B4: Region | C4: What you get | D4: Stay | E4: Notes | F4: Confidence | G4: USA B1/B2 visa | H4: Schengen C visa (multi-entry) | I4: UK Standard Visitor visa | J4: Canada visitor visa (TRV) | K4: Japan visa | L4: Australia Visitor visa | M4: Singapore visa | N4: Usable NOW?
A5: Mexico | B5: Americas | C5: Visa exempt | D5: up to 180 d | E5: Australia NOT accepted. US visa is the safe one. | F5: Researched | G5: Yes | H5: Yes - often refused w/o residence proof | I5: Yes - often refused w/o residence proof | J5: Yes | K5: Yes - often refused w/o residence proof | N5: =IF(SUMPRODUCT(--($G$3:$M$3="Yes"),--(G5:M5<>""))>0,"YES","-")
A6: Costa Rica | B6: Americas | C6: Visa exempt | D6: ~30-90 d | E6: Transit (C1-C3) US visas excluded | F6: Researched | G6: Yes - multiple-entry; valid on entry | H6: Yes - C multi-entry/D; 90 d validity left | J6: Yes - multiple-entry | N6: =IF(SUMPRODUCT(--($G$3:$M$3="Yes"),--(G6:M6<>""))>0,"YES","-")
A7: Panama | B7: Americas | C7: Visa exempt | D7: 30 d | E7: Your Aus visa is UNUSED so not yet valid for this | F7: Researched | G7: Yes - used once; >=1 yr validity left | H7: Yes - used once; >=1 yr left | I7: Yes - used once; >=1 yr left | J7: Yes - used once; >=1 yr left | K7: Yes - used once; >=1 yr left | L7: Yes - used once; >=1 yr left | N7: =IF(SUMPRODUCT(--($G$3:$M$3="Yes"),--(G7:M7<>""))>0,"YES","-")
A8: Belize | B8: Americas | C8: VoA / exempt | D8: 90 d (Schengen) | F8: Researched | G8: Yes - multiple-entry | H8: Yes | J8: Yes - multiple-entry | N8: =IF(SUMPRODUCT(--($G$3:$M$3="Yes"),--(G8:M8<>""))>0,"YES","-")
A9: Guatemala | B9: Americas | C9: Visa exempt | D9: 90 d | E9: Sources conflict (some list e-Visa) - confirm | F9: CONFIRM | G9: Yes | H9: Yes | J9: Yes | N9: =IF(SUMPRODUCT(--($G$3:$M$3="Yes"),--(G9:M9<>""))>0,"YES","-")
A10: Honduras | B10: Americas | C10: Visa exempt | D10: 90 d | F10: Researched | G10: Yes | H10: Yes | J10: Yes | N10: =IF(SUMPRODUCT(--($G$3:$M$3="Yes"),--(G10:M10<>""))>0,"YES","-")
A11: Dominican Republic | B11: Americas | C11: Tourist card on arrival (~US$10) | D11: ~30 d | F11: Researched | G11: Yes - multiple-entry, in passport | H11: Yes - multiple-entry | I11: Yes - multiple-entry | J11: Yes - multiple-entry | N11: =IF(SUMPRODUCT(--($G$3:$M$3="Yes"),--(G11:M11<>""))>0,"YES","-")
A12: Colombia | B12: Americas | C12: Visa exempt | D12: 90 d | E12: Resolution 0439/2016 via Indian Embassy Bogota | F12: Researched | G12: Yes - not C1; >=180 d validity left | H12: Yes - >=180 d validity left | N12: =IF(SUMPRODUCT(--($G$3:$M$3="Yes"),--(G12:M12<>""))>0,"YES","-")
A13: Peru | B13: Americas | C13: Visa exempt | D13: up to 180 d / 365 | E13: Australia works | F13: Researched | G13: Yes - >=6 mo validity left | H13: Yes | I13: Yes | J13: Yes | L13: Yes - >=6 mo validity left | N13: =IF(SUMPRODUCT(--($G$3:$M$3="Yes"),--(G13:M13<>""))>0,"YES","-")
A14: Chile | B14: Americas | C14: Visa exempt | D14: - | F14: Researched | G14: Yes - not transit C; >=6 mo validity | N14: =IF(SUMPRODUCT(--($G$3:$M$3="Yes"),--(G14:M14<>""))>0,"YES","-")
A15: Argentina | B15: Americas | C15: Visa-free tourism (Res. 353/2025) | D15: 90 d (one notice: 30 d) | E15: Wikipedia's 'Apr 2026' note looks wrong | F15: Researched | G15: Yes - B2 etc.; insurance required | N15: =IF(SUMPRODUCT(--($G$3:$M$3="Yes"),--(G15:M15<>""))>0,"YES","-")
A16: Aruba / Curacao / Bonaire / Sint Maarten | B16: Caribbean | C16: Visa exempt | D16: ~30 d | E16: Single-entry visas do NOT qualify | F16: Researched | G16: Yes - multiple-entry only | H16: Yes - multiple-entry only | I16: Yes - multiple-entry only | J16: Yes - multiple-entry only | N16: =IF(SUMPRODUCT(--($G$3:$M$3="Yes"),--(G16:M16<>""))>0,"YES","-")
A17: Bahamas | B17: Caribbean | C17: VoA | D17: up to 3 mo | E17: Otherwise eVisa | F17: Researched | G17: Yes | H17: Yes | I17: Yes | J17: Yes | N17: =IF(SUMPRODUCT(--($G$3:$M$3="Yes"),--(G17:M17<>""))>0,"YES","-")
A18: Antigua & Barbuda | B18: Caribbean | C18: VoA (US$100) | D18: 30 d | F18: Researched | G18: Yes | H18: Yes | I18: Yes | J18: Yes | N18: =IF(SUMPRODUCT(--($G$3:$M$3="Yes"),--(G18:M18<>""))>0,"YES","-")
A19: Albania | B19: Europe (non-Schengen) | C19: Visa exempt | D19: 90 d | E19: Otherwise eVisa | F19: Researched | G19: Yes - multi-entry, used once | H19: Yes - multi-entry, used once in Schengen | I19: Yes - multi-entry, used once | N19: =IF(SUMPRODUCT(--($G$3:$M$3="Yes"),--(G19:M19<>""))>0,"YES","-")
A20: Montenegro | B20: Europe (non-Schengen) | C20: Visa exempt | D20: 30 d | E20: Australia works | F20: Researched | G20: Yes | H20: Yes | I20: Yes | J20: Yes | K20: Yes | L20: Yes | N20: =IF(SUMPRODUCT(--($G$3:$M$3="Yes"),--(G20:M20<>""))>0,"YES","-")
A21: Serbia | B21: Europe (non-Schengen) | C21: Visa exempt | D21: 90 d / 180 | E21: Blogs add multi-entry/used-once conditions | F21: Researched | G21: Yes | H21: Yes | I21: Yes | N21: =IF(SUMPRODUCT(--($G$3:$M$3="Yes"),--(G21:M21<>""))>0,"YES","-")
A22: North Macedonia | B22: Europe (non-Schengen) | C22: Visa exempt | D22: 15 d | E22: Onward ticket needed | F22: Researched | G22: Yes - visa physically in passport | H22: Yes - multi-entry C | I22: Yes | J22: Yes | N22: =IF(SUMPRODUCT(--($G$3:$M$3="Yes"),--(G22:M22<>""))>0,"YES","-")
A23: Bosnia & Herzegovina | B23: Europe (non-Schengen) | C23: Visa exempt | D23: up to 6 mo (your old sheet said 30 d) | F23: Researched | G23: Yes - multi-entry | H23: Yes - multi-entry | N23: =IF(SUMPRODUCT(--($G$3:$M$3="Yes"),--(G23:M23<>""))>0,"YES","-")
A24: Georgia | B24: Caucasus | C24: Visa exempt | D24: 90 d / 180 | E24: Otherwise eVisa 30 d. Australia works | F24: Researched | G24: Yes | H24: Yes | I24: Yes | J24: Yes | K24: Yes | L24: Yes | N24: =IF(SUMPRODUCT(--($G$3:$M$3="Yes"),--(G24:M24<>""))>0,"YES","-")
A25: Moldova | B25: Europe (non-Schengen) | C25: Visa exempt | D25: 90 d | F25: Researched | G25: Yes - not transit | J25: Yes | N25: =IF(SUMPRODUCT(--($G$3:$M$3="Yes"),--(G25:M25<>""))>0,"YES","-")
A26: Armenia | B26: Caucasus | C26: VoA | D26: 90 d | E26: Australia works. (Your old sheet said UK visa 120 d - recheck) | F26: Researched | G26: Yes | H26: Yes | I26: Yes | J26: Yes | K26: Yes | L26: Yes | N26: =IF(SUMPRODUCT(--($G$3:$M$3="Yes"),--(G26:M26<>""))>0,"YES","-")
A27: Turkey | B27: Europe/Asia | C27: Conditional eVisa (single entry) | D27: ~30 d | E27: Australia NOT accepted | F27: Researched | G27: Yes | H27: Yes | I27: Yes | N27: =IF(SUMPRODUCT(--($G$3:$M$3="Yes"),--(G27:M27<>""))>0,"YES","-")
A28: Cyprus | B28: Europe | C28: Visa exempt (reported) | D28: - | E28: Only a Schengen claim found - confirm | F28: CONFIRM | H28: Yes - multi-entry C | N28: =IF(SUMPRODUCT(--($G$3:$M$3="Yes"),--(G28:M28<>""))>0,"YES","-")
A29: Ireland | B29: Europe | C29: Visa exempt via UK BIVS | D29: - | E29: US/Schengen give nothing | F29: Researched | I29: Yes - must first enter UK on a short-stay visa | N29: =IF(SUMPRODUCT(--($G$3:$M$3="Yes"),--(G29:M29<>""))>0,"YES","-")
A30: Gibraltar | B30: Europe | C30: Visa exempt | D30: - | E30: US/Aus give nothing | F30: Researched | H30: Yes - multi-entry | I30: Yes - >=6 mo validity | N30: =IF(SUMPRODUCT(--($G$3:$M$3="Yes"),--(G30:M30<>""))>0,"YES","-")
A31: UK (airside transit only) | B31: Europe | C31: DATV-exempt transit | D31: 24 h airside | E31: Landside transit w/o visa is discretionary | F31: Researched | G31: Yes - to/from USA | J31: Yes - to/from Canada | L31: Yes - to/from Australia | N31: =IF(SUMPRODUCT(--($G$3:$M$3="Yes"),--(G31:M31<>""))>0,"YES","-")
A32: UAE | B32: Middle East | C32: VoA | D32: 14 d (+14) | E32: Aus VISITOR visa NOT accepted (only Aus residence permits) | F32: Researched | G32: Yes | H32: Yes - EU/Schengen visa | I32: Yes | N32: =IF(SUMPRODUCT(--($G$3:$M$3="Yes"),--(G32:M32<>""))>0,"YES","-")
A33: Oman | B33: Middle East | C33: VoA / exempt | D33: 14 d | E33: Australia works | F33: Researched | G33: Yes | H33: Yes | I33: Yes | J33: Yes | K33: Yes | L33: Yes | N33: =IF(SUMPRODUCT(--($G$3:$M$3="Yes"),--(G33:M33<>""))>0,"YES","-")
A34: Saudi Arabia | B34: Middle East | C34: eVisa / VoA | D34: up to 90 d | E34: Aus NOT accepted | F34: Researched | G34: Yes - may need used-once | H34: Yes - may need used-once | I34: Yes - may need used-once | N34: =IF(SUMPRODUCT(--($G$3:$M$3="Yes"),--(G34:M34<>""))>0,"YES","-")
A35: Bahrain | B35: Middle East | C35: VoA / eVisa | D35: 14 d | E35: Aus NOT accepted | F35: Researched | G35: Yes - visit visa/Green Card | H35: Yes | I35: Yes | N35: =IF(SUMPRODUCT(--($G$3:$M$3="Yes"),--(G35:M35<>""))>0,"YES","-")
A36: Kuwait | B36: Middle East | C36: eVisa eligibility | D36: - | F36: Researched | G36: Yes | H36: Yes | I36: Yes | N36: =IF(SUMPRODUCT(--($G$3:$M$3="Yes"),--(G36:M36<>""))>0,"YES","-")
A37: Philippines | B37: Asia-Pacific | C37: Visa-free | D37: 30 d (vs 14 d normally) | E37: Australia works; 6 mo passport, return ticket | F37: Researched | G37: Yes | H37: Yes | I37: Yes | J37: Yes | K37: Yes | L37: Yes | M37: Yes | N37: =IF(SUMPRODUCT(--($G$3:$M$3="Yes"),--(G37:M37<>""))>0,"YES","-")
A38: Taiwan | B38: Asia-Pacific | C38: Travel Authorization Certificate | D38: 14 d (old 30 d outdated) | E38: Expired visas also count | F38: Researched | G38: Yes - even if expired <10 yrs | H38: Yes | I38: Yes | J38: Yes | K38: Yes | L38: Yes | N38: =IF(SUMPRODUCT(--($G$3:$M$3="Yes"),--(G38:M38<>""))>0,"YES","-")
A39: South Korea (transit) | B39: Asia-Pacific | C39: Visa-free B-2 transit | D39: up to 30 d, onward ticket | E39: Must continue to 3rd country | F39: Researched | G39: Yes | H39: Yes - European visa | J39: Yes | L39: Yes - checked via VEVO | N39: =IF(SUMPRODUCT(--($G$3:$M$3="Yes"),--(G39:M39<>""))>0,"YES","-")
A40: Singapore (transit) | B40: Asia-Pacific | C40: 96-hr visa-free transit | D40: 96 h | E40: Onward ticket required | F40: Researched | G40: Yes - >=1 mo validity | I40: Yes | J40: Yes | K40: Yes | L40: Yes | N40: =IF(SUMPRODUCT(--($G$3:$M$3="Yes"),--(G40:M40<>""))>0,"YES","-")
...

Sheet Power Visas
A1: Power visas - which visa unlocks the most
A2: Counts update automatically from the Access Map. 'Held?' follows the Yes/No switch on the Access Map (row 3).
A4: Rank | B4: Document | C4: Held now? | D4: Other countries unlocked (count) | E4: + Schengen-area countries | F4: Total reach | G4: Best for your yatras | H4: Recommendation
A5: 1 | B5: USA B1/B2 visa | C5: ='Access Map'!G3 | D5: =COUNTIF('Access Map'!G5:G40,"?*") | E5: 0 | F5: =D5+E5 | G5: USA yatras; Mexico, Colombia, Peru, Chile, Argentina, Dominican Rep., Gulf (UAE/Saudi/Bahrain/Oman), Balkans | H5: Keep. Already held to Dec 2034 - best value: Americas, Caribbean, Balkans, Gulf, Philippines, Taiwan. Remember: carry the passport that holds it.
A6: 2 | B6: Schengen C visa (multi-entry) | C6: ='Access Map'!H3 | D6: =COUNTIF('Access Map'!H5:H40,"?*") | E6: 29 | F6: =D6+E6 | G6: Europe yatras (Paris, Radhadesh, Mayapur-Europe tours) + Albania, Serbia, N. Macedonia, Bosnia, Georgia, Costa Rica, Dominican Rep. | H6: Renew NOW (expired Apr 2026). You qualify for the EU cascade 2-year multi-entry visa. 29 countries + ~20 extra destinations.
A7: 3 | B7: UK Standard Visitor visa | C7: ='Access Map'!I3 | D7: =COUNTIF('Access Map'!I5:I40,"?*") | E7: 0 | F7: =D7+E7 | G7: UK/Manor; Ireland; Gulf; Armenia; Georgia; Philippines; Taiwan | H7: Renew (expired Dec 2024). Ask for 2-year/longer visitor visa. Adds Ireland (via BIVS), Gulf, Armenia, Georgia, Mexico etc.
A8: 4 | B8: Australia Visitor visa | C8: ='Access Map'!L3 | D8: =COUNTIF('Access Map'!L5:L40,"?*") | E8: 0 | F8: =D8+E8 | G8: Australia; Philippines; Taiwan; Peru; Georgia; Armenia; Oman | H8: Held to Nov 2030 but it only helps in ~10 places (Philippines, Taiwan, Peru, Georgia, Armenia, Oman, Montenegro, Panama once used, SG/KR transit). Check stream (Business vs Tourist) before yatra.
A9: 5 | B9: Canada visitor visa (TRV) | C9: ='Access Map'!J3 | D9: =COUNTIF('Access Map'!J5:J40,"?*") | E9: 0 | F9: =D9+E9 | G9: Canada; Mexico; Costa Rica; Panama; Philippines | H9: Optional. Adds Mexico/Costa Rica/Panama/Peru-type exemptions that US already gives; real value = ISKCON Toronto + Canada itself.
A10: 6 | B10: Japan visa | C10: ='Access Map'!K3 | D10: =COUNTIF('Access Map'!K5:K40,"?*") | E10: 0 | F10: =D10+E10 | G10: Japan; Philippines; Taiwan; Georgia | H10: Low priority: only unlocks Mexico/Philippines/Taiwan/Georgia/Oman type entries which you mostly already get.
A12: Other multi-country / special-purpose visas worth tracking (unverified background knowledge unless marked)
B13: Visa | C13: What it covers | D13: Yatra relevance | E13: Priority | F13: Confidence
B14: Chinese visa | C14: Mainland China + enables Tibet/Kailash (needs Tibet permit + ATP) | D14: Kailash Mansarovar, Buddhist circuit; does NOT unlock other countries | E14: HIGH for Kailash | F14: V (see yatra sheet)
B15: GCC Grand Tours visa | C15: Planned single visa for UAE, Saudi, Oman, Qatar, Bahrain, Kuwait | D15: Gulf yatra/transit | E15: Watch - launch status unconfirmed | F15: U
B16: East Africa Tourist Visa (Kenya-Rwanda-Uganda) | C16: One visa for 3 countries (reported US$100); Kenya now needs eTA | D16: Nairobi/Kampala ISKCON temples | E16: Low | F16: U
B17: Schengen 2-yr / 5-yr (EU cascade) | C17: Same 29 countries but multi-year validity - you now qualify (2 Schengen visas within 3 yrs) | D17: All Europe yatras | E17: HIGH | F17: V
B18: UK 2-yr / 5-yr / 10-yr Standard Visitor | C18: Long-validity UK visa; unlocks Ireland via BIVS + ~15 other entries | D18: Manor/Ireland/Gulf | E18: HIGH | F18: V

Sheet Yatra Visa Planner
A1: Yatra Visa Planner - entry rules for an Indian passport (researched 20 Oct 2026)
A2: Confidence 'Confirm' = from background knowledge or conflicting reports: check the official portal before booking. Update 'My status' & 'Next action'.
A4: Destination | B4: Yatra use | C4: Entry requirement (Indian passport) | D4: Max stay | E4: Cost / lead time | F4: Helped by a visa I hold? | G4: Priority | H4: Confidence | I4: Source | J4: My status | K4: Next action / date
A5: Nepal | B5: Muktinath, Pashupatinath, Janakpur | C5: No visa. Valid passport or original Voter ID (Aadhaar conflicting - don't rely). Muktinath needs TIMS/ACAP permits via operator (U) | D5: No limit set for Indians | E5: Free / none | F5: n/a | G5: Done before x3 | H5: Researched | I5: happyfares.in 2026 | J5: To check
A6: Bhutan | B6: Monastery circuit | C6: No visa but Entry PERMIT via registered operator. SDF Nu 1,200/person/night (under 6 free, 6-12 half) | D6: Per permit | E6: SDF + operator | F6: n/a | G6: Medium | H6: Researched | I6: windhorsetours.com 2026 | J6: To check
A7: Sri Lanka | B7: Ramayana trail | C7: Free 30-day double-entry tourist ETA scheme reported from 25 May 2026 (still apply online at eta.gov.lk). End date unclear | D7: 30 days | E7: Free (reported) / 1-2 days | F7: n/a | G7: Done before x3 | H7: Researched | I7: traveltradejournal, newsonair 2026 | J7: To check
A8: Thailand | B8: Bangkok/Pattaya temples, Cambodia gateway | C8: Visa-exempt tourism. REPORTED cut from 60 to 30 days from 15 Sep 2026; TDAC arrival card within 3 days before arrival | D8: 30 days (+30 ext. discretionary) | E8: Free / TDAC online | F8: n/a | G8: Done before x3 | H8: Researched | I8: Khaleej Times, VisaVerge Sep 2026 | J8: To check
A9: Cambodia | B9: Angkor Wat | C9: e-Visa (about US$30, ~30 days) - from background knowledge | D9: ~30 days | E9: ~US$30 / 3-4 days | F9: n/a | G9: Done before x2 | H9: Confirm | I9: previous stamps p.10/p.20 | J9: To check
A10: Malaysia | B10: Batu Caves, KL temples | C10: Visa-free 30 days until 31 Dec 2026 (no extension seen) -> plan visa fallback for 2027 | D10: 30 days | E10: Free | F10: n/a | G10: Medium | H10: Researched | I10: theweek.in Dec 2024 | J10: To check
A11: Vietnam | B11: Cham temples, Angkor-route extension | C11: e-Visa valid 90 days; US$25 single / US$50 multiple; apply only at evisa.gov.vn | D11: Up to 90 days | E11: US$25-50 / ~3-5 days | F11: n/a | G11: Medium | H11: Researched | I11: wego 2026 | J11: To check
A12: Indonesia (Bali, Java) | B12: Hindu temples, Prambanan | C12: e-VOA IDR 500,000, 30 days (+1 ext.). Bali levy IDR 150,000 + digital arrival card. Confirm India on eligible list | D12: 30 days (+30) | E12: ~IDR 650k | F12: n/a | G12: Planned Feb 2026 | H12: Confirm | I12: wego 2026 | J12: To check
A13: Philippines | B13: Limited | C13: Visa-free 14 days (hotel, funds, onward ticket). Holders of valid US/Japan/AU/CA/Schengen/SG/UK visa get 30 days | D13: 14 days / 30 days with US or AU visa | E13: Free | F13: YES - your US visa or Australia visa | G13: Low | H13: Researched | I13: Philippine Consulate advisory 07-2025 | J13: To check
A14: Japan | B14: Buddhist/ISKCON centres | C14: Visa required: e-Visa/VFS route, fee Rs 500 + service charges (reported) | D14: Typically 15-90 days | E14: Rs 500 + VFS / 5-10 days | F14: n/a | G14: Medium | H14: Researched | I14: businesstoday Jul 2026 | J14: To check
A15: China (incl. Tibet / Kailash) | B15: Kailash Mansarovar | C15: Chinese visa (tourist: 4 working days; group visa via operator ~6 working days) + Tibet Travel Permit + ATP via Nepal; or MEA KMY lottery (kmy.gov.in, June-Aug, 1,000 pilgrims) | D15: Per permit | E15: MEA route ~Rs 2.1-3.3 lakh | F15: n/a | G15: HIGH (Kailash) | H15: Researched | I15: Tribune, businesstoday 2026 | J15: To check
A16: Hong Kong | B16: Transit hub | C16: Pre-Arrival Registration (PAR) online, up to 14 days; valid 6 months | D16: 14 days | E16: Free / minutes | F16: n/a | G16: Low | H16: Researched | I16: HK Immigration ID1023 | J16: To check
... A36: New Zealand | B36: ISKCON Auckland | C36: Visitor visa required (NZeTA not valid for Indians) (unverified) | D36: - | E36: - | F36: n/a | G36: Low | H36: Confirm | I36: not researched | J36: To check

Sheet To Confirm
A1: Trips in your dashboard with NO passport stamp yet
A2: Your spreadsheet shows these; the passport scan (to Nov 2025) doesn't. Confirm -> copy to Travel Log.
A4: Trip | B4: From | C4: To | D4: Where recorded | E4: Observation | F4: Action | G4: Confirmed? (Y/N)
A5: Europe (Schengen) | B5: 45934 | C5: 45947 | D5: Dashboard 'MKCD' column | E5: Schengen visa #2 only valid from 21 Oct 2025 - this window pre-dates it; likely moved to Nov | F5: Confirm
A6: Europe (Schengen) | B6: 45967 | C6: 45981 | D6: Dashboard 'MKCD' column | E6: Inside Schengen #2 validity (21 Oct 2025-19 Apr 2026); no stamp in Nov-2025 scan | F6: Confirm
A7: Sri Lanka (Ramayan Yatra) | B7: 46040 | C7: 46048 | D7: Dashboard 'MKCD' column | E7: Future relative to scan; confirm if done | F7: Confirm
A8: Australia (Yatra) | B8: 46063 | C8: 46072 | D8: Dashboard 'MKCD' column | E8: Visa granted 13 Nov 2025; would be FIRST Australia entry - confirm | F8: Confirm
A9: Bali, Indonesia | B9: 46074 | C9: 46080 | D9: Dashboard 'MKCD' column | E9: Confirm | F9: Confirm
A10: Nepal (Muktinath Yatra) | B10: 45592 | C10: 45598 | D10: Dashboard yatra column | E10: No 2024 Nepal stamp seen - may have been an escorted group yatra or not run | F10: Confirm
A11: Sri Lanka (Ramayan Yatra) | B11: 45627 | C11: 45633 | D11: Dashboard yatra column | E11: No Dec-2024 SL stamp in scan - confirm | F11: Confirm
A12: Thailand / Cambodia Yatra | B12: 45664 | C12: 45669 | D12: Dashboard yatra column | E12: No Jan-2025 stamp in scan - confirm | F12: Confirm
A13: Nepal (Muktinath Yatra) | B13: 45748 | C13: 45768 | D13: Dashboard yatra column | E13: No Apr-2025 stamp in scan - confirm | F13: Confirm
A14: OOS / BJ (domestic?) | B14: 45727 | C14: 45732 | D14: Dashboard 'MKCD' column | E14: Label unclear ('OOS'); probably out-of-station, not international | F14: Ignore?

Sheet Alerts
A1: Alerts & action items
A2: Review every month.
A4: Alert | B4: What to do
A5: Passport expires 17 Sep 2028 | B5: Most countries need 6 months validity -> practical last safe travel date ~17 Mar 2028. Start renewal ~Sep 2027. Passports issued in India are e-passports since 28 May 2025. Keep old passport: US & Australia visas stay valid but must be carried; tell Australia Home Affairs new passport number (ImmiAccount).
A6: Schengen: no valid visa | B6: Both France visas expired (Apr 2026). You now have 2 lawful visas in 3 years -> eligible for the EU 'cascade' 2-year multiple-entry visa. Apply 3 months before the next Europe yatra.
A7: UK: no valid visa | B7: UK visa expired 29 Dec 2024. Apply 3-4 weeks ahead; consider a 2-year or 5-year Standard Visitor visa if you will return often.
A8: Australia: confirm stream | B8: Visa is Business Visitor stream (condition 8115). A pilgrimage yatra with devotees may count as tourism - confirm whether to apply for a Tourist-stream visa.
A9: Malaysia visa-free ends 31 Dec 2026 | B9: Get visa/e-visa for any 2027 Malaysia yatra unless extended.
A10: Thailand now 30 days (from 15 Sep 2026, reported) | B10: Plan group stays accordingly; complete TDAC before arrival.
A12: Mismatches found between your sheets and the documents
A13: Schengen #1 duration | B13: Your 'Visa' tab says 45 days; the visa sticker says 30 days (valid 15-Jul-24 to 29-Aug-24).
A14: Schengen #2 duration | B14: Sticker: 30 days within 21-Oct-25 to 19-Apr-26 (your tab shows 180 = validity window, not stay).
A15: US visa stay | B15: Your tab shows 3,647 days = visa validity. Stay per entry is set by CBP at the port (I-94), not by the visa.
A16: Australia | B16: Your tab says 'Business'. VEVO confirms Business Visitor stream (conditions 8115/8201). Tourism/pilgrimage may need Tourist stream.
A17: Old access lists | B17: Armenia 'UK visa 120 days', Bosnia '30 days', Montenegro 'US 15 days', Turkey/Qatar/Kuwait entries were out of date - corrected in Access Map.
A18: Hong Kong / Barbados etc. | B18: Your 'Indian PP visa on arrival' rows were not re-researched except those listed in the Yatra Visa Planner. Treat as unverified.

Sheet Sources & Method
A1: Sources, method and change log
A3: Travel history: read from the 13-page passport scan 'as on November 2025' (stamps + visa stickers) and the VEVO check dated 13 Nov 2025. Faint stamps are marked 'Check'.
A4: Planned/other trips: from tabs 'ACTUAL-Main Updated Dashboard' and 'PLANNED' in 'MKCD 2026 - MY TRAVEL PLAN 2026.xlsx' - NOT proof of travel; listed under To Confirm.
A5: Entry rules: research on 20 Oct 2026 mostly from secondary sources (Wikipedia 'Visa requirements for Indian citizens', news, embassy PDFs). Some official sites (IRCC, Taiwan BOCA) would not load. Always verify on the official government portal before issuing tickets.
A6: Old passport (issued 2008) was not provided, so pre-2018 travel is not captured.
A7: Passport number is shown only in masked form in these files.
A8: Change log:
A9: 20-Oct-2026 - v1 created from the four uploaded files + research.
