Workbook

Sheet Guide
A1: Donor & Yatri Gift Items – Packing & Stock Register
A2: Hare Krishna Movement, Hyderabad • Storeroom / Warehouse • Nov 2026 – Oct 2027
A4: Purpose
B5: • Keep sufficient, well-packed stock of blessed items (prasadam, threads, tilak, photos, books, souvenirs) to be given to DONORS and to YATRIS who join our yatras.
B6: • This workbook tells the storeroom person HOW to pack each item, WHERE to store it, and records WHEN items were prepared & stored and HOW MUCH stock is left – every month.
A8: Sheets in this workbook
B9: Item Master | C9: Master list of every item: category, who gets it, recommended packing method, material spec, label text, shelf life, storage rack, reorder level. Edit here – all monthly sheets update automatically.
B10: Packing Guide | C10: Research-based comparison of packing options (zip-lock, sachets, containers, bottles, sleeves…), golden rules for oily/liquid items, packing-station SOP, label & batch-number format, rack layout, compliance notes.
B11: Kits | C11: Ready combinations: Yatri Welcome Kit, Donor kits by donation level, Birthday/Anniversary kit. Enter how many kits you plan – the sheet calculates items needed vs. stock available.
B12: Nov-2026 … Oct-2027 | C12: 12 monthly stock sheets. For each item: opening stock, up to 2 packing batches (date packed, date stored, batch no., qty), issued to donors / yatris / events, damaged, closing stock, physical count, variance, status, qty to pack next month. Monthly checklist at the bottom.
B13: Annual Summary | C13: Year view: closing stock every month, total packed and issued, average monthly use and a suggested reorder level. Choose a month at the top to see current stock & status.
B14: Distribution Register | C14: Who received what: date, donor/yatri name, phone, yatra/event, receipt no., kit given. Helps follow-up (Sankalpa video, thank-you call).
B15: Services | C15: Non-stock offerings (Sankalpa/Archana video, birthday cake, Kalyanam/Abhishekam booking, catering) and fresh prasadam (Sweet Pongal, Shayana / Baalya / Chappan Bhog) with packing guidance.
A17: Monthly routine for the storeroom person
B18: 1st of the month: open the month's sheet. Opening stock comes automatically from last month (physical count if entered, otherwise book closing). Only Nov-2026 opening is typed by hand.
B19: When you pack a batch: write Date Packed, Date Stored, Batch No. (format ITEMID-YYMM-01, e.g. TIL-2611-01) and Qty Packed. Use Batch 2 columns for a second batch in the same month.
B20: Every issue: record in Distribution Register; at month end total the issues into the Issued – Donors / Yatris / Events columns.
B21: Damaged, leaked, expired or returned items go into the Damaged / Expired column – never just remove them silently.
B22: Last working day: physically count every item, enter Physical Count. Investigate any Variance that is not zero.
B23: Check Status column: REORDER NOW / OUT OF STOCK items must be packed or ordered first. 'Qty to Pack Next Month' tells you how many.
B24: Tick the Monthly Checklist at the bottom of the sheet, sign, and get it verified by the in-charge.
A26: Colour legend
C27: Yellow cells – type here (dates, quantities, names, counts).
C28: Green cells – automatic formulas. Please do not overwrite.
C29: Status OK
C30: Status LOW – plan packing soon
C31: Status REORDER NOW – stock at or below reorder level
C32: Status OUT OF STOCK
A34: Notes & assumptions
B35: • Reorder levels and target stock in Item Master are suggested starting values. After 2–3 months, use 'Suggested Reorder Level' in Annual Summary to adjust them.
B36: • Packing costs are indicative per-unit estimates based on Indian wholesale marketplace listings (IndiaMart / TradeIndia, Oct 2026). Always take 3 quotes from local suppliers (e.g. Begum Bazar, Hyderabad) before bulk buying.
B37: • Donor kit levels in 'Kits' (₹ ranges) are examples – management can change the names, ranges and contents.
B38: • 'LP Set Combo' contents were not specified – please confirm and update its row in Item Master.
B39: • The first row of the Nov-2026 sheet and of the Distribution Register shows an EXAMPLE entry so the format is clear – overwrite it with real data.

Sheet Item Master
A1: Item Master – What we give, how we pack it, where we store it
A2: Edit names, packing, reorder & target levels here – the 12 monthly sheets, Kits and Annual Summary pick them up automatically.
A3: Yellow = editable inputs (reorder level, target stock, cost). Storage Location fills from the Storage Code (see Packing Guide → Rack layout).
A4: Item ID | B4: Item Name | C4: Category | D4: Given To | E4: Purpose / Description | F4: Unit of Issue | G4: Qty per Pack | H4: Recommended Packing | I4: Packing Material Specification | J4: Est. Packing Cost per Unit (₹) | K4: Label Must Show | L4: Shelf Life | M4: Storage Code | N4: Storage Location | O4: Storage & Handling Notes | P4: Reorder Level (Min Stock) | Q4: Target Stock (Max) | R4: Item Status | S4: Remarks
A5: THR | B5: Kalasha Thread (wrist thread) | C5: Kalasha & Yagna Prasadam | D5: Both | E5: Sacred thread from Kalasha – Abhishekams, Swathi Nakshatra, Narasimha Kalasha etc. Tied around the wrist for protection. | F5: Pouch | G5: 1 thread (30 cm) | H5: Zip-lock pouch + small printed insert card | I5: 2"x3" clear LDPE zip-lock, 50 micron; cut thread to 30 cm, coil neatly; insert 2"x2.5" card naming the Kalasha/Utsav & date | J5: 1 | K5: Item name, Kalasha/Utsav name, Batch No., Packed date | L5: 12 months | M5: R1 | N5: =IFERROR(VLOOKUP(M5,'Packing Guide'!$A$60:$B$66,2,FALSE()),"") -> Rack 1 – Prasadam & Edibles | O5: Keep dry. Bundle 50 pouches in one larger zip bag labelled with batch no. | P5: 300 | Q5: 600 | R5: Existing
A6: TIL | B6: Narasimha Yagna Tilak | C6: Kalasha & Yagna Prasadam | D6: Both | E6: Daily available from Vigna Vinaashaka Narasimha Yagna – Maha Prasadam tilak (yagna bhasma with ghee/oil). | F6: Container | G6: 5 g | H6: DOUBLE BARRIER: 5 g leak-proof PP screw-cap container → zip-lock pouch | I6: 5 g PP container with inner wad/plug; fill only 80%; wipe rim; tape cap; then 2"x3" zip-lock 60 micron. Alternative: heat-sealed laminated sachet | J6: 6 | K6: "Vigna Vinaashaka Narasimha Yagna Maha Prasadam", Batch No., Packed date, Best before | L6: 3 months | M6: R2 | N6: =IFERROR(VLOOKUP(M6,'Packing Guide'!$A$60:$B$66,2,FALSE()),"") -> Rack 2 – Liquids & Oils (bottom shelf, in trays) | O6: OIL MUST NOT LEAK – store UPRIGHT in a tray; leak-test 5 pcs per batch (invert 30 min on tissue). Keep below 30°C. | P6: 300 | Q6: 600 | R6: Existing | S6: Do not pack oily tilak directly in zip-lock – oil seeps through the zip.
A7: KAV | B7: Narasimha Kavacha (protective amulet / locket) | C7: Protection & Mantra | D7: Donors | E7: Energised Narasimha Kavacha for protection. | F7: Piece | G7: 1 | H7: Small organza / velvet pouch with care card | I7: 3"x4" drawstring organza pouch (saffron/red) + printed card with Kavacha meaning & how to wear | J7: 5 | K7: Item name, Batch No., Care instructions | L7: Long life | M7: LK | N7: =IFERROR(VLOOKUP(M7,'Packing Guide'!$A$60:$B$66,2,FALSE()),"") -> Locked Cabinet – Valuables | O7: Count every month (higher value). Keep away from moisture. | P7: 100 | Q7: 200 | R7: Existing
A8: AKV | B8: Audio – Narasimha Kavacha (QR card) | C8: Audio / Digital | D8: Both | E8: Audio recitation of Narasimha Kavacha – shared as QR-code card + WhatsApp link. | F8: Card | G8: 1 | H8: Printed QR card (visiting-card size), bundled in OPP sleeve of 50 | I8: 300 GSM matte card, 3.5"x2"; QR code to audio + temple contact; lamination optional | J8: 1.5 | K8: Title, QR code, Temple contact number | L8: Long life (check QR link every month) | M8: R4 | N8: =IFERROR(VLOOKUP(M8,'Packing Guide'!$A$60:$B$66,2,FALSE()),"") -> Rack 4 – Books, Cards & Paper | O8: Test QR link monthly. Also send audio on WhatsApp after donation. | P8: 200 | Q8: 500 | R8: Existing | S8: Digital – near-zero cost per donor.
A9: AKR | B9: Audio – Narasimha Kirtan (QR card) | C9: Audio / Digital | D9: Both | E9: Narasimha Kirtan audio – QR-code card + WhatsApp link. | F9: Card | G9: 1 | H9: Printed QR card, bundled in OPP sleeve of 50 | I9: 300 GSM matte card, 3.5"x2"; QR code to playlist | J9: 1.5 | K9: Title, QR code, Temple contact number | L9: Long life (check QR link every month) | M9: R4 | N9: =IFERROR(VLOOKUP(M9,'Packing Guide'!$A$60:$B$66,2,FALSE()),"") -> Rack 4 – Books, Cards & Paper | O9: Can be combined with AKV on a single two-sided card to save cost. | P9: 200 | Q9: 500 | R9: Existing
A10: PFR | B10: Narasimha Photo Frame | C10: Deity Photos & Frames | D10: Donors | E10: Framed photo of Lord Narasimha for home altar. | F10: Piece | G10: 1 | H10: Bubble wrap + corner protectors + corrugated (3-ply) box | I10: Glass face taped with masking-tape "X"; 2 layers bubble wrap; 3-ply carton sized to frame | J10: 25 | K10: Item name, size, FRAGILE sticker | L10: Long life | M10: R3 | N10: =IFERROR(VLOOKUP(M10,'Packing Guide'!$A$60:$B$66,2,FALSE()),"") -> Rack 3 – Photos, Frames & Fragile | O10: Store VERTICALLY like books, never stacked flat. Max 10 per shelf section. | P10: 25 | Q10: 50 | R10: Existing
A11: TTP | B11: Narasimha Table Top (idol/stand) | C11: Deity Photos & Frames | D11: Donors | E11: Table-top Narasimha murti/stand for office or car dashboard. | F11: Piece | G11: 1 | H11: Foam/bubble wrap + gift box | I11: Moulded or cut-foam insert; printed gift box | J11: 20 | K11: Item name, FRAGILE sticker | L11: Long life | M11: R3 | N11: =IFERROR(VLOOKUP(M11,'Packing Guide'!$A$60:$B$66,2,FALSE()),"") -> Rack 3 – Photos, Frames & Fragile | O11: Keep in original boxes; handle with both hands. | P11: 20 | Q11: 40 | R11: Existing
A12: STK | B12: Narasimha Sticker | C12: Protection & Mantra | D12: Both | E12: Sticker for car, door, laptop – remembrance of the Lord. | F12: Piece | G12: 1 | H12: Flat in OPP self-adhesive sleeve (sets of 10) | I12: OPP cellophane sleeve slightly larger than sticker; keep a card backing so stickers stay flat | J12: 0.5 | K12: Bundle label: Item, Qty, Batch No. | L12: 24 months | M12: R4 | N12: =IFERROR(VLOOKUP(M12,'Packing Guide'!$A$60:$B$66,2,FALSE()),"") -> Rack 4 – Books, Cards & Paper | O12: Keep flat, away from heat and humidity (adhesive weakens). | P12: 300 | Q12: 600 | R12: Existing
A13: KPR | B13: Narasimha Kavacha Print Out | C13: Protection & Mantra | D13: Both | E13: Printed Narasimha Kavacha text (Sanskrit + transliteration + meaning). | F13: Sheet | G13: 1 | H13: Laminated A5 card in OPP sleeve | I13: A5, 250 micron lamination; both sides printed | J13: 6 | K13: Title, Temple name | L13: Long life | M13: R4 | N13: =IFERROR(VLOOKUP(M13,'Packing Guide'!$A$60:$B$66,2,FALSE()),"") -> Rack 4 – Books, Cards & Paper | O13: Store flat in boxes of 100. | P13: 200 | Q13: 400 | R13: Existing
A14: MBX | B14: Mantra Box | C14: Protection & Mantra | D14: Donors | E14: Box with mantra slips / sacred items for the altar. | F14: Box | G14: 1 | H14: Shrink-wrap or OPP bag over box | I14: Box sealed with transparent sticker; OPP bag 1" larger than box | J14: 2 | K14: Item name, Batch No. | L14: Long life | M14: R4 | N14: =IFERROR(VLOOKUP(M14,'Packing Guide'!$A$60:$B$66,2,FALSE()),"") -> Rack 4 – Books, Cards & Paper | O14: Stack max 10 high. | P14: 50 | Q14: 100 | R14: Existing
A15: PRG | B15: Radha Govinda Photo | C15: Deity Photos & Frames | D15: Both | E15: Photo of Sri Sri Radha Govinda (temple Deities). | F15: Piece | G15: 1 | H15: Laminated photo + cardboard backing in OPP sleeve | I15: Sizes: 4"x6" (yatris) / 8"x10" (donors); 125 micron lamination | J15: 4 | K15: Deity name, Temple name | L15: Long life | M15: R3 | N15: =IFERROR(VLOOKUP(M15,'Packing Guide'!$A$60:$B$66,2,FALSE()),"") -> Rack 3 – Photos, Frames & Fragile | O15: Store flat, never folded. Separate by size. | P15: 200 | Q15: 400 | R15: Existing
A16: PHN | B16: Hanuman Photo | C16: Deity Photos & Frames | D16: Both | E16: Photo of Sri Hanuman. | F16: Piece | G16: 1 | H16: Laminated photo + cardboard backing in OPP sleeve | I16: 4"x6" / 8"x10"; 125 micron lamination | J16: 4 | K16: Deity name, Temple name | L16: Long life | M16: R3 | N16: =IFERROR(VLOOKUP(M16,'Packing Guide'!$A$60:$B$66,2,FALSE()),"") -> Rack 3 – Photos, Frames & Fragile | O16: Store flat. | P16: 100 | Q16: 200 | R16: Existing
A17: PLN | B17: Lakshmi Narasimha Photo | C17: Deity Photos & Frames | D17: Both | E17: Photo of Sri Lakshmi Narasimha. | F17: Piece | G17: 1 | H17: Laminated photo + cardboard backing in OPP sleeve | I17: 4"x6" / 8"x10"; 125 micron lamination | J17: 4 | K17: Deity name, Temple name | L17: Long life | M17: R3 | N17: =IFERROR(VLOOKUP(M17,'Packing Guide'!$A$60:$B$66,2,FALSE()),"") -> Rack 3 – Photos, Frames & Fragile | O17: Store flat. | P17: 150 | Q17: 300 | R17: Existing
A18: CTL | B18: Charan Tulasi | C18: Kalasha & Yagna Prasadam | D18: Both | E18: Tulasi leaves offered at the Lord's Lotus Feet. | F18: Pouch | G18: 3–5 leaves | H18: Shade-dry fully (2–3 days), then food-grade zip-lock or butter-paper pouch | I18: 2"x3" FOOD-GRADE virgin LDPE zip-lock, or glassine/butter-paper pouch; NO silica gel inside (edible) | J18: 1 | K18: "Charan Tulasi – please honour, do not discard", Packed date | L18: 6 months (dry) | M18: R1 | N18: =IFERROR(VLOOKUP(M18,'Packing Guide'!$A$60:$B$66,2,FALSE()),"") -> Rack 1 – Prasadam & Edibles | O18: Must be completely dry before packing (else fungus). Keep away from agarbathi/perfume rack (absorbs smell). | P18: 300 | Q18: 600 | R18: Existing
A19: CAM | B19: Charanamrita | C19: Holy Items & Liquids | D19: Both | E19: Sacred water/liquid from the Abhishekam of the Lord. | F19: Bottle | G19: 20–30 ml | H19: Small PET bottle, screw cap + shrink band (tamper evident) | I19: 20/30 ml PET bottle, food grade; fill to neck; screw cap + PVC shrink band; pack bottles upright in zip bag of 10 | J19: 4 | K19: "Charanamrita", Packed date, Best before, "Keep cool" | L19: Water-based: 7 days; Milk/curd-based: SAME DAY only | M19: R2 | N19: =IFERROR(VLOOKUP(M19,'Packing Guide'!$A$60:$B$66,2,FALSE()),"") -> Rack 2 – Liquids & Oils (bottom shelf, in trays) | O19: Dairy-based charanamrita must NOT be stocked – prepare on the day. Store water-based in cool place. | P19: 50 | Q19: 100 | R19: Existing | S19: Perishable – pack in small batches only.
A20: HWR | B20: Holy Water from Holy Rivers | C20: Holy Items & Liquids | D20: Both | E20: Ganga / Yamuna / holy-river water brought from yatras. | F20: Bottle | G20: 30–50 ml | H20: PET/HDPE bottle, screw cap + shrink band | I20: 30/50 ml PET; label with river & place; pack upright in zip bag of 10 | J20: 4 | K20: River name, Place, Collected date, Batch No. | L20: 24 months (sealed) | M20: R2 | N20: =IFERROR(VLOOKUP(M20,'Packing Guide'!$A$60:$B$66,2,FALSE()),"") -> Rack 2 – Liquids & Oils (bottom shelf, in trays) | O20: Filter before bottling. Store upright, away from sunlight. | P20: 100 | Q20: 200 | R20: Existing | S20: Great yatra souvenir – collect during each yatra.
A21: BPF | B21: Badrinath Prasadam Perfume (Attar) | C21: Fragrance & Puja | D21: Donors | E21: Perfume/attar prasadam from Badrinath. | F21: Bottle | G21: 3 ml | H21: Glass roll-on/attar vial in bubble sleeve, placed in small box | I21: 3 ml glass vial, tight cap + cap tape; bubble sleeve; keep upright | J21: 12 | K21: Item name, Origin, FRAGILE | L21: 24 months | M21: LK | N21: =IFERROR(VLOOKUP(M21,'Packing Guide'!$A$60:$B$66,2,FALSE()),"") -> Locked Cabinet – Valuables | O21: Heat & light reduce fragrance – keep in closed cabinet. Never store with food items. | P21: 50 | Q21: 100 | R21: Existing
A22: CHN | B22: Chandan Prasadam | C22: Kalasha & Yagna Prasadam | D22: Both | E22: Sandalwood paste offered to the Lord (e.g. Chandan Yatra). | F22: Pouch | G22: 2–3 g dried tablet / powder | H22: Dry the chandan into small tablets/powder → zip-lock; if paste, 5 g PP container | I22: 2"x3" food-grade zip-lock 50 micron (dry), or 5 g PP container (paste) | J22: 1.5 | K22: "Chandan Prasadam", Packed date, Batch No. | L22: Dry: 12 months; Paste: 7 days | M22: R1 | N22: =IFERROR(VLOOKUP(M22,'Packing Guide'!$A$60:$B$66,2,FALSE()),"") -> Rack 1 – Prasadam & Edibles | O22: Wet chandan spoils – always dry before stocking. | P22: 200 | Q22: 400 | R22: Existing
A23: AGR | B23: Agarbathi | C23: Fragrance & Puja | D23: Both | E23: Incense sticks (temple brand or offered). | F23: Pack | G23: 10 sticks | H23: Kraft/OPP pouch with temple sticker (or keep original sealed pack) | I23: Repack 10 sticks in OPP sleeve or kraft pouch; temple sticker | J23: 1.5 | K23: Fragrance name, Temple name | L23: 24 months | M23: R5 | N23: =IFERROR(VLOOKUP(M23,'Packing Guide'!$A$60:$B$66,2,FALSE()),"") -> Rack 5 – Fragrance & Puja items | O23: Keep dry, away from edibles & tulasi. | P23: 200 | Q23: 400 | R23: Existing
A24: BKS | B24: Book (small booklet) | C24: Books & Media | D24: Both | E24: Small spiritual booklet for first-time visitors/yatris. | F24: Piece | G24: 1 | H24: Shrink wrap (bundles of 10) or OPP sleeve | I24: Heat-shrink film bundle of 10; individual OPP sleeve for donor kits | J24: 1 | K24: Title, Language | L24: Long life | M24: R4 | N24: =IFERROR(VLOOKUP(M24,'Packing Guide'!$A$60:$B$66,2,FALSE()),"") -> Rack 4 – Books, Cards & Paper | O24: Store flat, off the floor, away from walls (damp). | P24: 200 | Q24: 400 | R24: Existing
A25: JML | B25: Japa Mala (Tulasi beads) | C25: Japa & Spiritual | D25: Both | E25: 108-bead tulasi japa mala for chanting Hare Krishna Maha-mantra. | F25: Piece | G25: 1 | H25: Zip-lock pouch with "How to chant" card (or inside Japa Bag) | I25: 4"x6" zip-lock 50 micron + chanting instruction card | J25: 2 | K25: Item name, How-to-chant card | L25: Long life | M25: R5 | N25: =IFERROR(VLOOKUP(M25,'Packing Guide'!$A$60:$B$66,2,FALSE()),"") -> Rack 5 – Fragrance & Puja items | O25: Keep dry (tulasi beads crack/fungus in damp). | P25: 100 | Q25: 200 | R25: Existing
A26: JBG | B26: Japa Bag | C26: Japa & Spiritual | D26: Both | E26: Cloth bag for japa mala. | F26: Piece | G26: 1 | H26: Fold, OPP bag (bundles of 10) | I26: OPP bag 6"x9" | J26: 1 | K26: Item name, Size | L26: Long life | M26: R5 | N26: =IFERROR(VLOOKUP(M26,'Packing Guide'!$A$60:$B$66,2,FALSE()),"") -> Rack 5 – Fragrance & Puja items | O26: Keep dry, pest-free (naphthalene NOT near edibles). | P26: 100 | Q26: 200 | R26: Existing
A27: MCD | B27: Mantra Card | C27: Protection & Mantra | D27: Both | E27: Hare Krishna Maha-mantra card / Narasimha pranam card. | F27: Card | G27: 1 | H27: Laminated card, OPP bundles of 50 | I27: Visiting-card or A6 size, 300 GSM, lamination | J27: 1.5 | K27: Title, Temple contact | L27: Long life | M27: R4 | N27: =IFERROR(VLOOKUP(M27,'Packing Guide'!$A$60:$B$66,2,FALSE()),"") -> Rack 4 – Books, Cards & Paper | O27: Store flat. | P27: 300 | Q27: 600 | R27: Existing | S27: Cheapest high-impact item – include in every kit.
A28: SPB | B28: Srila Prabhupada Books (Gita, Krishna Book) | C28: Books & Media | D28: Donors | E28: Bhagavad-gita As It Is, Krishna Book and other SP books. | F28: Book | G28: 1 | H28: Shrink wrap + gift tag / bookmark inside | I28: Heat-shrink film; for big donors gift-wrap in kraft paper | J28: 3 | K28: Title, Language | L28: Long life | M28: R4 | N28: =IFERROR(VLOOKUP(M28,'Packing Guide'!$A$60:$B$66,2,FALSE()),"") -> Rack 4 – Books, Cards & Paper | O28: Store flat, max 15 high; off floor; check for termites. | P28: 50 | Q28: 100 | R28: Existing
A29: LPS | B29: LP Set Combo | C29: Books & Media | D29: Donors | E29: Combo set (contents to be confirmed by management). | F29: Set | G29: 1 | H29: Gift box / shrink wrap | I29: Box or shrink-wrapped set | J29: 5 | K29: Set name, Contents list | L29: Long life | M29: R4 | N29: =IFERROR(VLOOKUP(M29,'Packing Guide'!$A$60:$B$66,2,FALSE()),"") -> Rack 4 – Books, Cards & Paper | O29: Please confirm contents and update this row. | P29: 25 | Q29: 50 | R29: Existing | S29: CLARIFY: what does 'LP Set' contain?
A30: PEN | B30: Pen Drive with Kirtans & Mantras | C30: Books & Media | D30: Donors | E30: Pen drive pre-loaded with kirtans, mantras, lectures. | F30: Piece | G30: 1 | H30: Small plastic/kraft box or anti-static zip pouch + content list card | I30: Anti-static zip pouch or 2"x3" box; content list card | J30: 3 | K30: Content list, Capacity, Version/date | L30: Long life (re-verify files every 6 months) | M30: LK | N30: =IFERROR(VLOOKUP(M30,'Packing Guide'!$A$60:$B$66,2,FALSE()),"") -> Locked Cabinet – Valuables | O30: Test 1 in 20 before issue. Keep in locked cabinet. | P30: 25 | Q30: 50 | R30: Existing
A31: CDS | B31: Chardham Souvenir | C31: Souvenirs & Coins | D31: Both | E31: Souvenir from Chardham Yatra (Kedarnath, Badrinath, Gangotri, Yamunotri). | F31: Piece | G31: 1 | H31: Bubble wrap + gift box | I31: Bubble wrap; printed gift box with yatra name | J31: 10 | K31: Item, Yatra name, Year | L31: Long life | M31: R3 | N31: =IFERROR(VLOOKUP(M31,'Packing Guide'!$A$60:$B$66,2,FALSE()),"") -> Rack 3 – Photos, Frames & Fragile | O31: Fragile items on lower shelves. | P31: 50 | Q31: 100 | R31: Existing
A32: LXC | B32: Lakshmi Coins | C32: Souvenirs & Coins | D32: Donors | E32: Lakshmi coins (silver-plated/brass) for prosperity blessings. | F32: Piece | G32: 1 | H32: Coin capsule or velvet pouch + anti-tarnish paper | I32: Clear coin capsule (fits coin size) in small velvet pouch | J32: 6 | K32: Item, Metal, Batch No. | L32: Long life | M32: LK | N32: =IFERROR(VLOOKUP(M32,'Packing Guide'!$A$60:$B$66,2,FALSE()),"") -> Locked Cabinet – Valuables | O32: HIGH VALUE – keep in locked cabinet; issue against register; count weekly. | P32: 50 | Q32: 100 | R32: Existing
A33: KUM | B33: Kumkum | C33: Fragrance & Puja | D33: Both | E33: Kumkum prasadam. | F33: Container | G33: 5 g | H33: 5 g PP snap/screw container, OR heat-sealed sachet inside zip-lock | I33: 5 g PP container; or 2"x3" heat-sealed sachet | J33: 3 | K33: "Kumkum Prasadam", Packed date | L33: 24 months | M33: R5 | N33: =IFERROR(VLOOKUP(M33,'Packing Guide'!$A$60:$B$66,2,FALSE()),"") -> Rack 5 – Fragrance & Puja items | O33: Powder stains – always double-pack. Keep dry. | P33: 200 | Q33: 400 | R33: Existing
A34: SCT | B34: Scent Sticks | C34: Fragrance & Puja | D34: Both | E34: Scented sticks. | F34: Pouch | G34: 5 sticks | H34: Zip cover (as specified) | I34: 3"x8" zip-lock 50 micron | J34: 1.5 | K34: Fragrance name, Temple name | L34: 24 months | M34: R5 | N34: =IFERROR(VLOOKUP(M34,'Packing Guide'!$A$60:$B$66,2,FALSE()),"") -> Rack 5 – Fragrance & Puja items | O34: Keep away from edibles. | P34: 200 | Q34: 400 | R34: Existing
A35: DHP | B35: Dhoop Sticks | C35: Fragrance & Puja | D35: Both | E35: Dhoop sticks for home puja. | F35: Pack | G35: 10 sticks | H35: Original box, or zip-lock with sticker | I35: 3"x8" zip-lock 50 micron | J35: 1.5 | K35: Fragrance name | L35: 24 months | M35: R5 | N35: =IFERROR(VLOOKUP(M35,'Packing Guide'!$A$60:$B$66,2,FALSE()),"") -> Rack 5 – Fragrance & Puja items | O35: Keep dry. | P35: 150 | Q35: 300 | R35: Existing
A36: CDL | B36: Candles / Diyas | C36: Fragrance & Puja | D36: Both | E36: Candles for festivals (Karthika, Diwali). | F36: Piece | G36: 1 | H36: Kraft box or shrink wrap | I36: Store in original boxes | J36: 1 | K36: Item, Burn time | L36: Long life | M36: R5 | N36: =IFERROR(VLOOKUP(M36,'Packing Guide'!$A$60:$B$66,2,FALSE()),"") -> Rack 5 – Fragrance & Puja items | O36: Keep below 30°C (melts/bends). Not near gas or heat. | P36: 100 | Q36: 200 | R36: Existing
A37: BBS | B37: Bahumana Bag – Small | C37: Gift Packaging Material | D37: Both | E37: Small gift bag (yatri kits / small donations). | F37: Piece | G37: 1 | H37: — | I37: Cloth/jute/kraft paper bag (plastic carry bags avoided) | K37: — | L37: Long life | M37: R6 | N37: =IFERROR(VLOOKUP(M37,'Packing Guide'!$A$60:$B$66,2,FALSE()),"") -> Rack 6 – Packing & Serving Material | O37: Store flat in bundles of 50. | P37: 200 | Q37: 400 | R37: Existing
A38: BBM | B38: Bahumana Bag – Medium | C38: Gift Packaging Material | D38: Both | E38: Medium gift bag (regular donors). | F38: Piece | G38: 1 | H38: — | I38: Cloth/jute bag with temple print | K38: — | L38: Long life | M38: R6 | N38: =IFERROR(VLOOKUP(M38,'Packing Guide'!$A$60:$B$66,2,FALSE()),"") -> Rack 6 – Packing & Serving Material | O38: Store flat in bundles of 25. | P38: 100 | Q38: 200 | R38: Existing
A39: BBB | B39: Bahumana Bag – Big | C39: Gift Packaging Material | D39: Donors | E39: Big gift bag (major donors / patrons). | F39: Piece | G39: 1 | H39: — | I39: Premium jute/canvas bag with temple print | K39: — | L39: Long life | M39: R6 | N39: =IFERROR(VLOOKUP(M39,'Packing Guide'!$A$60:$B$66,2,FALSE()),"") -> Rack 6 – Packing & Serving Material | O39: Store flat in bundles of 25. | P39: 50 | Q39: 100 | R39: Existing
A40: PBS | B40: Prasadam Box – Small | C40: Prasadam Serving Material | D40: Both | E40: Small sweet/prasadam box. | F40: Piece | G40: 1 | H40: — | I40: Food-grade duplex board box | K40: — | L40: Long life | M40: R6 | N40: =IFERROR(VLOOKUP(M40,'Packing Guide'!$A$60:$B$66,2,FALSE()),"") -> Rack 6 – Packing & Serving Material | O40: Keep flat-packed; assemble only on the day. | P40: 300 | Q40: 600 | R40: Existing
...

Sheet Packing Guide
A1: Packing Guide – Simple, low-cost, leak-proof & respectful
A2: Research summary: which packing to use for which item, step-by-step SOP, labels, storage layout and compliance.
A4: A. Packing options compared (indicative costs, India, Oct 2026)
A5: Packing Option | B5: Best For (Item IDs) | C5: Approx. Cost / Unit (₹) | D5: Advantages | E5: Limitations | F5: Verdict
A6: Clear LDPE zip-lock pouch, 50–60 micron (2"x3", 3"x4", 4"x6", 3"x8") | B6: THR, CTL, CHN, SCT, DHP, JML, KNT, GCH, outer layer for TIL & KUM | C6: ₹0.50 – 2 | D6: Cheapest; re-closable; transparent (donor sees the item); no machine needed; easy to count & stack | E6: Zip does not stop oil seepage; thin (<40 micron) bags tear; plastic – use food-grade for edibles | F6: ★ PRIMARY CHOICE for dry items
A7: Heat-sealed LDPE / laminated sachet (hand impulse sealer ~₹1,500–3,000 one-time) | B7: TIL (oily), KUM (powder), GWK | C7: ₹0.30 – 1 | D7: Air-tight & leak-proof; tamper-evident; very low running cost; professional look | E7: Needs a sealer machine & a little training; not re-closable | F7: ★ Best for oily/powder items at volume
A8: 5 g / 10 g PP screw-cap container with inner wad | B8: TIL, KUM, CHN (paste) | C8: ₹3 – 7 | D8: Rigid, re-usable by devotee, holds oily tilak safely; looks premium | E8: Costlier; must not overfill; cap can loosen in transit – tape it | F8: ★ Recommended for tilak (inside zip-lock)
A9: PET / HDPE bottle 20–50 ml, screw cap + PVC shrink band | B9: HWR, CAM | C9: ₹2 – 5 (incl. cap) | D9: Leak-proof; tamper-evident; light; ideal for yatra holy water | E9: Cap neck size must match bottle; dairy liquids spoil | F9: ★ Standard for liquids
A10: Glass attar vial 3 ml + bubble sleeve | B10: BPF | C10: ₹8 – 15 | D10: Protects fragrance; premium feel | E10: Fragile; costlier | F10: Use for perfume only
A11: OPP self-adhesive cellophane sleeve | B11: PRG, PHN, PLN, KPR, MCD, STK, AKV, AKR, BKS, CAL, BMK | C11: ₹0.50 – 3 | D11: Crystal-clear; protects from dust & finger-marks; flat storage | E11: Not for liquids/oils | F11: ★ Standard for photos & printed items
A12: Butter paper / glassine cover (printed) | B12: CTL, DRP, dry prasadam | C12: ₹1 – 2 | D12: Food-safe, eco-friendly, breathable, carries our message | E12: Not moisture-proof; not for oily items unless grease-proof grade | F12: Eco option for edibles
A13: Kraft-paper stand-up pouch with window & zip | B13: Premium donor kits, AGR, CHN | C13: ₹5 – 12 | D13: Eco look; premium; printable | E13: Costlier than plain zip-lock | F13: For Gold / Patron donor kits
A14: Organza / velvet drawstring pouch | B14: KAV, LXC, JML (donor) | C14: ₹4 – 15 | D14: Auspicious & gift-like; re-usable | E14: Not waterproof | F14: For valuables & amulets
A15: Bubble wrap + 3-ply corrugated box / gift box | B15: PFR, TTP, CDS | C15: ₹10 – 40 | D15: Prevents breakage in transit | E15: Bulky; more storage space | F15: Must for glass / fragile
A16: Heat-shrink film (heat gun) | B16: SPB, BKS bundles, LPS, MBX | C16: ₹1 – 3 | D16: Dust & moisture protection; neat bundles | E16: Needs heat gun | F16: For books & sets
A17: Cloth / jute Bahumana bag | B17: Outer bag for every kit | C17: ₹15 – 80 | D17: Re-usable, carries temple branding into homes for years; avoids banned plastic carry bags | E17: Higher cost | F17: ★ Outer bag for all kits
A18: Prices: indicative ranges compiled from Indian wholesale marketplace listings (IndiaMart / TradeIndia), Oct 2026. Take 3 local quotes before buying in bulk.
A20: B. Golden rules for OILY & LIQUID items (Narasimha Yagna Tilak, Charanamrita, Holy Water, Perfume)
A21: 1. NEVER put oily tilak directly in a zip-lock – oil creeps through the zip. Always: leak-proof container (or heat-sealed sachet) → then zip-lock = DOUBLE BARRIER.
A22: 2. Fill containers only up to 80%. Wipe the rim and threads with a clean dry cloth before closing.
A23: 3. Close tightly, wrap a strip of cello-tape over the cap edge (or use shrink band for bottles).
A24: 4. Leak test each batch: take 5 random pieces, place upside-down on tissue paper for 30 minutes. Any stain = re-pack the whole batch.
A25: 5. Store UPRIGHT in plastic trays on the LOWEST shelf (Rack 2), so any leak does not spoil items below.
A26: 6. Keep below 30°C and away from direct sunlight. Ghee/oil-based items: best before 3 months.
A27: 7. Dairy-based Charanamrita is NOT stocked – prepare on the day. Only water-based charanamrita may be bottled (7 days).
A29: C. Packing-station SOP (step by step)
A30: 1. Clean table, wash hands; for edible prasadam (tulasi, chandan, dry prasadam) wear gloves & hair cover. Chant / play kirtan – these are the Lord's mercy.
A31: 2. Prepare materials: pouches, containers, labels, pen, batch stamp, scissors, tray, sealer (if used).
... A38: D. Label standard & batch number
A39: Every label shows | B39: Item name • Hare Krishna Movement, Hyderabad • Batch No. • Packed date • Best before (if perishable) • Temple phone / QR
A40: Batch No. format | B40: ITEMID-YYMM-NN e.g. TIL-2611-01 = Narasimha Yagna Tilak, Nov 2026, batch 1
A41: Respect line (optional) | B41: "Maha Prasadam – please honour, do not discard" / "Always Remember Krishna, Never Forget Krishna"
A42: Label size | B42: Small pouch: 1.5" x 1" sticker • Bottles: wrap label 2" x 1" • Boxes: 3" x 2"
A44: E. Compliance & good practice
A45: • Plastic Waste Management Rules (India): plastic carry bags below 120 micron are banned – use cloth/jute/kraft Bahumana bags as the OUTER bag. Small zip-lock pouches are used only as item packaging.
A46: • Use FOOD-GRADE virgin LDPE / PET for anything edible (tulasi, chandan, charanamrita, dry prasadam). Never put silica gel or naphthalene inside edible packs.
A47: • Keep fragrance items (agarbathi, dhoop, perfume, scent sticks) on a SEPARATE rack from edibles – tulasi and prasadam absorb smells.
A48: • Dry prasadam given outside the temple: mention prepared date & best before; follow FSSAI labelling if the kitchen is registered.
A58: F. Storeroom rack layout (Storage Codes)
A59: Code | B59: Rack / Location | C59: Keep here | D59: Conditions
...

Sheet Nov-2026
A1: Monthly Stock & Packing Register – Nov-2026
A2: Hare Krishna Movement, Hyderabad • Festivals / focus this month: Karthika month (deepam, ghee wicks), Gita Jayanti prep
A3: Month: | C3: Nov-2026 | G3: Storekeeper: | M3: Physical count date: | S3: Verified by (In-charge):
A4: Yellow = type here • Green = automatic • Opening stock = last month's physical count (or book closing if not counted) • NOV-2026: type opening stock by hand.
A6: ITEM & OPENING | G6: PACKING BATCH 1 | K6: PACKING BATCH 2 | O6: IN | P6: OUT (ISSUED) | U6: CLOSING & CONTROL | AA6: STORAGE & NOTES
A7: S.No | B7: Item ID | C7: Item Name | D7: Category | E7: Unit | F7: Opening Stock | G7: Date Packed | H7: Date Stored | I7: Batch No. | J7: Qty Packed | K7: Date Packed | L7: Date Stored | M7: Batch No. | N7: Qty Packed | O7: Total Packed / Received | P7: Issued – Donors | Q7: Issued – Yatris | R7: Issued – Events / Other | S7: Damaged / Expired | T7: Total Issued & Out | U7: Closing Stock (Book) | V7: Physical Count (Month End) | W7: Variance (Physical – Book) | X7: Reorder Level | Y7: Stock Status | Z7: Qty to Pack / Order Next Month | AA7: Best Before / Expiry | AB7: Storage Location | AC7: Packed By | AD7: Remarks
A8: 1 | B8: ='Item Master'!A5 -> THR | C8: ='Item Master'!B5 -> Kalasha Thread (wrist thread) | D8: ='Item Master'!C5 -> Kalasha & Yagna Prasadam | E8: ='Item Master'!F5 -> Pouch | O8: =N(J8)+N(N8) -> 0 | T8: =SUM(P8:S8) -> 0 | U8: =N(F8)+O8-T8 -> 0 | W8: =IF(V8="","",V8-U8) | X8: ='Item Master'!P5 -> 300 | Y8: =IF(B8="","",IF(U8<=0,"OUT OF STOCK",IF(U8<=X8,"REORDER NOW",IF(U8<=X8*1.5,"LOW","OK")))) -> OUT OF STOCK | Z8: =MAX(0,'Item Master'!Q5-IF(V8<>"",V8,U8)) -> 600 | AB8: ='Item Master'!N5 -> Rack 1 – Prasadam & Edibles
A9: 2 | B9: ='Item Master'!A6 -> TIL | C9: ='Item Master'!B6 -> Narasimha Yagna Tilak | D9: ='Item Master'!C6 -> Kalasha & Yagna Prasadam | E9: ='Item Master'!F6 -> Container | F9: 120 | G9: =DATE(2026,11,3) -> 46329 | H9: =DATE(2026,11,4) -> 46330 | I9: TIL-2611-01 | J9: 300 | O9: =N(J9)+N(N9) -> 300 | P9: 140 | Q9: 60 | R9: 20 | S9: 5 | T9: =SUM(P9:S9) -> 225 | U9: =N(F9)+O9-T9 -> 195 | W9: =IF(V9="","",V9-U9) | X9: ='Item Master'!P6 -> 300 | Y9: =IF(B9="","",IF(U9<=0,"OUT OF STOCK",IF(U9<=X9,"REORDER NOW",IF(U9<=X9*1.5,"LOW","OK")))) -> REORDER NOW | Z9: =MAX(0,'Item Master'!Q6-IF(V9<>"",V9,U9)) -> 405 | AA9: =DATE(2027,2,3) -> 46421 | AB9: ='Item Master'!N6 -> Rack 2 – Liquids & Oils (bottom shelf, in trays) | AC9: Example – overwrite | AD9: EXAMPLE ROW: 3 Nov packed 300, stored 4 Nov; 5 leaked in test
A10: 3 | B10: ='Item Master'!A7 -> KAV | C10: ='Item Master'!B7 -> Narasimha Kavacha (protective amulet / locket) | D10: ='Item Master'!C7 -> Protection & Mantra | E10: ='Item Master'!F7 -> Piece | O10: =N(J10)+N(N10) -> 0 | T10: =SUM(P10:S10) -> 0 | U10: =N(F10)+O10-T10 -> 0 | W10: =IF(V10="","",V10-U10) | X10: ='Item Master'!P7 -> 100 | Y10: =IF(B10="","",IF(U10<=0,"OUT OF STOCK",IF(U10<=X10,"REORDER NOW",IF(U10<=X10*1.5,"LOW","OK")))) -> OUT OF STOCK | Z10: =MAX(0,'Item Master'!Q7-IF(V10<>"",V10,U10)) -> 200 | AB10: ='Item Master'!N7 -> Locked Cabinet – Valuables
A11: 4 | B11: ='Item Master'!A8 -> AKV | C11: ='Item Master'!B8 -> Audio – Narasimha Kavacha (QR card) | D11: ='Item Master'!C8 -> Audio / Digital | E11: ='Item Master'!F8 -> Card | O11: =N(J11)+N(N11) -> 0 | T11: =SUM(P11:S11) -> 0 | U11: =N(F11)+O11-T11 -> 0 | W11: =IF(V11="","",V11-U11) | X11: ='Item Master'!P8 -> 200 | Y11: =IF(B11="","",IF(U11<=0,"OUT OF STOCK",IF(U11<=X11,"REORDER NOW",IF(U11<=X11*1.5,"LOW","OK")))) -> OUT OF STOCK | Z11: =MAX(0,'Item Master'!Q8-IF(V11<>"",V11,U11)) -> 500 | AB11: ='Item Master'!N8 -> Rack 4 – Books, Cards & Paper
A12: 5 | B12: ='Item Master'!A9 -> AKR | C12: ='Item Master'!B9 -> Audio – Narasimha Kirtan (QR card) | D12: ='Item Master'!C9 -> Audio / Digital | E12: ='Item Master'!F9 -> Card | O12: =N(J12)+N(N12) -> 0 | T12: =SUM(P12:S12) -> 0 | U12: =N(F12)+O12-T12 -> 0 | W12: =IF(V12="","",V12-U12) | X12: ='Item Master'!P9 -> 200 | Y12: =IF(B12="","",IF(U12<=0,"OUT OF STOCK",IF(U12<=X12,"REORDER NOW",IF(U12<=X12*1.5,"LOW","OK")))) -> OUT OF STOCK | Z12: =MAX(0,'Item Master'!Q9-IF(V12<>"",V12,U12)) -> 500 | AB12: ='Item Master'!N9 -> Rack 4 – Books, Cards & Paper
A13: 6 | B13: ='Item Master'!A10 -> PFR | C13: ='Item Master'!B10 -> Narasimha Photo Frame | D13: ='Item Master'!C10 -> Deity Photos & Frames | E13: ='Item Master'!F10 -> Piece | O13: =N(J13)+N(N13) -> 0 | T13: =SUM(P13:S13) -> 0 | U13: =N(F13)+O13-T13 -> 0 | W13: =IF(V13="","",V13-U13) | X13: ='Item Master'!P10 -> 25 | Y13: =IF(B13="","",IF(U13<=0,"OUT OF STOCK",IF(U13<=X13,"REORDER NOW",IF(U13<=X13*1.5,"LOW","OK")))) -> OUT OF STOCK | Z13: =MAX(0,'Item Master'!Q10-IF(V13<>"",V13,U13)) -> 50 | AB13: ='Item Master'!N10 -> Rack 3 – Photos, Frames & Fragile
A14: 7 | B14: ='Item Master'!A11 -> TTP | C14: ='Item Master'!B11 -> Narasimha Table Top (idol/stand) | D14: ='Item Master'!C11 -> Deity Photos & Frames | E14: ='Item Master'!F11 -> Piece | O14: =N(J14)+N(N14) -> 0 | T14: =SUM(P14:S14) -> 0 | U14: =N(F14)+O14-T14 -> 0 | W14: =IF(V14="","",V14-U14) | X14: ='Item Master'!P11 -> 20 | Y14: =IF(B14="","",IF(U14<=0,"OUT OF STOCK",IF(U14<=X14,"REORDER NOW",IF(U14<=X14*1.5,"LOW","OK")))) -> OUT OF STOCK | Z14: =MAX(0,'Item Master'!Q11-IF(V14<>"",V14,U14)) -> 40 | AB14: ='Item Master'!N11 -> Rack 3 – Photos, Frames & Fragile
A15: 8 | B15: ='Item Master'!A12 -> STK | C15: ='Item Master'!B12 -> Narasimha Sticker | D15: ='Item Master'!C12 -> Protection & Mantra | E15: ='Item Master'!F12 -> Piece | O15: =N(J15)+N(N15) -> 0 | T15: =SUM(P15:S15) -> 0 | U15: =N(F15)+O15-T15 -> 0 | W15: =IF(V15="","",V15-U15) | X15: ='Item Master'!P12 -> 300 | Y15: =IF(B15="","",IF(U15<=0,"OUT OF STOCK",IF(U15<=X15,"REORDER NOW",IF(U15<=X15*1.5,"LOW","OK")))) -> OUT OF STOCK | Z15: =MAX(0,'Item Master'!Q12-IF(V15<>"",V15,U15)) -> 600 | AB15: ='Item Master'!N12 -> Rack 4 – Books, Cards & Paper
A16: 9 | B16: ='Item Master'!A13 -> KPR | C16: ='Item Master'!B13 -> Narasimha Kavacha Print Out | D16: ='Item Master'!C13 -> Protection & Mantra | E16: ='Item Master'!F13 -> Sheet | O16: =N(J16)+N(N16) -> 0 | T16: =SUM(P16:S16) -> 0 | U16: =N(F16)+O16-T16 -> 0 | W16: =IF(V16="","",V16-U16) | X16: ='Item Master'!P13 -> 200 | Y16: =IF(B16="","",IF(U16<=0,"OUT OF STOCK",IF(U16<=X16,"REORDER NOW",IF(U16<=X16*1.5,"LOW","OK")))) -> OUT OF STOCK | Z16: =MAX(0,'Item Master'!Q13-IF(V16<>"",V16,U16)) -> 400 | AB16: ='Item Master'!N13 -> Rack 4 – Books, Cards & Paper
A17: 10 | B17: ='Item Master'!A14 -> MBX | C17: ='Item Master'!B14 -> Mantra Box | D17: ='Item Master'!C14 -> Protection & Mantra | E17: ='Item Master'!F14 -> Box | O17: =N(J17)+N(N17) -> 0 | T17: =SUM(P17:S17) -> 0 | U17: =N(F17)+O17-T17 -> 0 | W17: =IF(V17="","",V17-U17) | X17: ='Item Master'!P14 -> 50 | Y17: =IF(B17="","",IF(U17<=0,"OUT OF STOCK",IF(U17<=X17,"REORDER NOW",IF(U17<=X17*1.5,"LOW","OK")))) -> OUT OF STOCK | Z17: =MAX(0,'Item Master'!Q14-IF(V17<>"",V17,U17)) -> 100 | AB17: ='Item Master'!N14 -> Rack 4 – Books, Cards & Paper
A18: 11 | B18: ='Item Master'!A15 -> PRG | C18: ='Item Master'!B15 -> Radha Govinda Photo | D18: ='Item Master'!C15 -> Deity Photos & Frames | E18: ='Item Master'!F15 -> Piece | O18: =N(J18)+N(N18) -> 0 | T18: =SUM(P18:S18) -> 0 | U18: =N(F18)+O18-T18 -> 0 | W18: =IF(V18="","",V18-U18) | X18: ='Item Master'!P15 -> 200 | Y18: =IF(B18="","",IF(U18<=0,"OUT OF STOCK",IF(U18<=X18,"REORDER NOW",IF(U18<=X18*1.5,"LOW","OK")))) -> OUT OF STOCK | Z18: =MAX(0,'Item Master'!Q15-IF(V18<>"",V18,U18)) -> 400 | AB18: ='Item Master'!N15 -> Rack 3 – Photos, Frames & Fragile
A19: 12 | B19: ='Item Master'!A16 -> PHN | C19: ='Item Master'!B16 -> Hanuman Photo | D19: ='Item Master'!C16 -> Deity Photos & Frames | E19: ='Item Master'!F16 -> Piece | O19: =N(J19)+N(N19) -> 0 | T19: =SUM(P19:S19) -> 0 | U19: =N(F19)+O19-T19 -> 0 | W19: =IF(V19="","",V19-U19) | X19: ='Item Master'!P16 -> 100 | Y19: =IF(B19="","",IF(U19<=0,"OUT OF STOCK",IF(U19<=X19,"REORDER NOW",IF(U19<=X19*1.5,"LOW","OK")))) -> OUT OF STOCK | Z19: =MAX(0,'Item Master'!Q16-IF(V19<>"",V19,U19)) -> 200 | AB19: ='Item Master'!N16 -> Rack 3 – Photos, Frames & Fragile
A20: 13 | B20: ='Item Master'!A17 -> PLN | C20: ='Item Master'!B17 -> Lakshmi Narasimha Photo | D20: ='Item Master'!C17 -> Deity Photos & Frames | E20: ='Item Master'!F17 -> Piece | O20: =N(J20)+N(N20) -> 0 | T20: =SUM(P20:S20) -> 0 | U20: =N(F20)+O20-T20 -> 0 | W20: =IF(V20="","",V20-U20) | X20: ='Item Master'!P17 -> 150 | Y20: =IF(B20="","",IF(U20<=0,"OUT OF STOCK",IF(U20<=X20,"REORDER NOW",IF(U20<=X20*1.5,"LOW","OK")))) -> OUT OF STOCK | Z20: =MAX(0,'Item Master'!Q17-IF(V20<>"",V20,U20)) -> 300 | AB20: ='Item Master'!N17 -> Rack 3 – Photos, Frames & Fragile
A21: 14 | B21: ='Item Master'!A18 -> CTL | C21: ='Item Master'!B18 -> Charan Tulasi | D21: ='Item Master'!C18 -> Kalasha & Yagna Prasadam | E21: ='Item Master'!F18 -> Pouch | O21: =N(J21)+N(N21) -> 0 | T21: =SUM(P21:S21) -> 0 | U21: =N(F21)+O21-T21 -> 0 | W21: =IF(V21="","",V21-U21) | X21: ='Item Master'!P18 -> 300 | Y21: =IF(B21="","",IF(U21<=0,"OUT OF STOCK",IF(U21<=X21,"REORDER NOW",IF(U21<=X21*1.5,"LOW","OK")))) -> OUT OF STOCK | Z21: =MAX(0,'Item Master'!Q18-IF(V21<>"",V21,U21)) -> 600 | AB21: ='Item Master'!N18 -> Rack 1 – Prasadam & Edibles
... A66: 59 | B66: ='Item Master'!A63 -> YID | C66: ='Item Master'!B63 -> Yatri ID Card + Lanyard | D66: ='Item Master'!C63 -> Suggested New Items | E66: ='Item Master'!F63 -> Set | O66: =N(J66)+N(N66) -> 0 | T66: =SUM(P66:S66) -> 0 | U66: =N(F66)+O66-T66 -> 0 | W66: =IF(V66="","",V66-U66) | X66: ='Item Master'!P63 -> 100 | Y66: =IF(B66="","",IF(U66<=0,"OUT OF STOCK",IF(U66<=X66,"REORDER NOW",IF(U66<=X66*1.5,"LOW","OK")))) -> OUT OF STOCK | Z66: =MAX(0,'Item Master'!Q63-IF(V66<>"",V66,U66)) -> 300 | AB66: ='Item Master'!N63 -> Rack 6 – Packing & Serving Material
C67: TOTAL (all items) | F67: =SUM(F8:F66) -> 120 | J67: =SUM(J8:J66) -> 300 | N67: =SUM(N8:N66) -> 0 | O67: =SUM(O8:O66) -> 300 | P67: =SUM(P8:P66) -> 140 | Q67: =SUM(Q8:Q66) -> 60 | R67: =SUM(R8:R66) -> 20 | S67: =SUM(S8:S66) -> 5 | T67: =SUM(T8:T66) -> 225 | U67: =SUM(U8:U66) -> 195 | V67: =SUM(V8:V66) -> 0 | Y67: =COUNTIF(Y8:Y66,"REORDER NOW")+COUNTIF(Y8:Y66,"OUT OF STOCK")&" to act" -> 59 to act | Z67: =SUM(Z8:Z66) -> 26995
A69: MONTHLY STOREROOM CHECKLIST (write Y / N and initials) | J69: Done? | K69: Initials
A70: 1 | B70: Physical count of every item done and entered in 'Physical Count'
A71: 2 | B71: All variances explained in Remarks
A72: 3 | B72: Leak test done for tilak / liquid batches packed this month
A73: 4 | B73: Best-before dates checked – items expiring within 30 days moved to front / issued first
A74: 5 | B74: FIFO followed – old stock in front, new stock behind
A75: 6 | B75: Racks cleaned; floor dry; no pests / termites / rodent signs
A76: 7 | B76: Edibles kept separate from fragrance items
A77: 8 | B77: Locked cabinet (coins, kavacha, perfume, pen drives) counted & tallied
A78: 9 | B78: QR audio links tested and working
A79: 10 | B79: Packing consumables (pouches, containers, labels) sufficient for next month
A80: 11 | B80: Upcoming festival / yatra demand checked with Yatra & Donor teams
A81: 12 | B81: Sheet signed by Storekeeper and verified by In-charge
B83: Storekeeper signature: ____________________ | I83: In-charge signature: ____________________ | R83: Date: ____________

Sheet Dec-2026
A1: Monthly Stock & Packing Register – Dec-2026
A2: Hare Krishna Movement, Hyderabad • Festivals / focus this month: Gita Jayanti / Vaikuntha Ekadashi prep – books & calendars demand high
A3: Month: | C3: Dec-2026 | G3: Storekeeper: | M3: Physical count date: | S3: Verified by (In-charge):
A4: Yellow = type here • Green = automatic • Opening stock = last month's physical count (or book closing if not counted)
A6: ITEM & OPENING | G6: PACKING BATCH 1 | K6: PACKING BATCH 2 | O6: IN | P6: OUT (ISSUED) | U6: CLOSING & CONTROL | AA6: STORAGE & NOTES
A7: S.No | B7: Item ID | C7: Item Name | D7: Category | E7: Unit | F7: Opening Stock | G7: Date Packed | H7: Date Stored | I7: Batch No. | J7: Qty Packed | K7: Date Packed | L7: Date Stored | M7: Batch No. | N7: Qty Packed | O7: Total Packed / Received | P7: Issued – Donors | Q7: Issued – Yatris | R7: Issued – Events / Other | S7: Damaged / Expired | T7: Total Issued & Out | U7: Closing Stock (Book) | V7: Physical Count (Month End) | W7: Variance (Physical – Book) | X7: Reorder Level | Y7: Stock Status | Z7: Qty to Pack / Order Next Month | AA7: Best Before / Expiry | AB7: Storage Location | AC7: Packed By | AD7: Remarks
A8: 1 | B8: ='Item Master'!A5 -> THR | C8: ='Item Master'!B5 -> Kalasha Thread (wrist thread) | D8: ='Item Master'!C5 -> Kalasha & Yagna Prasadam | E8: ='Item Master'!F5 -> Pouch | F8: =IF('Nov-2026'!V8<>"",'Nov-2026'!V8,'Nov-2026'!U8) -> 0 | O8: =N(J8)+N(N8) -> 0 | T8: =SUM(P8:S8) -> 0 | U8: =N(F8)+O8-T8 -> 0 | W8: =IF(V8="","",V8-U8) | X8: ='Item Master'!P5 -> 300 | Y8: =IF(B8="","",IF(U8<=0,"OUT OF STOCK",IF(U8<=X8,"REORDER NOW",IF(U8<=X8*1.5,"LOW","OK")))) -> OUT OF STOCK | Z8: =MAX(0,'Item Master'!Q5-IF(V8<>"",V8,U8)) -> 600 | AB8: ='Item Master'!N5 -> Rack 1 – Prasadam & Edibles
A9: 2 | B9: ='Item Master'!A6 -> TIL | C9: ='Item Master'!B6 -> Narasimha Yagna Tilak | D9: ='Item Master'!C6 -> Kalasha & Yagna Prasadam | E9: ='Item Master'!F6 -> Container | F9: =IF('Nov-2026'!V9<>"",'Nov-2026'!V9,'Nov-2026'!U9) -> 195 | O9: =N(J9)+N(N9) -> 0 | T9: =SUM(P9:S9) -> 0 | U9: =N(F9)+O9-T9 -> 195 | W9: =IF(V9="","",V9-U9) | X9: ='Item Master'!P6 -> 300 | Y9: =IF(B9="","",IF(U9<=0,"OUT OF STOCK",IF(U9<=X9,"REORDER NOW",IF(U9<=X9*1.5,"LOW","OK")))) -> REORDER NOW | Z9: =MAX(0,'Item Master'!Q6-IF(V9<>"",V9,U9)) -> 405 | AB9: ='Item Master'!N6 -> Rack 2 – Liquids & Oils (bottom shelf, in trays)
A10: 3 | B10: ='Item Master'!A7 -> KAV | C10: ='Item Master'!B7 -> Narasimha Kavacha (protective amulet / locket) | D10: ='Item Master'!C7 -> Protection & Mantra | E10: ='Item Master'!F7 -> Piece | F10: =IF('Nov-2026'!V10<>"",'Nov-2026'!V10,'Nov-2026'!U10) -> 0 | O10: =N(J10)+N(N10) -> 0 | T10: =SUM(P10:S10) -> 0 | U10: =N(F10)+O10-T10 -> 0 | W10: =IF(V10="","",V10-U10) | X10: ='Item Master'!P7 -> 100 | Y10: =IF(B10="","",IF(U10<=0,"OUT OF STOCK",IF(U10<=X10,"REORDER NOW",IF(U10<=X10*1.5,"LOW","OK")))) -> OUT OF STOCK | Z10: =MAX(0,'Item Master'!Q7-IF(V10<>"",V10,U10)) -> 200 | AB10: ='Item Master'!N7 -> Locked Cabinet – Valuables
A11: 4 | B11: ='Item Master'!A8 -> AKV | C11: ='Item Master'!B8 -> Audio – Narasimha Kavacha (QR card) | D11: ='Item Master'!C8 -> Audio / Digital | E11: ='Item Master'!F8 -> Card | F11: =IF('Nov-2026'!V11<>"",'Nov-2026'!V11,'Nov-2026'!U11) -> 0 | O11: =N(J11)+N(N11) -> 0 | T11: =SUM(P11:S11) -> 0 | U11: =N(F11)+O11-T11 -> 0 | W11: =IF(V11="","",V11-U11) | X11: ='Item Master'!P8 -> 200 | Y11: =IF(B11="","",IF(U11<=0,"OUT OF STOCK",IF(U11<=X11,"REORDER NOW",IF(U11<=X11*1.5,"LOW","OK")))) -> OUT OF STOCK | Z11: =MAX(0,'Item Master'!Q8-IF(V11<>"",V11,U11)) -> 500 | AB11: ='Item Master'!N8 -> Rack 4 – Books, Cards & Paper
A12: 5 | B12: ='Item Master'!A9 -> AKR | C12: ='Item Master'!B9 -> Audio – Narasimha Kirtan (QR card) | D12: ='Item Master'!C9 -> Audio / Digital | E12: ='Item Master'!F9 -> Card | F12: =IF('Nov-2026'!V12<>"",'Nov-2026'!V12,'Nov-2026'!U12) -> 0 | O12: =N(J12)+N(N12) -> 0 | T12: =SUM(P12:S12) -> 0 | U12: =N(F12)+O12-T12 -> 0 | W12: =IF(V12="","",V12-U12) | X12: ='Item Master'!P9 -> 200 | Y12: =IF(B12="","",IF(U12<=0,"OUT OF STOCK",IF(U12<=X12,"REORDER NOW",IF(U12<=X12*1.5,"LOW","OK")))) -> OUT OF STOCK | Z12: =MAX(0,'Item Master'!Q9-IF(V12<>"",V12,U12)) -> 500 | AB12: ='Item Master'!N9 -> Rack 4 – Books, Cards & Paper
A13: 6 | B13: ='Item Master'!A10 -> PFR | C13: ='Item Master'!B10 -> Narasimha Photo Frame | D13: ='Item Master'!C10 -> Deity Photos & Frames | E13: ='Item Master'!F10 -> Piece | F13: =IF('Nov-2026'!V13<>"",'Nov-2026'!V13,'Nov-2026'!U13) -> 0 | O13: =N(J13)+N(N13) -> 0 | T13: =SUM(P13:S13) -> 0 | U13: =N(F13)+O13-T13 -> 0 | W13: =IF(V13="","",V13-U13) | X13: ='Item Master'!P10 -> 25 | Y13: =IF(B13="","",IF(U13<=0,"OUT OF STOCK",IF(U13<=X13,"REORDER NOW",IF(U13<=X13*1.5,"LOW","OK")))) -> OUT OF STOCK | Z13: =MAX(0,'Item Master'!Q10-IF(V13<>"",V13,U13)) -> 50 | AB13: ='Item Master'!N10 -> Rack 3 – Photos, Frames & Fragile
A14: 7 | B14: ='Item Master'!A11 -> TTP | C14: ='Item Master'!B11 -> Narasimha Table Top (idol/stand) | D14: ='Item Master'!C11 -> Deity Photos & Frames | E14: ='Item Master'!F11 -> Piece | F14: =IF('Nov-2026'!V14<>"",'Nov-2026'!V14,'Nov-2026'!U14) -> 0 | O14: =N(J14)+N(N14) -> 0 | T14: =SUM(P14:S14) -> 0 | U14: =N(F14)+O14-T14 -> 0 | W14: =IF(V14="","",V14-U14) | X14: ='Item Master'!P11 -> 20 | Y14: =IF(B14="","",IF(U14<=0,"OUT OF STOCK",IF(U14<=X14,"REORDER NOW",IF(U14<=X14*1.5,"LOW","OK")))) -> OUT OF STOCK | Z14: =MAX(0,'Item Master'!Q11-IF(V14<>"",V14,U14)) -> 40 | AB14: ='Item Master'!N11 -> Rack 3 – Photos, Frames & Fragile
A15: 8 | B15: ='Item Master'!A12 -> STK | C15: ='Item Master'!B12 -> Narasimha Sticker | D15: ='Item Master'!C12 -> Protection & Mantra | E15: ='Item Master'!F12 -> Piece | F15: =IF('Nov-2026'!V15<>"",'Nov-2026'!V15,'Nov-2026'!U15) -> 0 | O15: =N(J15)+N(N15) -> 0 | T15: =SUM(P15:S15) -> 0 | U15: =N(F15)+O15-T15 -> 0 | W15: =IF(V15="","",V15-U15) | X15: ='Item Master'!P12 -> 300 | Y15: =IF(B15="","",IF(U15<=0,"OUT OF STOCK",IF(U15<=X15,"REORDER NOW",IF(U15<=X15*1.5,"LOW","OK")))) -> OUT OF STOCK | Z15: =MAX(0,'Item Master'!Q12-IF(V15<>"",V15,U15)) -> 600 | AB15: ='Item Master'!N12 -> Rack 4 – Books, Cards & Paper
A16: 9 | B16: ='Item Master'!A13 -> KPR | C16: ='Item Master'!B13 -> Narasimha Kavacha Print Out | D16: ='Item Master'!C13 -> Protection & Mantra | E16: ='Item Master'!F13 -> Sheet | F16: =IF('Nov-2026'!V16<>"",'Nov-2026'!V16,'Nov-2026'!U16) -> 0 | O16: =N(J16)+N(N16) -> 0 | T16: =SUM(P16:S16) -> 0 | U16: =N(F16)+O16-T16 -> 0 | W16: =IF(V16="","",V16-U16) | X16: ='Item Master'!P13 -> 200 | Y16: =IF(B16="","",IF(U16<=0,"OUT OF STOCK",IF(U16<=X16,"REORDER NOW",IF(U16<=X16*1.5,"LOW","OK")))) -> OUT OF STOCK | Z16: =MAX(0,'Item Master'!Q13-IF(V16<>"",V16,U16)) -> 400 | AB16: ='Item Master'!N13 -> Rack 4 – Books, Cards & Paper
A17: 10 | B17: ='Item Master'!A14 -> MBX | C17: ='Item Master'!B14 -> Mantra Box | D17: ='Item Master'!C14 -> Protection & Mantra | E17: ='Item Master'!F14 -> Box | F17: =IF('Nov-2026'!V17<>"",'Nov-2026'!V17,'Nov-2026'!U17) -> 0 | O17: =N(J17)+N(N17) -> 0 | T17: =SUM(P17:S17) -> 0 | U17: =N(F17)+O17-T17 -> 0 | W17: =IF(V17="","",V17-U17) | X17: ='Item Master'!P14 -> 50 | Y17: =IF(B17="","",IF(U17<=0,"OUT OF STOCK",IF(U17<=X17,"REORDER NOW",IF(U17<=X17*1.5,"LOW","OK")))) -> OUT OF STOCK | Z17: =MAX(0,'Item Master'!Q14-IF(V17<>"",V17,U17)) -> 100 | AB17: ='Item Master'!N14 -> Rack 4 – Books, Cards & Paper
A18: 11 | B18: ='Item Master'!A15 -> PRG | C18: ='Item Master'!B15 -> Radha Govinda Photo | D18: ='Item Master'!C15 -> Deity Photos & Frames | E18: ='Item Master'!F15 -> Piece | F18: =IF('Nov-2026'!V18<>"",'Nov-2026'!V18,'Nov-2026'!U18) -> 0 | O18: =N(J18)+N(N18) -> 0 | T18: =SUM(P18:S18) -> 0 | U18: =N(F18)+O18-T18 -> 0 | W18: =IF(V18="","",V18-U18) | X18: ='Item Master'!P15 -> 200 | Y18: =IF(B18="","",IF(U18<=0,"OUT OF STOCK",IF(U18<=X18,"REORDER NOW",IF(U18<=X18*1.5,"LOW","OK")))) -> OUT OF STOCK | Z18: =MAX(0,'Item Master'!Q15-IF(V18<>"",V18,U18)) -> 400 | AB18: ='Item Master'!N15 -> Rack 3 – Photos, Frames & Fragile
A19: 12 | B19: ='Item Master'!A16 -> PHN | C19: ='Item Master'!B16 -> Hanuman Photo | D19: ='Item Master'!C16 -> Deity Photos & Frames | E19: ='Item Master'!F16 -> Piece | F19: =IF('Nov-2026'!V19<>"",'Nov-2026'!V19,'Nov-2026'!U19) -> 0 | O19: =N(J19)+N(N19) -> 0 | T19: =SUM(P19:S19) -> 0 | U19: =N(F19)+O19-T19 -> 0 | W19: =IF(V19="","",V19-U19) | X19: ='Item Master'!P16 -> 100 | Y19: =IF(B19="","",IF(U19<=0,"OUT OF STOCK",IF(U19<=X19,"REORDER NOW",IF(U19<=X19*1.5,"LOW","OK")))) -> OUT OF STOCK | Z19: =MAX(0,'Item Master'!Q16-IF(V19<>"",V19,U19)) -> 200 | AB19: ='Item Master'!N16 -> Rack 3 – Photos, Frames & Fragile
... A66: 59 | B66: ='Item Master'!A63 -> YID | C66: ='Item Master'!B63 -> Yatri ID Card + Lanyard | D66: ='Item Master'!C63 -> Suggested New Items | E66: ='Item Master'!F63 -> Set | F66: =IF('Nov-2026'!V66<>"",'Nov-2026'!V66,'Nov-2026'!U66) -> 0 | O66: =N(J66)+N(N66) -> 0 | T66: =SUM(P66:S66) -> 0 | U66: =N(F66)+O66-T66 -> 0 | W66: =IF(V66="","",V66-U66) | X66: ='Item Master'!P63 -> 100 | Y66: =IF(B66="","",IF(U66<=0,"OUT OF STOCK",IF(U66<=X66,"REORDER NOW",IF(U66<=X66*1.5,"LOW","OK")))) -> OUT OF STOCK | Z66: =MAX(0,'Item Master'!Q63-IF(V66<>"",V66,U66)) -> 300 | AB66: ='Item Master'!N63 -> Rack 6 – Packing & Serving Material
C67: TOTAL (all items) | F67: =SUM(F8:F66) -> 195 | J67: =SUM(J8:J66) -> 0 | N67: =SUM(N8:N66) -> 0 | O67: =SUM(O8:O66) -> 0 | P67: =SUM(P8:P66) -> 0 | Q67: =SUM(Q8:Q66) -> 0 | R67: =SUM(R8:R66) -> 0 | S67: =SUM(S8:S66) -> 0 | T67: =SUM(T8:T66) -> 0 | U67: =SUM(U8:U66) -> 195 | V67: =SUM(V8:V66) -> 0 | Y67: =COUNTIF(Y8:Y66,"REORDER NOW")+COUNTIF(Y8:Y66,"OUT OF STOCK")&" to act" -> 59 to act | Z67: =SUM(Z8:Z66) -> 26995
A69: MONTHLY STOREROOM CHECKLIST (write Y / N and initials) | J69: Done? | K69: Initials
A70: 1 | B70: Physical count of every item done and entered in 'Physical Count'
A71: 2 | B71: All variances explained in Remarks
A72: 3 | B72: Leak test done for tilak / liquid batches packed this month
A73: 4 | B73: Best-before dates checked – items expiring within 30 days moved to front / issued first
A74: 5 | B74: FIFO followed – old stock in front, new stock behind
A75: 6 | B75: Racks cleaned; floor dry; no pests / termites / rodent signs
A76: 7 | B76: Edibles kept separate from fragrance items
A77: 8 | B77: Locked cabinet (coins, kavacha, perfume, pen drives) counted & tallied
A78: 9 | B78: QR audio links tested and working
A79: 10 | B79: Packing consumables (pouches, containers, labels) sufficient for next month
A80: 11 | B80: Upcoming festival / yatra demand checked with Yatra & Donor teams
A81: 12 | B81: Sheet signed by Storekeeper and verified by In-charge
B83: Storekeeper signature: ____________________ | I83: In-charge signature: ____________________ | R83: Date: ____________

Sheet Jan-2027
A1: Monthly Stock & Packing Register – Jan-2027
A2: Hare Krishna Movement, Hyderabad • Festivals / focus this month: Vaikuntha Ekadashi, Sankranti – Pongal prasadam (mud pots)
A3: Month: | C3: Jan-2027 | G3: Storekeeper: | M3: Physical count date: | S3: Verified by (In-charge):
A4: Yellow = type here • Green = automatic • Opening stock = last month's physical count (or book closing if not counted)
A6: ITEM & OPENING | G6: PACKING BATCH 1 | K6: PACKING BATCH 2 | O6: IN | P6: OUT (ISSUED) | U6: CLOSING & CONTROL | AA6: STORAGE & NOTES
A7: S.No | B7: Item ID | C7: Item Name | D7: Category | E7: Unit | F7: Opening Stock | G7: Date Packed | H7: Date Stored | I7: Batch No. | J7: Qty Packed | K7: Date Packed | L7: Date Stored | M7: Batch No. | N7: Qty Packed | O7: Total Packed / Received | P7: Issued – Donors | Q7: Issued – Yatris | R7: Issued – Events / Other | S7: Damaged / Expired | T7: Total Issued & Out | U7: Closing Stock (Book) | V7: Physical Count (Month End) | W7: Variance (Physical – Book) | X7: Reorder Level | Y7: Stock Status | Z7: Qty to Pack / Order Next Month | AA7: Best Before / Expiry | AB7: Storage Location | AC7: Packed By | AD7: Remarks
A8: 1 | B8: ='Item Master'!A5 -> THR | C8: ='Item Master'!B5 -> Kalasha Thread (wrist thread) | D8: ='Item Master'!C5 -> Kalasha & Yagna Prasadam | E8: ='Item Master'!F5 -> Pouch | F8: =IF('Dec-2026'!V8<>"",'Dec-2026'!V8,'Dec-2026'!U8) -> 0 | O8: =N(J8)+N(N8) -> 0 | T8: =SUM(P8:S8) -> 0 | U8: =N(F8)+O8-T8 -> 0 | W8: =IF(V8="","",V8-U8) | X8: ='Item Master'!P5 -> 300 | Y8: =IF(B8="","",IF(U8<=0,"OUT OF STOCK",IF(U8<=X8,"REORDER NOW",IF(U8<=X8*1.5,"LOW","OK")))) -> OUT OF STOCK | Z8: =MAX(0,'Item Master'!Q5-IF(V8<>"",V8,U8)) -> 600 | AB8: ='Item Master'!N5 -> Rack 1 – Prasadam & Edibles
A9: 2 | B9: ='Item Master'!A6 -> TIL | C9: ='Item Master'!B6 -> Narasimha Yagna Tilak | D9: ='Item Master'!C6 -> Kalasha & Yagna Prasadam | E9: ='Item Master'!F6 -> Container | F9: =IF('Dec-2026'!V9<>"",'Dec-2026'!V9,'Dec-2026'!U9) -> 195 | O9: =N(J9)+N(N9) -> 0 | T9: =SUM(P9:S9) -> 0 | U9: =N(F9)+O9-T9 -> 195 | W9: =IF(V9="","",V9-U9) | X9: ='Item Master'!P6 -> 300 | Y9: =IF(B9="","",IF(U9<=0,"OUT OF STOCK",IF(U9<=X9,"REORDER NOW",IF(U9<=X9*1.5,"LOW","OK")))) -> REORDER NOW | Z9: =MAX(0,'Item Master'!Q6-IF(V9<>"",V9,U9)) -> 405 | AB9: ='Item Master'!N6 -> Rack 2 – Liquids & Oils (bottom shelf, in trays)
A10: 3 | B10: ='Item Master'!A7 -> KAV | C10: ='Item Master'!B7 -> Narasimha Kavacha (protective amulet / locket) | D10: ='Item Master'!C7 -> Protection & Mantra | E10: ='Item Master'!F7 -> Piece | F10: =IF('Dec-2026'!V10<>"",'Dec-2026'!V10,'Dec-2026'!U10) -> 0 | O10: =N(J10)+N(N10) -> 0 | T10: =SUM(P10:S10) -> 0 | U10: =N(F10)+O10-T10 -> 0 | W10: =IF(V10="","",V10-U10) | X10: ='Item Master'!P7 -> 100 | Y10: =IF(B10="","",IF(U10<=0,"OUT OF STOCK",IF(U10<=X10,"REORDER NOW",IF(U10<=X10*1.5,"LOW","OK")))) -> OUT OF STOCK | Z10: =MAX(0,'Item Master'!Q7-IF(V10<>"",V10,U10)) -> 200 | AB10: ='Item Master'!N7 -> Locked Cabinet – Valuables
A11: 4 | B11: ='Item Master'!A8 -> AKV | C11: ='Item Master'!B8 -> Audio – Narasimha Kavacha (QR card) | D11: ='Item Master'!C8 -> Audio / Digital | E11: ='Item Master'!F8 -> Card | F11: =IF('Dec-2026'!V11<>"",'Dec-2026'!V11,'Dec-2026'!U11) -> 0 | O11: =N(J11)+N(N11) -> 0 | T11: =SUM(P11:S11) -> 0 | U11: =N(F11)+O11-T11 -> 0 | W11: =IF(V11="","",V11-U11) | X11: ='Item Master'!P8 -> 200 | Y11: =IF(B11="","",IF(U11<=0,"OUT OF STOCK",IF(U11<=X11,"REORDER NOW",IF(U11<=X11*1.5,"LOW","OK")))) -> OUT OF STOCK | Z11: =MAX(0,'Item Master'!Q8-IF(V11<>"",V11,U11)) -> 500 | AB11: ='Item Master'!N8 -> Rack 4 – Books, Cards & Paper
A12: 5 | B12: ='Item Master'!A9 -> AKR | C12: ='Item Master'!B9 -> Audio – Narasimha Kirtan (QR card) | D12: ='Item Master'!C9 -> Audio / Digital | E12: ='Item Master'!F9 -> Card | F12: =IF('Dec-2026'!V12<>"",'Dec-2026'!V12,'Dec-2026'!U12) -> 0 | O12: =N(J12)+N(N12) -> 0 | T12: =SUM(P12:S12) -> 0 | U12: =N(F12)+O12-T12 -> 0 | W12: =IF(V12="","",V12-U12) | X12: ='Item Master'!P9 -> 200 | Y12: =IF(B12="","",IF(U12<=0,"OUT OF STOCK",IF(U12<=X12,"REORDER NOW",IF(U12<=X12*1.5,"LOW","OK")))) -> OUT OF STOCK | Z12: =MAX(0,'Item Master'!Q9-IF(V12<>"",V12,U12)) -> 500 | AB12: ='Item Master'!N9 -> Rack 4 – Books, Cards & Paper
A13: 6 | B13: ='Item Master'!A10 -> PFR | C13: ='Item Master'!B10 -> Narasimha Photo Frame | D13: ='Item Master'!C10 -> Deity Photos & Frames | E13: ='Item Master'!F10 -> Piece | F13: =IF('Dec-2026'!V13<>"",'Dec-2026'!V13,'Dec-2026'!U13) -> 0 | O13: =N(J13)+N(N13) -> 0 | T13: =SUM(P13:S13) -> 0 | U13: =N(F13)+O13-T13 -> 0 | W13: =IF(V13="","",V13-U13) | X13: ='Item Master'!P10 -> 25 | Y13: =IF(B13="","",IF(U13<=0,"OUT OF STOCK",IF(U13<=X13,"REORDER NOW",IF(U13<=X13*1.5,"LOW","OK")))) -> OUT OF STOCK | Z13: =MAX(0,'Item Master'!Q10-IF(V13<>"",V13,U13)) -> 50 | AB13: ='Item Master'!N10 -> Rack 3 – Photos, Frames & Fragile
A14: 7 | B14: ='Item Master'!A11 -> TTP | C14: ='Item Master'!B11 -> Narasimha Table Top (idol/stand) | D14: ='Item Master'!C11 -> Deity Photos & Frames | E14: ='Item Master'!F11 -> Piece | F14: =IF('Dec-2026'!V14<>"",'Dec-2026'!V14,'Dec-2026'!U14) -> 0 | O14: =N(J14)+N(N14) -> 0 | T14: =SUM(P14:S14) -> 0 | U14: =N(F14)+O14-T14 -> 0 | W14: =IF(V14="","",V14-U14) | X14: ='Item Master'!P11 -> 20 | Y14: =IF(B14="","",IF(U14<=0,"OUT OF STOCK",IF(U14<=X14,"REORDER NOW",IF(U14<=X14*1.5,"LOW","OK")))) -> OUT OF STOCK | Z14: =MAX(0,'Item Master'!Q11-IF(V14<>"",V14,U14)) -> 40 | AB14: ='Item Master'!N11 -> Rack 3 – Photos, Frames & Fragile
A15: 8 | B15: ='Item Master'!A12 -> STK | C15: ='Item Master'!B12 -> Narasimha Sticker | D15: ='Item Master'!C12 -> Protection & Mantra | E15: ='Item Master'!F12 -> Piece | F15: =IF('Dec-2026'!V15<>"",'Dec-2026'!V15,'Dec-2026'!U15) -> 0 | O15: =N(J15)+N(N15) -> 0 | T15: =SUM(P15:S15) -> 0 | U15: =N(F15)+O15-T15 -> 0 | W15: =IF(V15="","",V15-U15) | X15: ='Item Master'!P12 -> 300 | Y15: =IF(B15="","",IF(U15<=0,"OUT OF STOCK",IF(U15<=X15,"REORDER NOW",IF(U15<=X15*1.5,"LOW","OK")))) -> OUT OF STOCK | Z15: =MAX(0,'Item Master'!Q12-IF(V15<>"",V15,U15)) -> 600 | AB15: ='Item Master'!N12 -> Rack 4 – Books, Cards & Paper
