Workbook

Sheet Read me
A1: London Europe Yatra – Minute-by-minute itinerary (DRAFT for fine-tuning)
A2: Hare Krishna! Everything here can be edited. Durations and daily km recalculate automatically.
A4: Yatra | B4: London Europe Yatra with Hare Krishna Devotees — 8 countries
A5: Dates | B5: 17 April – 2 May 2027 (15 nights / 16 days). Out: Hyderabad EK 525/EK 31 (LHR T3 16:10) and Bangalore EY 1013/EY 67 (LHR T4 18:45) on 17 Apr. Back: EY 82 Malpensa 11:40 on 2 May → Abu Dhabi → EY 352 Hyderabad 02:45 / EY 232 Bangalore 03:15 on 3 May.
A6: Countries | B6: United Kingdom, France, Belgium, Netherlands, Germany, Switzerland, Italy, Vatican City
A7: Organised by | B7: Hare Krishna Golden Temple, Banjara Hills, Hyderabad (Punya Kshetras)
A8: Contact | B8: +91 95053 88886 · www.punyakshetras.com · www.hkmhyderabad.org
A9: Package price | B9: ₹5,00,000 per person (all inclusive, all flights) + 5% GST + 5% TCS (TCS claimable against income tax)
A10: Mode of transport | B10: Private coach for every road movement. Exceptions are marked in the Mode column: Flight, Ferry (Dover–Calais), Boat, Cable car (Titlis), Train (Lucerne–Interlaken).
A11: Meals | B11: Breakfast: hotel (complimentary). Lunch: Indian restaurant or ISKCON temple prasadam near the sightseeing. Dinner: at the hotel (Satvik menu pre-agreed or an Indian caterer delivering). The 'Provided by' column names the provider for every meal.
A12: Distances & times | B12: Coach estimates from route knowledge, NOT live Google Maps results. Click the 'Route' link on each movement to verify km and time, then overwrite the numbers. Coaches are slower than cars.
A13: Time zones | B13: Times are local. UK = BST (IST − 4:30). Continent = CEST (IST − 3:30). Abu Dhabi = GST (IST − 1:30). Flight and ferry rows show local clock times; their Duration is the real elapsed time.
A14: Ekadasi | B14: Kamada Ekadasi 17 Apr (travel day; break fast London 18 Apr 05:59–10:40). Varuthini Ekadasi 2 May (flight home; break fast in India 3 May before ~10:00).
A15: Status column | B15: Use the dropdown: Draft → To verify → Booked → Confirmed. Filter on it to see what is still open.
... A17: Source | B17: 2024 posters (15N/16D, 8 countries), brochure PDF, inclusions/exclusions sheet, Schengen biometric guidelines, shortlisted 2027 flights, team budget sheet; prices and events checked 22 Oct 2026.

Sheet Budget
A1: Budget per yatri – cost against the ₹5,00,000 price
A2: Blue cells are inputs. Group costs are divided by the number of yatris. GST (5%) and TCS (5%) are collected on top of the price and passed on, so they are not costs here.
A4: Yatris (paying) | B4: 40
A5: Package price per person (₹) | B5: 500000
A6: Contingency (% of costs) | B6: 0.05
A7: INR per 1 GBP | B7: ='Entry tickets'!B4 -> 126.78
A8: INR per 1 EUR | B8: ='Entry tickets'!B5 -> 106.13
A9: INR per 1 CHF | B9: ='Entry tickets'!B6 -> 114.66
A11: Hotels (twin share) | B11: Nights | C11: Room rate / night | D11: Currency | E11: Per person (₹)
A12: London (Wembley) | B12: 3 | C12: 165 | D12: GBP | E12: =B12*C12*$B$7/2 -> 31378.05
A13: Paris | B13: 2 | C13: 195 | D13: EUR | E13: =B13*C13*$B$8/2 -> 20695.35
A14: Brussels | B14: 1 | C14: 130 | D14: EUR | E14: =B14*C14*$B$8/2 -> 6898.45
A15: Amsterdam | B15: 1 | C15: 210 | D15: EUR | E15: =B15*C15*$B$8/2 -> 11143.65
A16: Cologne | B16: 1 | C16: 130 | D16: EUR | E16: =B16*C16*$B$8/2 -> 6898.45
A17: Titisee | B17: 1 | C17: 145 | D17: EUR | E17: =B17*C17*$B$8/2 -> 7694.425
A18: Zurich | B18: 1 | C18: 215 | D18: CHF | E18: =B18*C18*$B$9/2 -> 12325.95
A19: Interlaken | B19: 1 | C19: 250 | D19: CHF | E19: =B19*C19*$B$9/2 -> 14332.5
A20: Milan | B20: 1 | C20: 155 | D20: EUR | E20: =B20*C20*$B$8/2 -> 8225.075
A21: Venice-Mestre | B21: 1 | C21: 135 | D21: EUR | E21: =B21*C21*$B$8/2 -> 7163.775
A22: Florence | B22: 1 | C22: 170 | D22: EUR | E22: =B22*C22*$B$8/2 -> 9021.05
A23: Near Malpensa | B23: 1 | C23: 120 | D23: EUR | E23: =B23*C23*$B$8/2 -> 6367.8
A24: Total hotels | B24: =SUM(B12:B23) -> 15 | E24: =SUM(E12:E23) -> 142144.52
A26: Cost line | B26: Basis | C26: Amount | D26: Currency | E26: ₹ per person | F26: Team sheet ₹ | G26: Difference ₹ | H26: Group total ₹ | I26: Note
A27: UK visa (£135) | B27: pp | C27: 135 | D27: GBP | E27: =C27*$B$7 -> 17115.3 | F27: 18000 | G27: =IF(F27="","",E27-F27) -> -884.7 | H27: =E27*$B$4 -> 684612 | I27: gov.uk fee from 8 Apr 2026
A28: Schengen visa (€90) | B28: pp | C28: 90 | D28: EUR | E28: =C28*$B$8 -> 9551.7 | F28: 10000 | G28: =IF(F28="","",E28-F28) -> -448.3 | H28: =E28*$B$4 -> 382068 | I28: Standard fee
A29: Visa centre charges, photos, courier | B29: pp | C29: 6000 | D29: INR | E29: =C29*1 -> 6000 | F29: 6000 | G29: =IF(F29="","",E29-F29) -> 0 | H29: =E29*$B$4 -> 240000 | I29: VFS UK ~₹1,500 + Schengen ~₹2,300 + documents
A30: Flights – round trip (shortlisted fares) | B30: pp | C30: 70019 | D30: INR | E30: =C30*1 -> 70019 | F30: 70000 | G30: =IF(F30="","",E30-F30) -> 19 | H30: =E30*$B$4 -> 2800760 | I30: HYD ₹70,019; BLR ₹68,012; ask for a group fare
A31: Hotels – 15 nights twin share (see hotel table) | B31: hotels | D31: INR | E31: =E24 -> 142144.52 | F31: 105000 | G31: =IF(F31="","",E31-F31) -> 37144.525 | H31: =E31*$B$4 -> 5685781 | I31: Estimate from late-April rates; team sheet assumes ₹7,000 a night
A32: Hotel city taxes | B32: pp | C32: 63 | D32: EUR | E32: =C32*$B$8 -> 6686.19 | G32: =IF(F32="","",E32-F32) | H32: =E32*$B$4 -> 267447.6 | I32: Amsterdam 16% in 2027, Paris €5.53, Milan €7–10 ...
A33: Meals – lunch & dinner (24 paid meals + temple donations) | B33: pp | C33: 75000 | D33: INR | E33: =C33*1 -> 75000 | F33: 75000 | G33: =IF(F33="","",E33-F33) -> 0 | H33: =E33*$B$4 -> 3000000 | I33: Kept at team figure; covers Ekadasi extras, water, snacks
A34: Coach 16 days (€1,100/day) | B34: group | C34: 17600 | D34: EUR | E34: =C34*$B$8/$B$4 -> 46697.2 | F34: 80000 | G34: =IF(F34="","",E34-F34) -> -33302.8 | H34: =E34*$B$4 -> 1867888 | I34: Estimate; ending in Milan may add a repositioning charge
A35: Coach: driver hotel & meals, tolls, repositioning | B35: group | C35: 5500 | D35: EUR | E35: =C35*$B$8/$B$4 -> 14592.875 | G35: =IF(F35="","",E35-F35) | H35: =E35*$B$4 -> 583715 | I35: Driver room often free; tolls €1,200–1,800; one-way €2,000
A36: Coach permits & parking (Venice €310, Florence, Zaanse, Milan) + Rome local coach | B36: group | C36: 1500 | D36: EUR | E36: =C36*$B$8/$B$4 -> 3979.875 | G36: =IF(F36="","",E36-F36) | H36: =E36*$B$4 -> 159195 | I36: Swiss PSVA ~CHF 66 included
A37: Dover–Calais ferry (coach + 40) | B37: group | C37: 550 | D37: GBP | E37: =C37*$B$7/$B$4 -> 1743.225 | G37: =IF(F37="","",E37-F37) | H37: =E37*$B$4 -> 69729 | I37: Quote from DFDS / P&O groups desk
A38: Frecciarossa Venice→Rome→Florence (group fare) | B38: pp | C38: 98 | D38: EUR | E38: =C38*$B$8 -> 10400.74 | G38: =IF(F38="","",E38-F38) | H38: =E38*$B$4 -> 416029.6 | I38: 30% group discount; 1 free per 12
A39: Entry tickets (planned) – from Entry tickets sheet | B39: tickets | D39: INR | E39: ='Entry tickets'!F44 -> 50841.28 | F39: 50000 | G39: =IF(F39="","",E39-F39) -> 841.28 | H39: =E39*$B$4 -> 2033651.2 | I39: Linked to the Entry tickets sheet
A40: Licensed guides (London, Louvre, Vatican ×2, Colosseum ×2, Florence ×2, Venice ×2) | B40: group | C40: 2300 | D40: EUR | E40: =C40*$B$8/$B$4 -> 6102.475 | G40: =IF(F40="","",E40-F40) | H40: =E40*$B$4 -> 244099 | I40: Plus London Blue Badge £229 within this estimate
A41: Whisper headsets (6 guided days) | B41: pp | C41: 15 | D41: EUR | E41: =C41*$B$8 -> 1591.95 | G41: =IF(F41="","",E41-F41) | H41: =E41*$B$4 -> 63678 | I41: Compulsory at the Vatican
A42: Travel insurance (incl. UK, seniors) | B42: pp | C42: 4000 | D42: INR | E42: =C42*1 -> 4000 | F42: 3000 | G42: =IF(F42="","",E42-F42) -> 1000 | H42: =E42*$B$4 -> 160000 | I42: ₹2,000–3,500 for 61–70; ₹4,000–8,000 for 71–80
A43: Tour manager (fee, flight, visa, room, meals) | B43: group | C43: 440000 | D43: INR | E43: =C43*1/$B$4 -> 11000 | G43: =IF(F43="","",E43-F43) | H43: =E43*$B$4 -> 440000 | I43: Estimate for an Indian tour manager, 17 days
...

Sheet Day summary
A1: Day | B1: Date | C1: Route | D1: Overnight | E1: Coach km | F1: Coach time incl. breaks (h:mm) | G1: Driver-hours check (EU: max 9 h/day) | H1: First start | I1: Last end
A3: 1 | B3: 46494 | C3: Hyderabad & Bangalore → London Heathrow · Kamada Ekadasi | D3: London (Wembley) | E3: =SUMIFS('Minute-by-minute'!$K$3:$K$234,'Minute-by-minute'!$A$3:$A$234,A3,'Minute-by-minute'!$J$3:$J$234,"Coach") -> 75 | F3: =SUMIFS('Minute-by-minute'!$F$3:$F$234,'Minute-by-minute'!$A$3:$A$234,A3,'Minute-by-minute'!$J$3:$J$234,"Coach")/1440 -> 0.090277778 | G3: =IF(F3*24>9,"OVER 9 h – revise",IF(F3*24>6,"Long day – 45 min break + rest stops",IF(F3*24>4.5,"45 min break needed","OK"))) -> OK | H3: =_xlfn.MINIFS('Minute-by-minute'!$D$3:$D$234,'Minute-by-minute'!$A$3:$A$234,A3) -> 0.069444444 | I3: =_xlfn.MAXIFS('Minute-by-minute'!$E$3:$E$234,'Minute-by-minute'!$A$3:$A$234,A3) -> 0.91666667
A4: 2 | B4: 46495 | C4: Bhaktivedanta Manor Sunday programme · Oxford · Cotswolds | D4: London (Wembley) | E4: =SUMIFS('Minute-by-minute'!$K$3:$K$234,'Minute-by-minute'!$A$3:$A$234,A4,'Minute-by-minute'!$J$3:$J$234,"Coach") -> 302 | F4: =SUMIFS('Minute-by-minute'!$F$3:$F$234,'Minute-by-minute'!$A$3:$A$234,A4,'Minute-by-minute'!$J$3:$J$234,"Coach")/1440 -> 0.23263889 | G4: =IF(F4*24>9,"OVER 9 h – revise",IF(F4*24>6,"Long day – 45 min break + rest stops",IF(F4*24>4.5,"45 min break needed","OK"))) -> 45 min break needed | H4: =_xlfn.MINIFS('Minute-by-minute'!$D$3:$D$234,'Minute-by-minute'!$A$3:$A$234,A4) -> 0.25 | I4: =_xlfn.MAXIFS('Minute-by-minute'!$E$3:$E$234,'Minute-by-minute'!$A$3:$A$234,A4) -> 0.91666667
A5: 3 | B5: 46496 | C5: London city: Westminster · London Eye · Thames · Tower · Tussauds · Soho temple | D5: London (Wembley) | E5: =SUMIFS('Minute-by-minute'!$K$3:$K$234,'Minute-by-minute'!$A$3:$A$234,A5,'Minute-by-minute'!$J$3:$J$234,"Coach") -> 46 | F5: =SUMIFS('Minute-by-minute'!$F$3:$F$234,'Minute-by-minute'!$A$3:$A$234,A5,'Minute-by-minute'!$J$3:$J$234,"Coach")/1440 -> 0.125 | G5: =IF(F5*24>9,"OVER 9 h – revise",IF(F5*24>6,"Long day – 45 min break + rest stops",IF(F5*24>4.5,"45 min break needed","OK"))) -> OK | H5: =_xlfn.MINIFS('Minute-by-minute'!$D$3:$D$234,'Minute-by-minute'!$A$3:$A$234,A5) -> 0.25 | I5: =_xlfn.MAXIFS('Minute-by-minute'!$E$3:$E$234,'Minute-by-minute'!$A$3:$A$234,A5) -> 0.91666667
A6: 4 | B6: 46497 | C6: London → Dover → ferry → Calais → Paris · Balarama Rasayatra | D6: Paris | E6: =SUMIFS('Minute-by-minute'!$K$3:$K$234,'Minute-by-minute'!$A$3:$A$234,A6,'Minute-by-minute'!$J$3:$J$234,"Coach") -> 430 | F6: =SUMIFS('Minute-by-minute'!$F$3:$F$234,'Minute-by-minute'!$A$3:$A$234,A6,'Minute-by-minute'!$J$3:$J$234,"Coach")/1440 -> 0.26041667 | G6: =IF(F6*24>9,"OVER 9 h – revise",IF(F6*24>6,"Long day – 45 min break + rest stops",IF(F6*24>4.5,"45 min break needed","OK"))) -> Long day – 45 min break + rest stops | H6: =_xlfn.MINIFS('Minute-by-minute'!$D$3:$D$234,'Minute-by-minute'!$A$3:$A$234,A6) -> 0.25 | I6: =_xlfn.MAXIFS('Minute-by-minute'!$E$3:$E$234,'Minute-by-minute'!$A$3:$A$234,A6) -> 0.91666667
A7: 5 | B7: 46498 | C7: Paris: Arc de Triomphe · Eiffel Tower · Notre-Dame · ISKCON Paris · Seine cruise | D7: Paris | E7: =SUMIFS('Minute-by-minute'!$K$3:$K$234,'Minute-by-minute'!$A$3:$A$234,A7,'Minute-by-minute'!$J$3:$J$234,"Coach") -> 71 | F7: =SUMIFS('Minute-by-minute'!$F$3:$F$234,'Minute-by-minute'!$A$3:$A$234,A7,'Minute-by-minute'!$J$3:$J$234,"Coach")/1440 -> 0.17013889 | G7: =IF(F7*24>9,"OVER 9 h – revise",IF(F7*24>6,"Long day – 45 min break + rest stops",IF(F7*24>4.5,"45 min break needed","OK"))) -> OK | H7: =_xlfn.MINIFS('Minute-by-minute'!$D$3:$D$234,'Minute-by-minute'!$A$3:$A$234,A7) -> 0.25 | I7: =_xlfn.MAXIFS('Minute-by-minute'!$E$3:$E$234,'Minute-by-minute'!$A$3:$A$234,A7) -> 0.94097222
A8: 6 | B8: 46499 | C8: Louvre → Brussels: Atomium · Grand Place · Manneken Pis | D8: Brussels | E8: =SUMIFS('Minute-by-minute'!$K$3:$K$234,'Minute-by-minute'!$A$3:$A$234,A8,'Minute-by-minute'!$J$3:$J$234,"Coach") -> 333 | F8: =SUMIFS('Minute-by-minute'!$F$3:$F$234,'Minute-by-minute'!$A$3:$A$234,A8,'Minute-by-minute'!$J$3:$J$234,"Coach")/1440 -> 0.22916667 | G8: =IF(F8*24>9,"OVER 9 h – revise",IF(F8*24>6,"Long day – 45 min break + rest stops",IF(F8*24>4.5,"45 min break needed","OK"))) -> 45 min break needed | H8: =_xlfn.MINIFS('Minute-by-minute'!$D$3:$D$234,'Minute-by-minute'!$A$3:$A$234,A8) -> 0.25 | I8: =_xlfn.MAXIFS('Minute-by-minute'!$E$3:$E$234,'Minute-by-minute'!$A$3:$A$234,A8) -> 0.89583333
A9: 7 | B9: 46500 | C9: ISKCON Radhadesh (Durbuy) → Amsterdam · canal cruise | D9: Amsterdam | E9: =SUMIFS('Minute-by-minute'!$K$3:$K$234,'Minute-by-minute'!$A$3:$A$234,A9,'Minute-by-minute'!$J$3:$J$234,"Coach") -> 435 | F9: =SUMIFS('Minute-by-minute'!$F$3:$F$234,'Minute-by-minute'!$A$3:$A$234,A9,'Minute-by-minute'!$J$3:$J$234,"Coach")/1440 -> 0.26736111 | G9: =IF(F9*24>9,"OVER 9 h – revise",IF(F9*24>6,"Long day – 45 min break + rest stops",IF(F9*24>4.5,"45 min break needed","OK"))) -> Long day – 45 min break + rest stops | H9: =_xlfn.MINIFS('Minute-by-minute'!$D$3:$D$234,'Minute-by-minute'!$A$3:$A$234,A9) -> 0.25 | I9: =_xlfn.MAXIFS('Minute-by-minute'!$E$3:$E$234,'Minute-by-minute'!$A$3:$A$234,A9) -> 0.93055556
A10: 8 | B10: 46501 | C10: Zaanse Schans windmills · Keukenhof tulip gardens → Cologne | D10: Cologne | E10: =SUMIFS('Minute-by-minute'!$K$3:$K$234,'Minute-by-minute'!$A$3:$A$234,A10,'Minute-by-minute'!$J$3:$J$234,"Coach") -> 335 | F10: =SUMIFS('Minute-by-minute'!$F$3:$F$234,'Minute-by-minute'!$A$3:$A$234,A10,'Minute-by-minute'!$J$3:$J$234,"Coach")/1440 -> 0.19791667 | G10: =IF(F10*24>9,"OVER 9 h – revise",IF(F10*24>6,"Long day – 45 min break + rest stops",IF(F10*24>4.5,"45 min break needed","OK"))) -> 45 min break needed | H10: =_xlfn.MINIFS('Minute-by-minute'!$D$3:$D$234,'Minute-by-minute'!$A$3:$A$234,A10) -> 0.25 | I10: =_xlfn.MAXIFS('Minute-by-minute'!$E$3:$E$234,'Minute-by-minute'!$A$3:$A$234,A10) -> 0.89583333
A11: 9 | B11: 46502 | C11: Cologne · ISKCON Cologne → Goloka Dham Sunday programme → Black Forest | D11: Titisee (Black Forest) | E11: =SUMIFS('Minute-by-minute'!$K$3:$K$234,'Minute-by-minute'!$A$3:$A$234,A11,'Minute-by-minute'!$J$3:$J$234,"Coach") -> 530 | F11: =SUMIFS('Minute-by-minute'!$F$3:$F$234,'Minute-by-minute'!$A$3:$A$234,A11,'Minute-by-minute'!$J$3:$J$234,"Coach")/1440 -> 0.3125 | G11: =IF(F11*24>9,"OVER 9 h – revise",IF(F11*24>6,"Long day – 45 min break + rest stops",IF(F11*24>4.5,"45 min break needed","OK"))) -> Long day – 45 min break + rest stops | H11: =_xlfn.MINIFS('Minute-by-minute'!$D$3:$D$234,'Minute-by-minute'!$A$3:$A$234,A11) -> 0.25 | I11: =_xlfn.MAXIFS('Minute-by-minute'!$E$3:$E$234,'Minute-by-minute'!$A$3:$A$234,A11) -> 0.89583333
A12: 10 | B12: 46503 | C12: Lake Titisee · cuckoo clocks → Rhine Falls → Zurich · ISKCON Zurich | D12: Zurich | E12: =SUMIFS('Minute-by-minute'!$K$3:$K$234,'Minute-by-minute'!$A$3:$A$234,A12,'Minute-by-minute'!$J$3:$J$234,"Coach") -> 127 | F12: =SUMIFS('Minute-by-minute'!$F$3:$F$234,'Minute-by-minute'!$A$3:$A$234,A12,'Minute-by-minute'!$J$3:$J$234,"Coach")/1440 -> 0.11458333 | G12: =IF(F12*24>9,"OVER 9 h – revise",IF(F12*24>6,"Long day – 45 min break + rest stops",IF(F12*24>4.5,"45 min break needed","OK"))) -> OK | H12: =_xlfn.MINIFS('Minute-by-minute'!$D$3:$D$234,'Minute-by-minute'!$A$3:$A$234,A12) -> 0.25 | I12: =_xlfn.MAXIFS('Minute-by-minute'!$E$3:$E$234,'Minute-by-minute'!$A$3:$A$234,A12) -> 0.85416667
A13: 11 | B13: 46504 | C13: Mount Titlis (snow) · Lucerne · Lion Monument · lake cruise → train to Interlaken | D13: Interlaken | E13: =SUMIFS('Minute-by-minute'!$K$3:$K$234,'Minute-by-minute'!$A$3:$A$234,A13,'Minute-by-minute'!$J$3:$J$234,"Coach") -> 190 | F13: =SUMIFS('Minute-by-minute'!$F$3:$F$234,'Minute-by-minute'!$A$3:$A$234,A13,'Minute-by-minute'!$J$3:$J$234,"Coach")/1440 -> 0.13888889 | G13: =IF(F13*24>9,"OVER 9 h – revise",IF(F13*24>6,"Long day – 45 min break + rest stops",IF(F13*24>4.5,"45 min break needed","OK"))) -> OK | H13: =_xlfn.MINIFS('Minute-by-minute'!$D$3:$D$234,'Minute-by-minute'!$A$3:$A$234,A13) -> 0.25 | I13: =_xlfn.MAXIFS('Minute-by-minute'!$E$3:$E$234,'Minute-by-minute'!$A$3:$A$234,A13) -> 0.89583333
A14: 12 | B14: 46505 | C14: Interlaken → Gotthard → Lake Como → Villaggio Hare Krishna → Milan | D14: Milan | E14: =SUMIFS('Minute-by-minute'!$K$3:$K$234,'Minute-by-minute'!$A$3:$A$234,A14,'Minute-by-minute'!$J$3:$J$234,"Coach") -> 380 | F14: =SUMIFS('Minute-by-minute'!$F$3:$F$234,'Minute-by-minute'!$A$3:$A$234,A14,'Minute-by-minute'!$J$3:$J$234,"Coach")/1440 -> 0.27083333 | G14: =IF(F14*24>9,"OVER 9 h – revise",IF(F14*24>6,"Long day – 45 min break + rest stops",IF(F14*24>4.5,"45 min break needed","OK"))) -> Long day – 45 min break + rest stops | H14: =_xlfn.MINIFS('Minute-by-minute'!$D$3:$D$234,'Minute-by-minute'!$A$3:$A$234,A14) -> 0.25 | I14: =_xlfn.MAXIFS('Minute-by-minute'!$E$3:$E$234,'Minute-by-minute'!$A$3:$A$234,A14) -> 0.89583333
... A18: 16 | B18: 46509 | C18: Varuthini Ekadasi · Milan Malpensa → Abu Dhabi → Hyderabad / Bangalore | D18: On flight (land 3 May) | E18: =SUMIFS('Minute-by-minute'!$K$3:$K$234,'Minute-by-minute'!$A$3:$A$234,A18,'Minute-by-minute'!$J$3:$J$234,"Coach") -> 10 | F18: =SUMIFS('Minute-by-minute'!$F$3:$F$234,'Minute-by-minute'!$A$3:$A$234,A18,'Minute-by-minute'!$J$3:$J$234,"Coach")/1440 -> 0.013888889 | G18: =IF(F18*24>9,"OVER 9 h – revise",IF(F18*24>6,"Long day – 45 min break + rest stops",IF(F18*24>4.5,"45 min break needed","OK"))) -> OK | H18: =_xlfn.MINIFS('Minute-by-minute'!$D$3:$D$234,'Minute-by-minute'!$A$3:$A$234,A18) -> 0.27083333 | I18: =_xlfn.MAXIFS('Minute-by-minute'!$E$3:$E$234,'Minute-by-minute'!$A$3:$A$234,A18) -> 0.81944444
C19: TOTAL by coach | E19: =SUM(E3:E18) -> 4239 | F19: =SUM(F3:F18) -> 3.0555556
C21: Day 1 and Day 16 flights, the ferry, boats, cable cars and the train are excluded from coach km and hours.

Sheet Minute-by-minute
A1: Day | B1: Date | C1: Time zone | D1: Start | E1: End | F1: Duration (min) | G1: Type | H1: From | I1: To / Place | J1: Mode | K1: Distance (km) | L1: Activities & details | M1: Meal provided by | N1: Google Maps | O1: Notes / to verify | P1: Status
A3: 1 | B3: 46494 | C3: BST | G3: DAY 1 · Sat | I3: Hyderabad & Bangalore → London Heathrow · Kamada Ekadasi | L3: Overnight: London (Wembley)
A4: 1 | B4: 46494 | C4: IST | D4: 0.069444444 | E4: 0.16666667 | F4: =ROUND(MOD(E4-D4,1)*1440,0) -> 140 | G4: Reporting | I4: Rajiv Gandhi International Airport (HYD) | J4: Walk | L4: HYDERABAD GROUP: report at RGIA departures (3 h before). Tour manager hands over tickets, insurance, kit (cap, bag, ID card, name badge). Group check-in on Emirates; bag drop. 25 kg check-in + 7 kg cabin. Today is Kamada Ekadasi: fruit meals (FPML) pre-ordered on both flights. | N4: Location | P4: Draft
A5: 1 | B5: 46494 | C5: IST→BST | D5: 0.19444444 | E5: 0.67361111 | F5: 960 | G5: Flight transfer | H5: Rajiv Gandhi International Airport (HYD) | I5: Heathrow Terminal 3 | J5: Flight | K5: 7700 | L5: HYDERABAD GROUP: Emirates EK 525 HYD 04:40 → Dubai 06:45 (T3); 4 h 40 m layover; EK 31 Dubai 11:25 → Heathrow T3 16:10. Ekadasi: fruit meals on board; carry dry fruits, nuts, makhana. | N5: Route | O5: 16 h 00 m door to door. Fare ₹35,338 (cancellation fee applies). | P5: Draft
A6: 1 | B6: 46494 | C6: IST | D6: 0.29166667 | E6: 0.38541667 | F6: =ROUND(MOD(E6-D6,1)*1440,0) -> 135 | G6: Reporting | I6: Kempegowda International Airport (BLR), T2 | J6: Walk | L6: BANGALORE GROUP: report at Kempegowda T2 (3 h before). Group check-in on Etihad (first leg operated by Akasa Air); confirm bags are checked through to London. 30 kg check-in + 7 kg cabin. Ekadasi fruit meals pre-ordered. | N6: Location | P6: Draft
A7: 1 | B7: 46494 | C7: IST→BST | D7: 0.41666667 | E7: 0.78125 | F7: 795 | G7: Flight transfer | H7: Kempegowda International Airport (BLR), T2 | I7: Heathrow Terminal 4 | J7: Flight | K7: 8000 | L7: BANGALORE GROUP: Etihad EY 1013 (Akasa Air) BLR T2 10:00 → Abu Dhabi 12:35; 1 h 35 m layover; EY 67 Abu Dhabi 14:10 → Heathrow T4 18:45. | N7: Route | O7: 13 h 15 m. Tight-ish connection at AUH; fare ₹31,998 (non-refundable). | P7: Draft
A8: 1 | B8: 46494 | C8: BST | D8: 0.67361111 | E8: 0.72916667 | F8: =ROUND(MOD(E8-D8,1)*1440,0) -> 80 | G8: Arrival | I8: Heathrow Terminal 3 | J8: Walk | L8: HYDERABAD GROUP: UK Border (eVisa linked to passport), baggage claim, meet the tour manager at the T3 coach park. Headcount. | N8: Location | P8: Draft
A9: 1 | B9: 46494 | C9: BST | D9: 0.72916667 | E9: 0.76041667 | F9: =ROUND(MOD(E9-D9,1)*1440,0) -> 45 | G9: Coach transfer | H9: Heathrow Terminal 3 | I9: Hotel, Wembley area (TBC) | J9: Coach | K9: 25 | L9: Coach run 1: Hyderabad group to the hotel. Welcome talk, group rules, WhatsApp group, SIM/eSIM help. | N9: Route | P9: Draft
A10: 1 | B10: 46494 | C10: BST | D10: 0.76041667 | E10: 0.79166667 | F10: =ROUND(MOD(E10-D10,1)*1440,0) -> 45 | G10: Hotel check-in | I10: Hotel, Wembley area (TBC) | J10: Walk | L10: Hyderabad group check-in, rest. | N10: Location | P10: Draft
A11: 1 | B11: 46494 | C11: BST | D11: 0.76388889 | E11: 0.79166667 | F11: =ROUND(MOD(E11-D11,1)*1440,0) -> 40 | G11: Coach transfer | H11: Hotel, Wembley area (TBC) | I11: Heathrow Terminal 4 | J11: Coach | K11: 25 | L11: Coach run 2 (empty) back to Heathrow T4 for the Bangalore group. | N11: Route | P11: Draft
A12: 1 | B12: 46494 | C12: BST | D12: 0.8125 | E12: 0.85416667 | F12: =ROUND(MOD(E12-D12,1)*1440,0) -> 60 | G12: Dinner | I12: Hotel, Wembley area (TBC) | J12: — | L12: Hyderabad group dinner. No grains, beans, onion or garlic: fruit, potato, sabudana, paneer, nuts, milk. | M12: Hotel / Indian caterer – Ekadasi (grain-free) menu | N12: Location | P12: Draft
A13: 1 | B13: 46494 | C13: BST | D13: 0.78125 | E13: 0.82291667 | F13: =ROUND(MOD(E13-D13,1)*1440,0) -> 60 | G13: Arrival | I13: Heathrow Terminal 4 | J13: Walk | L13: BANGALORE GROUP: UK Border, baggage claim, meet the coach at T4. Headcount. | N13: Location | P13: Draft
A14: 1 | B14: 46494 | C14: BST | D14: 0.82291667 | E14: 0.85416667 | F14: =ROUND(MOD(E14-D14,1)*1440,0) -> 45 | G14: Coach transfer | H14: Heathrow Terminal 4 | I14: Hotel, Wembley area (TBC) | J14: Coach | K14: 25 | L14: Coach run 2: Bangalore group to the hotel. | N14: Route | P14: Draft
A15: 1 | B15: 46494 | C15: BST | D15: 0.86458333 | E15: 0.89583333 | F15: =ROUND(MOD(E15-D15,1)*1440,0) -> 45 | G15: Dinner | I15: Hotel, Wembley area (TBC) | J15: — | L15: Bangalore group dinner. | M15: Hotel / Indian caterer – Ekadasi (grain-free) menu | N15: Location | P15: Draft
A16: 1 | B16: 46494 | C16: BST | D16: 0.89583333 | E16: 0.91666667 | F16: =ROUND(MOD(E16-D16,1)*1440,0) -> 30 | G16: Briefing | I16: Hotel, Wembley area (TBC) | J16: Walk | L16: Joint welcome kirtan and briefing. Tomorrow: break fast (Dvadasi parana) 05:59–10:40 at breakfast (07:00–09:00); coach 09:00. Sunset tonight about 20:05; jet lag: sleep by 22:30. | N16: Location | P16: Draft
A17: 2 | B17: 46495 | C17: BST | G17: DAY 2 · Sun | I17: Bhaktivedanta Manor Sunday programme · Oxford · Cotswolds | L17: Overnight: London (Wembley)
A18: 2 | B18: 46495 | C18: BST | D18: 0.25 | E18: 0.29166667 | F18: =ROUND(MOD(E18-D18,1)*1440,0) -> 60 | G18: Morning programme | I18: Hotel, Wembley area (TBC) | J18: Walk | L18: Japa (16 rounds at own pace), short kirtan and Bhagavatam reading in the hotel hall or lobby (before breakfast; optional). | N18: Location | P18: Draft
A19: 2 | B19: 46495 | C19: BST | D19: 0.29166667 | E19: 0.375 | F19: =ROUND(MOD(E19-D19,1)*1440,0) -> 120 | G19: Breakfast | I19: Hotel, Wembley area (TBC) | J19: — | L19: Break the Ekadasi fast with grains at breakfast. | M19: Hotel – complimentary buffet (07:00–09:00) – Dvadasi break fast between 05:59 and 10:40 (London) | N19: Location | P19: Draft
A20: 2 | B20: 46495 | C20: BST | D20: 0.375 | E20: 0.40625 | F20: =ROUND(MOD(E20-D20,1)*1440,0) -> 45 | G20: Coach transfer | H20: Hotel, Wembley area (TBC) | I20: Bhaktivedanta Manor, ISKCON (Watford) | J20: Coach | K20: 22 | L20: Coach to Watford. Use the Hilfield Lane entrance (sat-nav WD25 8HE). | N20: Route | P20: Draft
A21: 2 | B21: 46495 | C21: BST | D21: 0.40625 | E21: 0.47916667 | F21: =ROUND(MOD(E21-D21,1)*1440,0) -> 105 | G21: Temple darshan | I21: Bhaktivedanta Manor, ISKCON (Watford) | J21: Walk | L21: Bhaktivedanta Manor: darshan of Sri Sri Radha-Gokulananda and Sita-Rama-Lakshmana-Hanuman, Srila Prabhupada's rooms, gardens, lake and goshala. Story of George Harrison's gift of the Manor. | N21: Location | P21: Draft
A22: 2 | B22: 46495 | C22: BST | D22: 0.47916667 | E22: 0.54166667 | F22: =ROUND(MOD(E22-D22,1)*1440,0) -> 90 | G22: Spiritual programme | I22: Bhaktivedanta Manor, ISKCON (Watford) | J22: Walk | L22: Sunday Love Feast programme: kirtan and Bhagavad-gita class with the London devotees. | N22: Location | O22: Morning Sunday programme 11:30–13:00 (last entry 11:45). Free; tel. 01923 851000. Inform the Manor of a 40-person group. | P22: Draft
A23: 2 | B23: 46495 | C23: BST | D23: 0.54166667 | E23: 0.57291667 | F23: =ROUND(MOD(E23-D23,1)*1440,0) -> 45 | G23: Lunch | I23: Bhaktivedanta Manor, ISKCON (Watford) | J23: — | M23: Bhaktivedanta Manor – Sunday feast prasadam (donation) | N23: Location | P23: Draft
A24: 2 | B24: 46495 | C24: BST | D24: 0.57291667 | E24: 0.63541667 | F24: =ROUND(MOD(E24-D24,1)*1440,0) -> 90 | G24: Coach transfer | H24: Bhaktivedanta Manor, ISKCON (Watford) | I24: Oxford University – Radcliffe Camera | J24: Coach | K24: 85 | L24: Coach via M25/M40 to Oxford. | N24: Route | P24: Draft
A25: 2 | B25: 46495 | C25: BST | D25: 0.63541667 | E25: 0.69791667 | F25: =ROUND(MOD(E25-D25,1)*1440,0) -> 90 | G25: Sightseeing | I25: Oxford University – Radcliffe Camera | J25: Walk | L25: Guided walk: Radcliffe Camera, Bodleian courtyard, Bridge of Sighs, Sheldonian Theatre, Christ Church exterior, Broad Street. Narration: Oxford and Sanskrit (Boden chair, Monier-Williams). | N25: Location | O25: Trinity term reportedly starts 25 April; Christ Church needs groups of 12+ to book 3 days ahead. | P25: Draft
A26: 2 | B26: 46495 | C26: BST | D26: 0.69791667 | E26: 0.74305556 | F26: =ROUND(MOD(E26-D26,1)*1440,0) -> 65 | G26: Coach transfer | H26: Oxford University – Radcliffe Camera | I26: Bourton-on-the-Water, Cotswolds | J26: Coach | K26: 55 | L26: Coach through the Cotswold hills (A40/A429). | N26: Route | P26: Draft
A27: 2 | B27: 46495 | C27: BST | D27: 0.74305556 | E27: 0.79166667 | F27: =ROUND(MOD(E27-D27,1)*1440,0) -> 70 | G27: Sightseeing | I27: Bourton-on-the-Water, Cotswolds | J27: Walk | L27: 'Venice of the Cotswolds' in the evening light: River Windrush footbridges, honey-coloured stone cottages, riverside walk. Flat and senior friendly. Sunset about 20:05. | N27: Location | P27: Draft
A28: 2 | B28: 46495 | C28: BST | D28: 0.79166667 | E28: 0.88541667 | F28: =ROUND(MOD(E28-D28,1)*1440,0) -> 135 | G28: Coach transfer | H28: Bourton-on-the-Water, Cotswolds | I28: Hotel, Wembley area (TBC) | J28: Coach | K28: 140 | L28: Coach back to Wembley via A40/M40 (2 h 15 m incl. short stop). | N28: Route | P28: Draft
A29: 2 | B29: 46495 | C29: BST | D29: 0.88541667 | E29: 0.91666667 | F29: =ROUND(MOD(E29-D29,1)*1440,0) -> 45 | G29: Dinner | I29: Hotel, Wembley area (TBC) | J29: — | L29: Late dinner; snacks on the coach. | M29: Hotel – Satvik menu pre-agreed (or Indian caterer delivering to the hotel) | N29: Location | P29: Draft
A30: 3 | B30: 46496 | C30: BST | G30: DAY 3 · Mon | I30: London city: Westminster · London Eye · Thames · Tower · Tussauds · Soho temple | L30: Overnight: London (Wembley)
A31: 3 | B31: 46496 | C31: BST | D31: 0.25 | E31: 0.29166667 | F31: =ROUND(MOD(E31-D31,1)*1440,0) -> 60 | G31: Morning programme | I31: Hotel, Wembley area (TBC) | J31: Walk | L31: Japa (16 rounds at own pace), short kirtan and Bhagavatam reading in the hotel hall or lobby (before breakfast; optional). | N31: Location | P31: Draft
A32: 3 | B32: 46496 | C32: BST | D32: 0.29166667 | E32: 0.375 | F32: =ROUND(MOD(E32-D32,1)*1440,0) -> 120 | G32: Breakfast | I32: Hotel, Wembley area (TBC) | J32: — | M32: Hotel – complimentary buffet (07:00–09:00) | N32: Location | P32: Draft
A33: 3 | B33: 46496 | C33: BST | D33: 0.375 | E33: 0.41319444 | F33: =ROUND(MOD(E33-D33,1)*1440,0) -> 55 | G33: Coach transfer | H33: Hotel, Wembley area (TBC) | I33: Westminster – Big Ben & Houses of Parliament | J33: Coach | K33: 20 | L33: Coach into central London; drop at Westminster Bridge. | N33: Route | P33: Draft
A34: 3 | B34: 46496 | C34: BST | D34: 0.41666667 | E34: 0.45833333 | F34: =ROUND(MOD(E34-D34,1)*1440,0) -> 60 | G34: Sightseeing | I34: London Eye | J34: Walk | L34: London Eye – 30-minute rotation in a capsule (pre-booked 10:00 group slot). Views of St Paul's, Buckingham Palace, the Shard. | N34: Location | P34: Draft
A35: 3 | B35: 46496 | C35: BST | D35: 0.45833333 | E35: 0.48958333 | F35: =ROUND(MOD(E35-D35,1)*1440,0) -> 45 | G35: Sightseeing | I35: Westminster – Big Ben & Houses of Parliament | J35: Walk | L35: Walk over Westminster Bridge: Big Ben, Houses of Parliament, Westminster Abbey (exterior), Parliament Square. | N35: Location | P35: Draft
A36: 3 | B36: 46496 | C36: BST | D36: 0.48958333 | E36: 0.53125 | F36: =ROUND(MOD(E36-D36,1)*1440,0) -> 60 | G36: Lunch | I36: Indian vegetarian restaurant near Westminster / Embankment (TBC) | J36: — | L36: Backup: packed Satvik lunch from the London caterer. | M36: Indian vegetarian restaurant near Westminster / Embankment (to be booked) | N36: Location | P36: Draft
A37: 3 | B37: 46496 | C37: BST | D37: 0.54166667 | E37: 0.56944444 | F37: =ROUND(MOD(E37-D37,1)*1440,0) -> 40 | G37: Boat transfer | H37: London Eye Pier (Thames cruise) | I37: Tower Millennium Pier | J37: Boat | K37: 5 | L37: Thames boat (Uber Boat), London Eye Pier → Tower Pier: Somerset House, St Paul's, Shakespeare's Globe, HMS Belfast. | N37: Route | P37: Draft
A38: 3 | B38: 46496 | C38: BST | D38: 0.57291667 | E38: 0.65625 | F38: =ROUND(MOD(E38-D38,1)*1440,0) -> 120 | G38: Sightseeing | I38: Tower of London – Crown Jewels (Kohinoor) | J38: Walk | L38: Tower of London: Crown Jewels including the Koh-i-Noor, White Tower, Yeoman Warder tour, ravens. Tower Bridge photo stop. | N38: Location | O38: Book timed group tickets (13:45 slot); last entry about 16:30. | P38: Draft
A39: 3 | B39: 46496 | C39: BST | D39: 0.65625 | E39: 0.6875 | F39: =ROUND(MOD(E39-D39,1)*1440,0) -> 45 | G39: Coach transfer | H39: Tower of London – Crown Jewels (Kohinoor) | I39: Madame Tussauds London | J39: Coach | K39: 8 | L39: Coach across the City to Marylebone Road. | N39: Route | P39: Draft
A40: 3 | B40: 46496 | C40: BST | D40: 0.6875 | E40: 0.73958333 | F40: =ROUND(MOD(E40-D40,1)*1440,0) -> 75 | G40: Sightseeing | I40: Madame Tussauds London | J40: Walk | L40: Madame Tussauds: Bollywood zone, royals, world leaders, Marvel. Timed group entry. | N40: Location | O40: Book the 16:30 slot; check the day's closing time. | P40: Draft
A41: 3 | B41: 46496 | C41: BST | D41: 0.73958333 | E41: 0.76041667 | F41: =ROUND(MOD(E41-D41,1)*1440,0) -> 30 | G41: Coach transfer | H41: Madame Tussauds London | I41: Radha-Krishna Temple, ISKCON Soho (10 Soho Street) | J41: Coach | K41: 3 | L41: Coach Madame Tussauds London → Radha-Krishna Temple, ISKCON Soho (10 Soho Street). Bhajans, japa and sthala-purana narration on board. | N41: Route | P41: Draft
...

Sheet Meal plan
A1: Day | B1: Date | C1: Meal | D1: Start | E1: End | F1: Where | G1: Provided by | H1: Notes | I1: Google Maps | J1: Booking status
A3: 1 | B3: 46494 | C3: Dinner | D3: 0.8125 | E3: 0.85416667 | F3: Hotel, Wembley area (TBC) | G3: Hotel / Indian caterer – Ekadasi (grain-free) menu | H3: Hyderabad group dinner. No grains, beans, onion or garlic: fruit, potato, sabudana, paneer, nuts, milk. | I3: Location | J3: Not booked
A4: 1 | B4: 46494 | C4: Dinner | D4: 0.86458333 | E4: 0.89583333 | F4: Hotel, Wembley area (TBC) | G4: Hotel / Indian caterer – Ekadasi (grain-free) menu | H4: Bangalore group dinner. | I4: Location | J4: Not booked
A5: 2 | B5: 46495 | C5: Breakfast | D5: 0.29166667 | E5: 0.375 | F5: Hotel, Wembley area (TBC) | G5: Hotel – complimentary buffet (07:00–09:00) – Dvadasi break fast between 05:59 and 10:40 (London) | H5: Break the Ekadasi fast with grains at breakfast. | I5: Location | J5: Not booked
A6: 2 | B6: 46495 | C6: Lunch | D6: 0.54166667 | E6: 0.57291667 | F6: Bhaktivedanta Manor, ISKCON (Watford) | G6: Bhaktivedanta Manor – Sunday feast prasadam (donation) | I6: Location | J6: Not booked
A7: 2 | B7: 46495 | C7: Dinner | D7: 0.88541667 | E7: 0.91666667 | F7: Hotel, Wembley area (TBC) | G7: Hotel – Satvik menu pre-agreed (or Indian caterer delivering to the hotel) | H7: Late dinner; snacks on the coach. | I7: Location | J7: Not booked
A8: 3 | B8: 46496 | C8: Breakfast | D8: 0.29166667 | E8: 0.375 | F8: Hotel, Wembley area (TBC) | G8: Hotel – complimentary buffet (07:00–09:00) | I8: Location | J8: Not booked
A9: 3 | B9: 46496 | C9: Lunch | D9: 0.48958333 | E9: 0.53125 | F9: Indian vegetarian restaurant near Westminster / Embankment (TBC) | G9: Indian vegetarian restaurant near Westminster / Embankment (to be booked) | H9: Backup: packed Satvik lunch from the London caterer. | I9: Location | J9: Not booked
A10: 3 | B10: 46496 | C10: Dinner | D10: 0.85416667 | E10: 0.89583333 | F10: Hotel, Wembley area (TBC) | G10: Hotel – Satvik menu pre-agreed (or Indian caterer delivering to the hotel) | I10: Location | J10: Not booked
A11: 4 | B11: 46497 | C11: Breakfast | D11: 0.29166667 | E11: 0.375 | F11: Hotel, Wembley area (TBC) | G11: Hotel – complimentary buffet (07:00–09:00) | I11: Location | J11: Not booked
A12: 4 | B12: 46497 | C12: Lunch | D12: 0.58333333 | E12: 0.61458333 | F12: Port of Dover – P&O / DFDS ferry | G12: Packed Satvik lunch from London Indian caterer (eaten on board) | H12: Lunch on the ferry. | I12: Location | J12: Not booked
A13: 4 | B13: 46497 | C13: Dinner | D13: 0.875 | E13: 0.91666667 | F13: Hotel, Gare du Nord / La Chapelle area (TBC) | G13: Hotel – Satvik menu pre-agreed (or Indian caterer delivering to the hotel) | I13: Location | J13: Not booked
A14: 5 | B14: 46498 | C14: Breakfast | D14: 0.29166667 | E14: 0.375 | F14: Hotel, Gare du Nord / La Chapelle area (TBC) | G14: Hotel – complimentary buffet (07:00–09:00) | I14: Location | J14: Not booked
A15: 5 | B15: 46498 | C15: Lunch | D15: 0.56597222 | E15: 0.60763889 | F15: Saravanaa Bhavan Paris (Rue du Faubourg Saint-Denis) | G15: Saravanaa Bhavan Paris – group booking | H15: South Indian vegetarian meals. | I15: Location | J15: Not booked
A16: 5 | B16: 46498 | C16: Dinner | D16: 0.80208333 | E16: 0.84375 | F16: Hotel, Gare du Nord / La Chapelle area (TBC) | G16: Hotel – Satvik menu pre-agreed (or Indian caterer delivering to the hotel) | I16: Location | J16: Not booked
A17: 6 | B17: 46499 | C17: Breakfast | D17: 0.29166667 | E17: 0.375 | F17: Hotel, Gare du Nord / La Chapelle area (TBC) | G17: Hotel – complimentary buffet (07:00–09:00) | I17: Location | J17: Not booked
A18: 6 | B18: 46499 | C18: Lunch | D18: 0.52430556 | E18: 0.56597222 | F18: Krishna Bhavan, Rue Cail (South Indian vegetarian) | G18: Krishna Bhavan, Rue Cail – group booking | H18: South Indian vegetarian lunch. | I18: Location | J18: Not booked
A19: 6 | B19: 46499 | C19: Dinner | D19: 0.85416667 | E19: 0.89583333 | F19: Hotel, Brussels centre (TBC) | G19: Hotel – Satvik menu pre-agreed (or Indian caterer delivering to the hotel) | I19: Location | J19: Not booked
A20: 7 | B20: 46500 | C20: Breakfast | D20: 0.29166667 | E20: 0.375 | F20: Hotel, Brussels centre (TBC) | G20: Hotel – complimentary buffet (07:00–09:00) | I20: Location | J20: Not booked
A21: 7 | B21: 46500 | C21: Lunch | D21: 0.53125 | E21: 0.57291667 | F21: ISKCON Radhadesh – Château de Petite Somme | G21: Radhadesh temple – prasadam (pre-arranged; donation) | I21: Location | J21: Not booked
A22: 7 | B22: 46500 | C22: Dinner | D22: 0.79166667 | E22: 0.83333333 | F22: Hotel, Amsterdam (TBC) | G22: Hotel – Satvik menu pre-agreed (or Indian caterer delivering to the hotel) | I22: Location | J22: Not booked
A23: 8 | B23: 46501 | C23: Breakfast | D23: 0.29166667 | E23: 0.375 | F23: Hotel, Amsterdam (TBC) | G23: Hotel – complimentary buffet (07:00–09:00) | I23: Location | J23: Not booked
A24: 8 | B24: 46501 | C24: Lunch | D24: 0.55208333 | E24: 0.58333333 | F24: Keukenhof tulip gardens | G24: Packed Satvik lunch from Amsterdam Indian caterer (picnic area) | I24: Location | J24: Not booked
A25: 8 | B25: 46501 | C25: Dinner | D25: 0.8125 | E25: 0.85416667 | F25: Hotel, Cologne centre (TBC) | G25: Hotel – Satvik menu pre-agreed (or Indian caterer delivering to the hotel) | I25: Location | J25: Not booked
A26: 9 | B26: 46502 | C26: Breakfast | D26: 0.29166667 | E26: 0.375 | F26: Hotel, Cologne centre (TBC) | G26: Hotel – complimentary buffet (07:00–09:00) | I26: Location | J26: Not booked
A27: 9 | B27: 46502 | C27: Lunch | D27: 0.5625 | E27: 0.59375 | F27: ISKCON Goloka Dham (Abentheuer, near Trier) | G27: Goloka Dham temple – prasadam (pre-arranged; donation) | H27: The Sunday feast is at 15:00; take feast sweets for the road. | I27: Location | J27: Not booked
A28: 9 | B28: 46502 | C28: Dinner | D28: 0.85416667 | E28: 0.89583333 | F28: Hotel, Titisee-Neustadt (TBC) | G28: Hotel – Satvik menu pre-agreed (or Indian caterer delivering to the hotel) | I28: Location | J28: Not booked
A29: 10 | B29: 46503 | C29: Breakfast | D29: 0.29166667 | E29: 0.375 | F29: Hotel, Titisee-Neustadt (TBC) | G29: Hotel – complimentary buffet (07:00–09:00) | I29: Location | J29: Not booked
A30: 10 | B30: 46503 | C30: Lunch | D30: 0.54166667 | E30: 0.58333333 | F30: Indian restaurant, Schaffhausen (TBC) | G30: Indian restaurant, Schaffhausen (to be booked) – backup: packed lunch | I30: Location | J30: Not booked
A31: 10 | B31: 46503 | C31: Dinner | D31: 0.8125 | E31: 0.85416667 | F31: Hotel, Zurich (TBC) | G31: Hotel – Satvik menu pre-agreed (or Indian caterer delivering to the hotel) | I31: Location | J31: Not booked
A32: 11 | B32: 46504 | C32: Breakfast | D32: 0.29166667 | E32: 0.375 | F32: Hotel, Zurich (TBC) | G32: Hotel – complimentary buffet (07:00–09:00) | H32: Winter clothing today: the Titlis summit is about −2 to −7 °C with snow in late April. | I32: Location | J32: Not booked
A33: 11 | B33: 46504 | C33: Lunch | D33: 0.54166667 | E33: 0.58333333 | F33: Indian Group Restaurant, Trübsee mid-station | G33: Indian Group Restaurant at Trübsee mid-station (moved down from the summit during construction; pre-book) | I33: Location | J33: Not booked
A34: 11 | B34: 46504 | C34: Dinner | D34: 0.85416667 | E34: 0.89583333 | F34: Hotel, Interlaken (TBC) | G34: Hotel – Satvik menu pre-agreed (or Indian caterer delivering to the hotel) | I34: Location | J34: Not booked
A35: 12 | B35: 46505 | C35: Breakfast | D35: 0.29166667 | E35: 0.375 | F35: Hotel, Interlaken (TBC) | G35: Hotel – complimentary buffet (07:00–09:00) | I35: Location | J35: Not booked
A36: 12 | B36: 46505 | C36: Lunch | D36: 0.57638889 | E36: 0.61805556 | F36: Indian restaurant, Como (TBC) | G36: Indian restaurant, Como (to be booked) – backup: packed lunch | I36: Location | J36: Not booked
A37: 12 | B37: 46505 | C37: Dinner | D37: 0.85416667 | E37: 0.89583333 | F37: Hotel, Milan (TBC) | G37: Hotel – Satvik menu pre-agreed (or Indian caterer delivering to the hotel) | I37: Location | J37: Not booked
A38: 13 | B38: 46506 | C38: Breakfast | D38: 0.29166667 | E38: 0.375 | F38: Hotel, Milan (TBC) | G38: Hotel – complimentary buffet (07:00–09:00) | I38: Location | J38: Not booked
A39: 13 | B39: 46506 | C39: Lunch | D39: 0.54166667 | E39: 0.57291667 | F39: ISKCON Prabhupada Desh (Albettone, Vicenza) | G39: Prabhupada Desh temple – prasadam (pre-arranged; donation) | I39: Location | J39: Not booked
A40: 13 | B40: 46506 | C40: Dinner | D40: 0.86458333 | E40: 0.90625 | F40: Hotel, Venice-Mestre (TBC) | G40: Hotel – Satvik menu pre-agreed (or Indian caterer delivering to the hotel) | I40: Location | J40: Not booked
A41: 14 | B41: 46507 | C41: Breakfast | D41: 0.20833333 | E41: 0.23611111 | F41: Hotel, Venice-Mestre (TBC) | G41: Hotel – breakfast boxes (ordered the evening before) | H41: EXCEPTION to the 07:00–09:00 breakfast / 09:00 start: the only Vatican day needs the 06:30 train. With a 09:00 start the group reaches Rome at ~13:15 and loses the Colosseum interior. | I41: Location | J41: Not booked
...

Sheet Places & maps
A1: # | B1: Place | C1: City | D1: Country | E1: Google Maps search text | F1: Open in Google Maps
A3: 1 | B3: Rajiv Gandhi International Airport (HYD) | C3: Hyderabad | D3: India | E3: Rajiv Gandhi International Airport Hyderabad | F3: Open map
A4: 2 | B4: London Heathrow Airport (LHR) | C4: London | D4: United Kingdom | E4: Heathrow Airport London | F4: Open map
A5: 3 | B5: Heathrow Terminal 3 | C5: London | D5: United Kingdom | E5: Heathrow Terminal 3 | F5: Open map
A6: 4 | B6: Heathrow Terminal 4 | C6: London | D6: United Kingdom | E6: Heathrow Terminal 4 | F6: Open map
A7: 5 | B7: Kempegowda International Airport (BLR), T2 | C7: Bangalore | D7: India | E7: Kempegowda International Airport Terminal 2 Bengaluru | F7: Open map
A8: 6 | B8: Abu Dhabi International Airport (AUH) | C8: Abu Dhabi | D8: UAE | E8: Abu Dhabi International Airport | F8: Open map
A9: 7 | B9: Milan Malpensa Airport (MXP), T1 | C9: Ferno | D9: Italy | E9: Milano Malpensa Terminal 1 | F9: Open map
A10: 8 | B10: Hotel near Malpensa airport (TBC) | C10: Somma Lombardo | D10: Italy | E10: Hotels near Milano Malpensa Airport | F10: Open map
A11: 9 | B11: Keukenhof tulip gardens | C11: Lisse | D11: Netherlands | E11: Keukenhof, Lisse | F11: Open map
A12: 10 | B12: Venezia Mestre railway station | C12: Mestre | D12: Italy | E12: Venezia Mestre station | F12: Open map
A13: 11 | B13: Roma Termini station | C13: Rome | D13: Italy | E13: Roma Termini | F13: Open map
A14: 12 | B14: Firenze Santa Maria Novella station | C14: Florence | D14: Italy | E14: Firenze Santa Maria Novella | F14: Open map
... A92: 90 | B92: Rome Fiumicino Airport (FCO) | C92: Rome | D92: Italy | E92: Rome Fiumicino Airport | F92: Open map

Sheet Entry tickets
A1: Entry tickets – adult price per person (official 2026 rates)
A2: Checked 2026-10-22. Edit a price or an exchange rate and the INR columns and totals update.
A4: INR per 1 GBP | B4: 126.78
A5: INR per 1 EUR | B5: 106.13
A6: INR per 1 CHF | B6: 114.66
A8: Day | B8: Place | C8: In plan? | D8: Currency | E8: Price (local) | F8: Price (INR) | G8: Notes | H8: Source
A10: 3 | B10: The Lion King, Lyceum (optional) | C10: Optional | D10: GBP | E10: 45 | F10: =IF(E10="","",E10*$B$4) -> 5705.1 | G10: Group 20+ Stalls/Royal Circle; group shows Tue–Fri only | H10: Open
A11: 2 | B11: Christ Church, Oxford (optional) | C11: Optional | D11: GBP | E11: 22.95 | F11: =IF(E11="","",E11*$B$4) -> 2909.601 | G11: Weekday; 65+ £20.50 | H11: Open
A12: 2 | B12: Bodleian Library 60-min tour (optional) | C12: Optional | D12: GBP | E12: 17.5 | F12: =IF(E12="","",E12*$B$4) -> 2218.65 | G12: From price | H12: Open
A13: 2 | B13: Bourton Model Village (optional) | C13: Optional | D13: GBP | E13: 4.95 | F13: =IF(E13="","",E13*$B$4) -> 627.561 | G13: Over 60 £4.50; card only | H13: Open
A14: 3 | B14: London Eye | C14: Yes | D14: GBP | E14: 26 | F14: =IF(E14="","",E14*$B$4) -> 3296.28 | G14: Group 10+; £29 online standard | H14: Open
A15: 3 | B15: Thames boat London Eye → Tower (Uber Boat) | C15: Yes | D15: GBP | E15: 11.7 | F15: =IF(E15="","",E15*$B$4) -> 1483.326 | G15: Online single; 10% off groups 10+; seniors 50% off | H15: Open
A16: 3 | B16: Tower of London (Crown Jewels) | C16: Yes | D16: GBP | E16: 37 | F16: =IF(E16="","",E16*$B$4) -> 4690.86 | G16: NOT VERIFIED – official site blocked | H16: Open
A17: 3 | B17: Madame Tussauds London | C17: Yes | D17: GBP | E17: 27 | F17: =IF(E17="","",E17*$B$4) -> 3423.06 | G17: Online from-price; walk-up £39 | H17: Open
A18: 4 | B18: Seine cruise – Bateaux Parisiens | C18: Yes | D18: EUR | E18: 18 | F18: =IF(E18="","",E18*$B$5) -> 1910.34 | G18: Online; €20 on the day (partly verified) | H18: Open
A19: 5 | B19: Eiffel Tower – lift to 2nd floor | C19: Yes | D19: EUR | E19: 23.5 | F19: =IF(E19="","",E19*$B$5) -> 2494.055 | G19: Youth 12–24 €11.80; child €6 | H19: Open
A20: 6 | B20: Louvre (non-EU rate) | C20: Yes | D20: EUR | E20: 32 | F20: =IF(E20="","",E20*$B$5) -> 3396.16 | G20: Group €28 + €90 fee per 7–20 people | H20: Open
A21: 6 | B21: Atomium inside (optional) | C21: Optional | D21: EUR | E21: 15 | F21: =IF(E21="","",E21*$B$5) -> 1591.95 | G21: Group 20+; standard €17 | H21: Open
A22: 7 | B22: Amsterdam canal cruise 75 min (Blue Boat) | C22: Yes | D22: EUR | E22: 26 | F22: =IF(E22="","",E22*$B$5) -> 2759.38 | G22: Plus passenger tax | H22: Open
A23: 8 | B23: De Kat windmill, Zaanse Schans (optional) | C23: Optional | D23: EUR | E23: 7.5 | F23: =IF(E23="","",E23*$B$5) -> 795.975 | G23: Village free | H23: Open
A24: 8 | B24: Keukenhof (group rate, 20+) | C24: Yes | D24: EUR | E24: 20.5 | F24: =IF(E24="","",E24*$B$5) -> 2175.665 | G24: NOT VERIFIED on keukenhof.nl; ~€21.50 online single; coach parking free | H24: Open
A25: 8 | B25: Cologne Cathedral inside (optional) | C25: Optional | D25: EUR | E25: 12 | F25: =IF(E25="","",E25*$B$5) -> 1273.56 | G25: New charge since 1 Jul 2026; free during services | H25: Open
A26: 10 | B26: Lake Titisee boat (optional) | C26: Optional | D26: EUR | E26: 7.5 | F26: =IF(E26="","",E26*$B$5) -> 795.975 | G26: About 25 min | H26: Open
A27: 10 | B27: Rhine Falls – Schloss Laufen platforms | C27: Yes | D27: CHF | E27: 5 | F27: =IF(E27="","",E27*$B$6) -> 573.3 | G27: Child CHF 3 | H27: Open
A28: 10 | B28: Rhine Falls boat to the rock (optional) | C28: Optional | D28: CHF | E28: 22.5 | F28: =IF(E28="","",E28*$B$6) -> 2579.85 | G28: Not for seniors | H28: Open
A29: 11 | B29: Mount Titlis return (group rate) | C29: Yes | D29: CHF | E29: 81.6 | F29: =IF(E29="","",E29*$B$6) -> 9356.256 | G29: 20% off CHF 102 for groups 10+ | H29: Open
A30: 11 | B30: Titlis Ice Flyer (optional, if running in spring) | C30: Optional | D30: CHF | E30: 12 | F30: =IF(E30="","",E30*$B$6) -> 1375.92 | G30: Extra; seasonal | H30: Open
A31: 11 | B31: Lake Lucerne 1-hour cruise | C31: Yes | D31: CHF | F31: =IF(E31="","",E31*$B$6) | G31: TBC – no 2026 fare published; groups@lakelucerne.ch | H31: Open
A32: 11 | B32: Luzern–Interlaken Express 2nd class (group) | C32: Yes | D32: CHF | E32: 39.8 | F32: =IF(E32="","",E32*$B$6) -> 4563.468 | G32: CHF 23.80 + CHF 16 reservation | H32: Open
A33: 12 | B33: Lake Como boat Como ↔ Cernobbio | C33: Yes | D33: EUR | E33: 6 | F33: =IF(E33="","",E33*$B$5) -> 636.78 | G33: Return; groups/seniors €4.80 | H33: Open
A34: 13 | B34: Milan Duomo cathedral + museum (optional) | C34: Optional | D34: EUR | E34: 10 | F34: =IF(E34="","",E34*$B$5) -> 1061.3 | G34: Terraces lift €18 | H34: Open
A35: 13 | B35: Venice vaporetto 1-day pass | C35: Yes | D35: EUR | E35: 25 | F35: =IF(E35="","",E35*$B$5) -> 2653.25 | G35: Single €9.50 | H35: Open
A36: 13 | B36: Venice gondola 30 min (per person, 5/boat) | C36: Yes | D36: EUR | E36: 18 | F36: =IF(E36="","",E36*$B$5) -> 1910.34 | G36: ~€90 per gondola; NOT VERIFIED
A37: 13 | B37: Doge's Palace (optional) | C37: Optional | D37: EUR | E37: 30 | F37: =IF(E37="","",E37*$B$5) -> 3183.9 | G37: Online 30 days ahead; €35 otherwise | H37: Open
A38: 15 | B38: Leaning Tower of Pisa climb (optional) | C38: Optional | D38: EUR | E38: 20 | F38: =IF(E38="","",E38*$B$5) -> 2122.6 | G38: Includes Cathedral | H38: Open
A39: 15 | B39: Florence Duomo Brunelleschi Pass (optional) | C39: Optional | D39: EUR | E39: 30 | F39: =IF(E39="","",E39*$B$5) -> 3183.9 | G39: Cathedral itself free | H39: Open
A40: 14 | B40: Vatican Museums & Sistine Chapel | C40: Yes | D40: EUR | E40: 25 | F40: =IF(E40="","",E40*$B$5) -> 2653.25 | G40: €20 + €5 booking | H40: Open
A41: 14 | B41: Colosseum + Forum + Palatine | C41: Yes | D41: EUR | E41: 18 | F41: =IF(E41="","",E41*$B$5) -> 1910.34 | G41: Under 18 free | H41: Open
A42: 14 | B42: Trevi Fountain basin access | C42: Yes | D42: EUR | E42: 2 | F42: =IF(E42="","",E42*$B$5) -> 212.26 | G42: Since Feb 2026 | H42: Open
A43: 14 | B43: Pantheon | C43: Yes | D43: EUR | E43: 7 | F43: =IF(E43="","",E43*$B$5) -> 742.91 | G43: Since Jul 2026 | H43: Open
...

Sheet Pros & cons
A1: Day | B1: Pros | C1: Cons / watch-outs
A3: 1 | B3: Both groups land the same afternoon/evening; one coach does two runs. | C3: Kamada Ekadasi on a 13–16 h travel day; Hyderabad yatris report at 01:40.
A4: 2 | B4: Bhaktivedanta Manor's Sunday programme and feast prasadam lunch in the morning, then Oxford and Bourton-on-the-Water in the evening light. | C4: Long day (09:00–21:15, dinner 21:15); some Oxford colleges may close at the start of Trinity term.
A5: 3 | B5: All the big London sights in one loop; Soho temple at arati time. | C5: Monday-morning traffic; early lunch (11:45) to fit the 13:00 boat and the Tower.
A6: 4 | B6: Ferry keeps coach and luggage with the group; Balarama Rasayatra kirtan on the coach. | C6: First EU biometric (EES) registration at Dover can take 1–2 h; with the 09:00 start the group reaches Paris only at 20:30.
A7: 5 | B7: Eiffel, Notre-Dame and ISKCON Paris with an Indian lunch; evening Seine cruise (21:00) after dinner. | C7: Paris is between the two rounds of the French presidential election: rallies possible.
A8: 6 | B8: Louvre on a Thursday (open) plus Brussels on one day. | C8: Louvre walking is tiring; 4 h of driving afterwards.
A9: 7 | B9: Radhadesh is a highlight; evening canal cruise; tulip fields from the coach. | C9: Two countries in one day; late finish (~22:00).
A10: 8 | B10: Keukenhof at peak tulip season; windmills at Zaanse Schans. | C10: Saturday crowds at both; Volendam dropped to make room.
A11: 9 | B11: ISKCON Cologne and Goloka Dham on a Sunday (kirtan, class, feast). | C11: Longest coach day (~7.5 h incl. breaks); Cologne Cathedral interior closed to tourists on Sunday morning.
A12: 10 | B12: Rhine Falls at full spring flow; Black Forest and Zurich are compact. | C12: Titisee boats may not have started their season; many short stops.
A13: 11 | B13: Titlis in deep spring snow; scenic train to Interlaken. | C13: Summit about −5 °C; Ice Flyer may not run; cloud can hide the views.
A14: 12 | B14: Alps to Italian lakes in one day; Villaggio at arati time. | C14: 4.5 h on the road over Gotthard; tunnel queues possible.
... A18: 16 | B18: Short transfer to Malpensa; both groups fly together to Abu Dhabi. | C18: Varuthini Ekadasi on the flight; landing at 02:45–03:15 in India.

Sheet Challenges
A1: Challenge | B1: What happens | C1: Mitigation
A3: Vatican day has no backup | B3: Vatican Museums are closed on 1 May and on Sundays, so Fri 30 April is the only day. It depends on two high-speed trains. | C3: Book the 11:00 group slot early. Watch the Italian strike register from mid-April (strikes are announced 10–12 days ahead). Backup: coach Mestre → Rome (6 h) with an overnight in Rome.
A4: First EU biometric check (EES) at Dover | B4: Every yatri gives fingerprints and a photo at first Schengen entry (live since 10 Apr 2026). Coach queues of 1–2 h have been reported. | C4: Arrive at Dover 2 h before sailing; book a later sailing as fallback; passports and visa copies in hand.
A5: Coach driver hours (EU rules) | B5: Max 9 h driving a day (10 h twice a week), 45-min break after 4.5 h, 11 h daily rest. Day 9 is the longest at ~7.5 h incl. breaks. | C5: Coach company to confirm driver hours for Days 7–9 and 12–15; a second driver if any day slips.
A6: Two Ekadasis on travel days | B6: Kamada Ekadasi on 17 Apr (outbound flights) and Varuthini Ekadasi on 2 May (flights home). | C6: Pre-order fruit meals (FPML); carry Ekadasi snacks; grain-free hotel dinner on 17 Apr; break fast in London 05:59–10:40 on 18 Apr and in India before ~10:00 on 3 May.
A7: Cold and wet spring weather | B7: London 7–15 °C with showers; Black Forest near 0 °C at night; Titlis summit about −5 °C in snow; Italy 10–21 °C. | C7: Warm jacket, thermal layer, gloves and cap for Titlis; umbrellas; non-slip shoes.
A8: Holidays and events | B8: 1 May Labour Day in Italy (Florence/Pisa crowds); French presidential election 18 Apr and 2 May; Keukenhof and Zaanse Schans busy on Saturday. | C8: Pre-book all timed entries; go early; avoid political rallies in Paris.
A9: Pickpockets | B9: Paris (Eiffel, Louvre, Métro), Rome (Trevi, Colosseum, Termini station), Venice crowds. | C9: Neck pouches, zipped bags worn in front, passports in the hotel safe except on ticket days, buddy system.
A10: Satvik food availability | B10: Most restaurants use onion and garlic; few Indian restaurants in small towns. | C10: Written no-onion/no-garlic menus; temple prasadam on 5 meals; packed lunches on 2 days; carry ready meals and dry snacks.
A11: Senior citizens' stamina | B11: Long walks (Louvre, Vatican, Venice), steps (Pisa, Venice bridges), altitude (Titlis), the 05:00–22:30 Rome day. | C11: Wheelchairs at museums, a rest option in Florence on Day 14, slow group with an assistant, pre-departure medical check.
A12: Visas and biometrics | B12: UK visa can be applied for only 3 months before travel; Schengen up to 6 months before. Passports are held during processing. | C12: UK first (mid-to-late Jan 2027), then Schengen via Italy (by late Feb / early Mar 2027).
A13: Budget shortfall | B13: Realistic cost about ₹5.29 lakh per yatri at 40 yatris vs ₹5.00 lakh price. | C13: Group hotel contracts, split UK/mainland coach, fill the coach to 45–49, review price (see Budget).
A14: Lost passport or luggage | B14: 12 hotels in 15 nights. | C14: Group luggage tags, a daily luggage count, scans of passports and visas, Indian embassy contacts.

Sheet Do's & don'ts
A1: Do | B1: Don't
A3: Carry your passport, visa and insurance card on travel days; keep a photocopy separately. | B3: Don't carry valuables or large amounts of cash in back pockets or open bags.
A4: Be at the coach 5 minutes before the departure time announced. | B4: Don't sign petitions or accept 'free' bracelets or roses from strangers (common scams).
A5: Wear comfortable walking shoes already broken in; 10,000–15,000 steps on city days. | B5: Don't wander off alone; never leave the group without telling the tour manager.
A6: Dress modestly for churches and the Vatican: shoulders and knees covered, no caps inside. | B6: Don't bring banned food items from India (meat, dairy, fresh fruit and vegetables into the UK/EU). Packaged food is mostly fine; declare it if in doubt.
A7: Keep a small day-bag: water, cap, sunscreen, umbrella, light jacket, medicines, chargers. | B7: Don't climb the Leaning Tower or do the Titlis Cliff Walk if you have heart, BP or knee problems.
A8: Pre-inform the tour manager of medical conditions and dietary needs. | B8: Don't take photos in the Sistine Chapel or where signs prohibit it.
A9: Use the buddy system; keep your phone on and charged (power bank). | B9: Don't eat in the coach unless permitted by the driver; no hot food.
A10: Respect temple etiquette abroad: shoes off, no photos of deities where asked, offer a donation if you wish. | B10: Don't block the bus aisle or leave bags in the stairwell.
A11: Keep coins of EUR and CHF for toilets (often €0.50–€1). | B11: Don't buy from street sellers near monuments (counterfeit goods; fines in Italy and France for buyers).
A12: Ask for VAT refund forms on purchases over the minimum (varies by country). | B12: Don't overstay your visa or lose your stamps; keep boarding passes until home.
A13: Drink plenty of water, especially in Italy.
A14: Keep the coach clean; take your waste with you.

Sheet Visa documents
A1: Schengen biometrics – documents to carry (keep a scan of each for the UK visa)
A3: Document | B3: Requirement | C3: Ready? (Y/N)
A5: Timing | B5: UK visa: apply from about 17 Jan 2027 (max 3 months before); decision usually 3 weeks after biometrics. Schengen: apply to Italy (longest stay) between Jan and early Mar 2027 (max 6 months, min 15 days before); normally 15 days, up to 45. Do UK first, then Schengen.
A6: Passport | B6: Current passport + previous passports if any. Print the first and last pages, plus pages with travel history (black & white is fine). Valid 3+ months beyond 3 May 2027 and 2 blank pages.
A7: Photos | B7: Schengen visa photos, 35 mm × 45 mm, white background, matte or glossy, no spectacles, 2 copies. Do not bring ordinary passport-size photos.
A8: Income Tax Return (ITR-V) | B8: Personal or company ITR-V acknowledgement for the last 3 financial years (FY 2023-24, 2024-25, 2025-26). Balance sheet not needed.
A9: Bank statement | B9: Personal or company account, last 3 months, sealed and signed by the bank. Minimum balance about ₹3 lakh per person.
A10: Salary slips | B10: Last 3 months (employees).
A11: Covering letter | B11: On company letterhead, or plain paper if there is none, signed by the sponsor (self, spouse or company). Add an explanation letter with proof for any sudden large deposit.
A12: Leave letter | B12: From the employer, if working.
A13: Certificate of incorporation | B13: If travelling on company funds or showing company ITR-V and bank statements: company registration or GST registration certificate.
A14: Provided by organisers at the biometric office | B14: Covering letter from Goldenavatar Ventures Pvt Ltd for the group, its ITR-V (3 years), 3-month sealed bank statement and incorporation letter, travel insurance (must cover the UK too), hotel confirmations, flight tickets, the filled visa application form.
A15: UK visa specifics | B15: £135 Standard Visitor visa, issued as an eVisa linked to the passport (each yatri creates a UKVI account). No UK ETA needed with a visa. Keep a scan of every Schengen document; most are reused.

Sheet Inclusions
A1: Inclusions | B1: Exclusions
A3: All transfers by private coach | B3: Personal expenses
A4: All meals | B4: Driver tips at EUR 3 per person per day
A5: All airfare (ex-Hyderabad / Chennai / Bangalore or any South Indian city) | B5: Optional extras not in the itinerary: Lion King show, Leaning Tower climb, Doge's Palace, other optional entries
A6: All visa charges
A7: Services of a tour manager
A8: All sightseeing as in the itinerary
A9: All hotels

Sheet Practical info
A1: Topic | B1: Details
A3: Weather in late April | B3: 15–21 °C by day, 6–11 °C at night, rain on 3–5 days in 11. Titisee mornings near freezing. Titlis summit −2 to −7 °C with snow. Sunset 20:00–21:00.
A4: Currency | B4: UK: GBP (£). France, Belgium, Netherlands, Germany, Italy, Vatican: EUR (€). Switzerland: CHF (EUR widely accepted at a poor rate). A multi-currency forex card plus a little cash in each.
A5: Power plugs | B5: UK: Type G (3-pin). Europe: Type C/F (2 round pins). Switzerland: Type J (Type C fits). Carry a universal adapter and a power bank.
A6: Mobile & data | B6: An international roaming pack or a Europe + UK eSIM. Switzerland is often excluded from EU packs, so check. Make WhatsApp the group channel.
A7: Time zones | B7: UK = IST − 4 h 30 m (BST). France to Italy = IST − 3 h 30 m (CEST). Abu Dhabi = IST − 1 h 30 m.
A8: Tipping | B8: Driver EUR 3 per person per day (collected by the tour manager). Local guides 2–5 EUR per person per tour (optional). Restaurants: service usually included.
A9: Emergency numbers | B9: UK 999 / 112; EU and Switzerland 112. Indian High Commission London +44 20 7836 8484 (verify); Indian embassies in Paris, Brussels, The Hague, Berlin, Bern and Rome (save their numbers before departure).
A10: Senior-citizen care | B10: Seats near the front, wheelchair booking at the Louvre, Vatican and airports, extra rest stops, a medicine pouch with prescriptions, an attendant ratio of 1:10, lifts used wherever available.
